Workbook

Sheet 공구영수증
B7: 문서번호 | C7: W-20260610-1 | F7: 주식회사 우프컴퍼니 (314-87-00725)
B8: 날짜 | C8: =TODAY() -> 46183 | F8: 서울 용산구 한남대로8길 6-17, 1F
B9: 문서제목 | C9: 영이공구 (2026.05) 판매 내역 정산 | F9: 대표자명 | G9: 이교영 (인)
B10: 수신 | C10: 안진양 대표님 (영이공구) | F10: team@wooof.co.kr
B13: 1. 귀사의 무궁한 발전과 건승을 기원합니다.
B14: 2. 아래와 같이 판매의 내역을 공유드리며, 확인 후 이상이 없으신 경우 지급처리를 위한 전자계산서 발행을 요청드립니다.
D16: - 아 래 -
B18: 품목 | C18: 세부항목 | E18: 진행기간 | F18: 판매금액 | G18: 공구수수료 | H18: 합계
B19: 5월 판매액 | C19: 베럴즈 아웃도어대전 카시트 및 스텝온옵션 | E19: 4/9 - 4/19 | F19: =판매내역집계!F21 -> 2283900 | G19: 0.2 | H19: =F19*G19 -> 456780
C20: 베럴즈 아웃도어대전 산책용품 (목줄/리쉬) | E20: 4/9 - 4/19 | F20: =판매내역집계!F34+판매내역집계!F47 -> 394800 | G20: 0.2 | H20: =F20*G20 -> 78960
C21: 베럴즈 아웃도어대전 드라잉타올 | E21: 5/12 - 진행중 | F21: =판매내역집계!F49 -> 610740 | G21: 0.2 | H21: =F21*G21 -> 122148
C22: 베럴즈 아웃도어대전 포포타올 | E22: 4/9 - 진행중 | F22: =판매내역집계!F52 -> 32504630 | G22: 0.2 | H22: =F22*G22 -> 6500926
C23: 콘디 냉감블랭킷 공구 | E23: 4/3 - 진행중 | F23: =판매내역집계!F15 -> 6307900 | G23: 0.2 | H23: =F23*G23 -> 1261580
C24: 도톤 아웃도어 스프레이 공구 | E24: 4/13 - 5/24 | F24: =판매내역집계!F58 -> 888600 | G24: 0.2 | H24: =F24*G24 -> 177720
C25: 합계 | F25: =SUM(F19:F24) -> 42990570 | H25: =SUM(H19:H24) -> 8598114
B27: 품목 | C27: 세부항목 | F27: 지출광고비 | G27: 부담비용 | H27: 합계
B28: 5월 광고비 정산 | C28: 포포타올 광고비 | F28: ='광고비용 집계'!B4 -> 619671 | G28: 0.5 | H28: =F28*G28 -> 309835.5
C29: 합계 | F29: =SUM(F28) -> 619671 | H29: =SUM(H28:H28) -> 309835.5
F31: 판매수수료 합계 | H31: =H25 -> 8598114
F32: 광고비 공제(-) | H32: =H29 -> 309835.5
E34: 총 합계액 (부가세 포함) | H34: =H31-H32 -> 8288278.5
B36: * 5/1-5/31 배송완료 내역 및 구매확정(스마트스토어) 내역 기준입니다.
B37: * 5/31 일 기준으로 매출 세금계산서 정발행해 주시면 익월 15일 까지 지정된 계좌로 지급 예정입니다.

Sheet 광고비용 집계
A2: 행 레이블 | B2: 합계 : 지출 금액 (KRW) | C2: 합계 | D2: 합계 (50%)
A3: 포포타올 | B3: =D9 -> 619671 | C3: =B3 -> 619671 | D3: =C3/2 -> 309835.5
A4: 총합계 | B4: =SUM(B3) -> 619671 | C4: =SUM(C3) -> 619671 | D4: =SUM(D3:D3) -> 309835.5
A8: 보고 시작 | B8: 보고 종료 | C8: 광고 이름 | D8: 지출 금액 (KRW) | E8: 노출 | F8: CPM(1,000회 노출당 비용) (KRW) | G8: 도달 | H8: 빈도 | I8: CTR(전체) | J8: 링크 클릭 | K8: CPC(전체) (KRW) | L8: 구매 ROAS(광고 지출 대비 수익률)
A9: 2026-05-01 | B9: 2026-05-31 | C9: 20260417_포포타올 광고 캠페인 | D9: 619671 | E9: 95891 | F9: 6462.2436 | G9: 71929 | H9: 1.333134 | I9: 7.027771 | J9: 5467 | K9: 91.95296

Sheet 판매내역집계
A1: 202605 | B1: 영이공구 판매내역 집계
B2: 스마트스토어 : 5/1-5/31 [구매확정] 기준 집계
B3: 우프자사몰 : 5/1-5/31 [배송완료] 기준 집계
A5: 제품 | B5: 구매옵션 | C5: 정상가 | D5: 공구판매가 | E5: 판매수량 | F5: 공구매출계 | G5: 공구수수료
A6: 콘디 | B6: 블루화이트 1개 | D6: 26900 | E6: 62 | F6: =D6*E6 -> 1667800 | G6: =F6*20% -> 333560
B7: 블루화이트 2개 | D7: 51900 | E7: 24 | F7: =D7*E7 -> 1245600 | G7: =F7*20% -> 249120
B8: 블루화이트 3개 | D8: 71900 | E8: 9 | F8: =D8*E8 -> 647100 | G8: =F8*20% -> 129420
B9: 블랙화이트 1개 | D9: 26900 | E9: 0 | F9: =D9*E9 -> 0 | G9: =F9*20% -> 0
B10: 블랙화이트 2개 | D10: 51900 | E10: 0 | F10: =D10*E10 -> 0 | G10: =F10*20% -> 0
B11: 블랙화이트 3개 | D11: 71900 | E11: 0 | F11: =D11*E11 -> 0 | G11: =F11*20% -> 0
B12: 블루화이트 1개 + 블랙화이트 1개 | D12: 51900 | E12: 28 | F12: =D12*E12 -> 1453200 | G12: =F12*20% -> 290640
B13: 블루화이트 2개 + 블랙화이트 1개 | D13: 71900 | E13: 6 | F13: =D13*E13 -> 431400 | G13: =F13*20% -> 86280
B14: 블루화이트 1개 + 블랙화이트 2개 | D14: 71900 | E14: 12 | F14: =D14*E14 -> 862800 | G14: =F14*20% -> 172560
B15: 합계 | E15: =SUM(E6:E14) -> 141 | F15: =SUM(F6:F14) -> 6307900 | G15: =SUM(G6:G14) -> 1261580
A16: 카시트 | B16: 컬러: 블랙 세트 | D16: 99300 | E16: 6 | F16: =D16*E16 -> 595800 | G16: =F16*20% -> 119160
B17: 컬러: 블루 세트 | D17: 99300 | E17: 2 | F17: =D17*E17 -> 198600 | G17: =F17*20% -> 39720
B18: 컬러: 아이보리 세트 | D18: 99300 | E18: 5 | F18: =D18*E18 -> 496500 | G18: =F18*20% -> 99300
B19: 컬러: 오렌지 세트 | D19: 99300 | E19: 5 | F19: =D19*E19 -> 496500 | G19: =F19*20% -> 99300
B20: 컬러: 카키 세트 | D20: 99300 | E20: 5 | F20: =D20*E20 -> 496500 | G20: =F20*20% -> 99300
B21: 합계 | E21: =SUM(E16:E20) -> 23 | F21: =SUM(F16:F20) -> 2283900 | G21: =SUM(G16:G20) -> 456780
A22: 리쉬 | B22: 컬러: 베지프렌즈 / 길이: 1.2M | D22: 13300 | E22: 0 | F22: =D22*E22 -> 0 | G22: =F22*20% -> 0
B23: 컬러: 베지프렌즈 / 길이: 2M | D23: 15400 | E23: 0 | F23: =D23*E23 -> 0 | G23: =F23*20% -> 0
B24: 컬러: 체크라일락 / 길이: 1.2M | D24: 13300 | E24: 1 | F24: =D24*E24 -> 13300 | G24: =F24*20% -> 2660
B25: 컬러: 체크라일락 / 길이: 2M | D25: 15400 | E25: 0 | F25: =D25*E25 -> 0 | G25: =F25*20% -> 0
B26: 컬러: 체크레드 / 길이: 1.2M | D26: 13300 | E26: 6 | F26: =D26*E26 -> 79800 | G26: =F26*20% -> 15960
B27: 컬러: 체크레드 / 길이: 2M | D27: 15400 | E27: 2 | F27: =D27*E27 -> 30800 | G27: =F27*20% -> 6160
B28: 컬러: 체크블랙 / 길이: 1.2M | D28: 13300 | E28: 2 | F28: =D28*E28 -> 26600 | G28: =F28*20% -> 5320
B29: 컬러: 체크블랙 / 길이: 2M | D29: 15400 | E29: 1 | F29: =D29*E29 -> 15400 | G29: =F29*20% -> 3080
B30: 컬러: 체크블루 / 길이: 1.2M | D30: 13300 | E30: 1 | F30: =D30*E30 -> 13300 | G30: =F30*20% -> 2660
B31: 컬러: 체크블루 / 길이: 2M | D31: 15400 | E31: 1 | F31: =D31*E31 -> 15400 | G31: =F31*20% -> 3080
B32: 컬러: 체크옐로우 / 길이: 1.2M | D32: 13300 | E32: 0 | F32: =D32*E32 -> 0 | G32: =F32*20% -> 0
B33: 컬러: 체크옐로우 / 길이: 2M | D33: 15400 | E33: 1 | F33: =D33*E33 -> 15400 | G33: =F33*20% -> 3080
B34: 합계 | E34: =SUM(E22:E33) -> 15 | F34: =SUM(F22:F33) -> 210000 | G34: =SUM(G22:G33) -> 42000
A35: 목줄 | B35: 컬러: 베지프렌즈 / 사이즈: M | D35: 15400 | E35: 0 | F35: =D35*E35 -> 0 | G35: =F35*20% -> 0
B36: 컬러: 베지프렌즈 / 사이즈: S | D36: 15400 | E36: 0 | F36: =D36*E36 -> 0 | G36: =F36*20% -> 0
B37: 컬러: 체크라일락 / 사이즈: M | D37: 15400 | E37: 0 | F37: =D37*E37 -> 0 | G37: =F37*20% -> 0
B38: 컬러: 체크라일락 / 사이즈: S | D38: 15400 | E38: 0 | F38: =D38*E38 -> 0 | G38: =F38*20% -> 0
B39: 컬러: 체크레드 / 사이즈: M | D39: 15400 | E39: 2 | F39: =D39*E39 -> 30800 | G39: =F39*20% -> 6160
B40: 컬러: 체크레드 / 사이즈: S | D40: 15400 | E40: 4 | F40: =D40*E40 -> 61600 | G40: =F40*20% -> 12320
B41: 컬러: 체크블랙 / 사이즈: M | D41: 15400 | E41: 1 | F41: =D41*E41 -> 15400 | G41: =F41*20% -> 3080
...

Sheet DB) 스마트스토어(5월구매확정)
A1: 상품주문번호 | B1: 주문번호 | C1: 구매확정일 | D1: 판매채널 | E1: 주문상태 | F1: 구매자명 | G1: 구매자ID | H1: 수취인명 | I1: 발송처리일 | J1: 배송방법 | K1: 택배사 | L1: 송장번호 | M1: 배송완료일 | N1: 상품번호 | O1: 상품명 | P1: 상품종류 | Q1: 옵션정보 | R1: 수량 | S1: 상품가격 | T1: 옵션가격 | U1: 최종 상품별 할인액 | V1: 판매자 부담 할인액 | W1: 최종 상품별 총 주문금액
A2: 2026052664374771 | B2: 2026052682589631 | C2: 46173.637 | D2: 스마트스토어 | E2: 구매확정 | F2: 김예지 | G2: bog2****** | H2: 김예지 | I2: 46169.424 | J2: 택배,등기,소포 | K2: 로젠택배 | L2: 92235491832 | M2: 46170.687 | N2: 9927394880 | O2: [영이 공구x베럴즈] PAW PAW TOWEL 특가 | P2: 조합형옵션상품 | Q2: 배송일확인: 바로배송 | R2: 4 | S2: 9500 | T2: 0 | U2: 8360 | V2: 8360 | W2: 29640
A3: 2026052175612981 | B3: 2026052158465231 | C3: 46173.05 | D3: 스마트스토어 | E3: 구매확정 | F3: 허지원 | G3: apfh*** | H3: 허지원 | I3: 46164.445 | J3: 택배,등기,소포 | K3: 로젠택배 | L3: 92235371196 | M3: 46165.679 | N3: 9927394880 | O3: [영이 공구x베럴즈] PAW PAW TOWEL 특가 | P3: 조합형옵션상품 | Q3: 배송일확인: 바로배송 | R3: 4 | S3: 9500 | T3: 0 | U3: 8360 | V3: 8360 | W3: 29640
A4: 2026052296095641 | B4: 2026052272120921 | C4: 46173.05 | D4: 스마트스토어 | E4: 구매확정 | F4: 김소형 | G4: xiah****** | H4: 김소형 | I4: 46164.445 | J4: 택배,등기,소포 | K4: 로젠택배 | L4: 92235371233 | M4: 46165.547 | N4: 9927394880 | O4: [영이 공구x베럴즈] PAW PAW TOWEL 특가 | P4: 조합형옵션상품 | Q4: 배송일확인: 바로배송 | R4: 6 | S4: 9500 | T4: 0 | U4: 19980 | V4: 19980 | W4: 37020
A5: 2026052231381941 | B5: 2026052289222291 | C5: 46172.945 | D5: 스마트스토어 | E5: 구매확정 | F5: 최현석 | G5: mase**** | H5: 김민소 | I5: 46168.438 | J5: 택배,등기,소포 | K5: 로젠택배 | L5: 92235430140 | M5: 46169.553 | N5: 9927394880 | O5: [영이 공구x베럴즈] PAW PAW TOWEL 특가 | P5: 조합형옵션상품 | Q5: 배송일확인: 바로배송 | R5: 4 | S5: 9500 | T5: 0 | U5: 8360 | V5: 8360 | W5: 29640
A6: 2026052526640271 | B6: 2026052557728981 | C6: 46172.873 | D6: 스마트스토어 | E6: 구매확정 | F6: 이은진 | G6: fh**** | H6: 이은진 | I6: 46168.438 | J6: 택배,등기,소포 | K6: 로젠택배 | L6: 92235430420 | M6: 46169.689 | N6: 9927394880 | O6: [영이 공구x베럴즈] PAW PAW TOWEL 특가 | P6: 조합형옵션상품 | Q6: 배송일확인: 바로배송 | R6: 6 | S6: 9500 | T6: 0 | U6: 19980 | V6: 19980 | W6: 37020
A7: 2026052466525681 | B7: 2026052423483081 | C7: 46172.535 | D7: 스마트스토어 | E7: 구매확정 | F7: 박수연 | G7: soos****** | H7: 박수연 | I7: 46168.438 | J7: 택배,등기,소포 | K7: 로젠택배 | L7: 92235430254 | M7: 46169.97 | N7: 9927394880 | O7: [영이 공구x베럴즈] PAW PAW TOWEL 특가 | P7: 조합형옵션상품 | Q7: 배송일확인: 바로배송 | R7: 6 | S7: 9500 | T7: 0 | U7: 19980 | V7: 19980 | W7: 37020
A8: 2026052163146041 | B8: 2026052150281731 | C8: 46172.104 | D8: 스마트스토어 | E8: 구매확정 | F8: 이하은 | G8: haeu**** | H8: 이하은 | I8: 46163.632 | J8: 택배,등기,소포 | K8: 로젠택배 | L8: 92235353766 | M8: 46164.551 | N8: 9927394880 | O8: 드라잉타올추가 (정가 27000원): 1개 | P8: 추가구성상품 | Q8: 드라잉타올추가 (정가 27000원): 1개 | R8: 1 | S8: 21060 | T8: 0 | U8: 0 | V8: 0 | W8: 21060
A9: 2026052163146031 | B9: 2026052150281731 | C9: 46172.104 | D9: 스마트스토어 | E9: 구매확정 | F9: 이하은 | G9: haeu**** | H9: 이하은 | I9: 46163.632 | J9: 택배,등기,소포 | K9: 로젠택배 | L9: 92235353766 | M9: 46164.551 | N9: 9927394880 | O9: [영이 공구x베럴즈] PAW PAW TOWEL 특가 | P9: 조합형옵션상품 | Q9: 배송일확인: 바로배송 | R9: 1 | S9: 9500 | T9: 0 | U9: 2090 | V9: 2090 | W9: 7410
A10: 2026052158835531 | B10: 2026052147463841 | C10: 46172.104 | D10: 스마트스토어 | E10: 구매확정 | F10: 조나영 | G10: rene******* | H10: 조나영 | I10: 46163.632 | J10: 택배,등기,소포 | K10: 로젠택배 | L10: 92235353836 | M10: 46164.468 | N10: 9927394880 | O10: [영이 공구x베럴즈] PAW PAW TOWEL 특가 | P10: 조합형옵션상품 | Q10: 배송일확인: 바로배송 | R10: 1 | S10: 9500 | T10: 0 | U10: 2090 | V10: 2090 | W10: 7410
A11: 2026052160478781 | B11: 2026052148543301 | C11: 46172.084 | D11: 스마트스토어 | E11: 구매확정 | F11: 김시연 | G11: tldu***** | H11: 김시연 | I11: 46163.632 | J11: 택배,등기,소포 | K11: 로젠택배 | L11: 92235353755 | M11: 46164.674 | N11: 9927394880 | O11: [영이 공구x베럴즈] PAW PAW TOWEL 특가 | P11: 조합형옵션상품 | Q11: 배송일확인: 바로배송 | R11: 2 | S11: 9500 | T11: 0 | U11: 4180 | V11: 4180 | W11: 14820
A12: 2026052046800421 | B12: 2026052039690491 | C12: 46172.06 | D12: 스마트스토어 | E12: 구매확정 | F12: 지민영 | G12: hell****** | H12: 지민영 | I12: 46163.445 | J12: 택배,등기,소포 | K12: 로젠택배 | L12: 92235330655 | M12: 46164.547 | N12: 9927394880 | O12: [영이 공구x베럴즈] PAW PAW TOWEL 특가 | P12: 조합형옵션상품 | Q12: 배송일확인: 바로배송 | R12: 1 | S12: 9500 | T12: 0 | U12: 2090 | V12: 2090 | W12: 7410
A13: 2026052151555531 | B13: 2026052142615801 | C13: 46172.052 | D13: 스마트스토어 | E13: 구매확정 | F13: 서지혜 | G13: sjh6**** | H13: 서지혜 | I13: 46163.445 | J13: 택배,등기,소포 | K13: 로젠택배 | L13: 92235330600 | M13: 46164.733 | N13: 9927394880 | O13: [영이 공구x베럴즈] PAW PAW TOWEL 특가 | P13: 조합형옵션상품 | Q13: 배송일확인: 바로배송 | R13: 2 | S13: 9500 | T13: 0 | U13: 4180 | V13: 4180 | W13: 14820
... A1249: 2026041563597381 | B1249: 2026041579071931 | C1249: 46143.303 | D1249: 스마트스토어 | E1249: 구매확정 | F1249: 윤은숙 | G1249: youn****** | H1249: 윤은숙 | I1249: 46140.634 | J1249: 택배,등기,소포 | K1249: 로젠택배 | L1249: 92234494240 | M1249: 46141.471 | N1249: 9927394880 | O1249: [영이 공구x베럴즈] PAW PAW TOWEL 특가 | P1249: 조합형옵션상품 | Q1249: 배송일확인: 2차: 예약배송 (약 3주 소요) | R1249: 6 | S1249: 9500 | T1249: 0 | U1249: 20080 | V1249: 20080 | W1249: 36920

Sheet DB) 콘디(5월배송완료)
A1: 주문번호 | B1: 주문일시 | C1: 결제일시(입금확인일) | D1: 주문자명 | E1: 주문상품명(옵션포함) | F1: 수량
A2: 20260429-0000131 | B2: 46141.481 | C2: 46141.481 | D2: 김보라 | E2: [영이공구특가 이벤트 상품] CONDY 접촉 냉감 쿨매트 듀라론 쿨링 블랭킷 (2컬러)(구성 선택=블루화이트 1개 + 블랙화이트 1개) | F2: 1
A3: 20260429-0000155 | B3: 46141.571 | C3: 46141.571 | D3: 김유진 | E3: [영이공구특가 이벤트 상품] CONDY 접촉 냉감 쿨매트 듀라론 쿨링 블랭킷 (2컬러)(구성 선택=블루화이트 1개) | F3: 1
A4: 20260430-0000112 | B4: 46142.616 | C4: 46142.616 | D4: 박하늘 | E4: [영이공구특가 이벤트 상품] CONDY 접촉 냉감 쿨매트 듀라론 쿨링 블랭킷 (2컬러)(구성 선택=블루화이트 1개 + 블랙화이트 1개) | F4: 1
A5: 20260430-0000123 | B5: 46142.649 | C5: 46142.649 | D5: 김청 | E5: [영이공구특가 이벤트 상품] CONDY 접촉 냉감 쿨매트 듀라론 쿨링 블랭킷 (2컬러)(구성 선택=블루화이트 1개) | F5: 1
A6: 20260501-0000011 | B6: 46143.112 | C6: 46143.112 | D6: 김세연 | E6: [영이공구특가 이벤트 상품] CONDY 접촉 냉감 쿨매트 듀라론 쿨링 블랭킷 (2컬러)(구성 선택=블루화이트 1개 + 블랙화이트 1개) | F6: 1
A7: 20260503-0000064 | B7: 46145.586 | C7: 46145.586 | D7: 박채원 | E7: [영이공구특가 이벤트 상품] CONDY 접촉 냉감 쿨매트 듀라론 쿨링 블랭킷 (2컬러)(구성 선택=블루화이트 1개) | F7: 1
A8: 20260503-0000109 | B8: 46145.973 | C8: 46145.973 | D8: 임채원 | E8: [영이공구특가 이벤트 상품] CONDY 접촉 냉감 쿨매트 듀라론 쿨링 블랭킷 (2컬러)(구성 선택=블루화이트 2개) | F8: 1
A9: 20260505-0000052 | B9: 46147.731 | C9: 46147.731 | D9: 권경연 | E9: [영이공구특가 이벤트 상품] CONDY 접촉 냉감 쿨매트 듀라론 쿨링 블랭킷 (2컬러)(구성 선택=블루화이트 1개 + 블랙화이트 1개) | F9: 1
A10: 20260505-0000067 | B10: 46147.748 | C10: 46147.748 | D10: 문보라 | E10: [영이공구특가 이벤트 상품] CONDY 접촉 냉감 쿨매트 듀라론 쿨링 블랭킷 (2컬러)(구성 선택=블루화이트 2개) | F10: 1
A11: 20260505-0000087 | B11: 46147.856 | C11: 46147.856 | D11: 심소라 | E11: [영이공구특가 이벤트 상품] CONDY 접촉 냉감 쿨매트 듀라론 쿨링 블랭킷 (2컬러)(구성 선택=블루화이트 1개) | F11: 1
A12: 20260506-0000216 | B12: 46148.975 | C12: 46148.975 | D12: 윤영경 | E12: [영이공구특가 이벤트 상품] CONDY 접촉 냉감 쿨매트 듀라론 쿨링 블랭킷 (2컬러)(구성 선택=블루화이트 1개 + 블랙화이트 1개) | F12: 1
A13: 20260507-0000011 | B13: 46149.012 | C13: 46149.012 | D13: 김윤서 | E13: [영이공구특가 이벤트 상품] CONDY 접촉 냉감 쿨매트 듀라론 쿨링 블랭킷 (2컬러)(구성 선택=블루화이트 1개) | F13: 1
... A98: 20260529-0000097 | B98: 46171.55 | C98: 46171.55 | D98: 김찬희 | E98: [영이공구특가 이벤트 상품] CONDY 접촉 냉감 쿨매트 듀라론 쿨링 블랭킷 (BLUE)(구성 선택=블루화이트 1개) | F98: 1

Sheet DB) 도톤(5월배송완료)
A1: 주문번호 | B1: 주문일시 | C1: 결제일시(입금확인일) | D1: 주문자명 | E1: 주문상품명(옵션포함) | F1: 수량
A2: 20260421-0000244 | B2: 46133.936 | C2: 46133.934 | D2: 임연주 | E2: [영이공구특가 이벤트 상품] 도톤 포레스트 아웃도어 해충방지 스프레이 150ml(수량=공구특가 1개 (25%할인)) | F2: 1
A3: 20260422-0000092 | B3: 46134.483 | C3: 46134.48 | D3: 이한슬 | E3: [영이공구특가 이벤트 상품] 도톤 포레스트 아웃도어 해충방지 스프레이 150ml(수량=공구특가 1개 (25%할인)) | F3: 1
A4: 20260423-0000261 | B4: 46135.936 | C4: 46135.934 | D4: 김규희 | E4: [영이공구특가 이벤트 상품] 도톤 포레스트 아웃도어 해충방지 스프레이 150ml(수량=공구 2개세트 (32%할인)) | F4: 1
A5: 20260424-0000051 | B5: 46136.413 | C5: 46136.411 | D5: 채보민 | E5: [영이공구특가 이벤트 상품] 도톤 포레스트 아웃도어 해충방지 스프레이 150ml(수량=공구 2개세트 (32%할인)) | F5: 1
A6: 20260426-0000011 | B6: 46138.142 | C6: 46138.14 | D6: 김예지 | E6: [영이공구특가 이벤트 상품] 도톤 포레스트 아웃도어 해충방지 스프레이 150ml(수량=공구 2개세트 (32%할인)) | F6: 1
A7: 20260426-0000221 | B7: 46138.937 | C7: 46138.934 | D7: 이지은 | E7: [영이공구특가 이벤트 상품] 도톤 포레스트 아웃도어 해충방지 스프레이 150ml(수량=공구 2개세트 (32%할인)) | F7: 1
A8: 20260429-0000122 | B8: 46141.441 | C8: 46141.438 | D8: 정해진 | E8: [영이공구특가 이벤트 상품] 도톤 포레스트 아웃도어 해충방지 스프레이 150ml(수량=공구특가 1개 (25%할인)) | F8: 1
A9: 20260429-0000187 | B9: 46141.637 | C9: 46141.634 | D9: 최진솔 | E9: [영이공구특가 이벤트 상품] 도톤 포레스트 아웃도어 해충방지 스프레이 150ml(수량=공구 2개세트 (32%할인)) | F9: 1
A10: 20260501-0000079 | B10: 46143.605 | C10: 46143.602 | D10: 박혜은 | E10: [영이공구특가 이벤트 상품] 도톤 포레스트 아웃도어 해충방지 스프레이 150ml(수량=공구특가 1개 (25%할인)) | F10: 1
A11: 20260502-0000061 | B11: 46144.922 | C11: 46144.922 | D11: 서은경 | E11: [영이공구특가 이벤트 상품] 도톤 포레스트 아웃도어 해충방지 스프레이 150ml(수량=공구특가 1개 (25%할인)) | F11: 1
A12: 20260503-0000075 | B12: 46145.825 | C12: 46145.823 | D12: 한수정 | E12: [영이공구특가 이벤트 상품] 도톤 포레스트 아웃도어 해충방지 스프레이 150ml(수량=공구특가 1개 (25%할인)) | F12: 1
A13: 20260504-0000065 | B13: 46146.539 | C13: 46146.537 | D13: 인나엽 | E13: [영이공구특가 이벤트 상품] 도톤 포레스트 아웃도어 해충방지 스프레이 150ml(수량=공구 2개세트 (32%할인)) | F13: 1
... A38: 20260524-0000035 | B38: 46166.672 | C38: 46166.672 | D38: 한주연 | E38: [영이공구특가 이벤트 상품] 도톤 포레스트 아웃도어 해충방지 스프레이 150ml(수량=공구 3개세트 (36%할인)) | F38: 1
