Workbook

Sheet 공구영수증
B7: 문서번호 | C7: W-20260511-1 | F7: 주식회사 우프컴퍼니 (314-87-00725)
B8: 날짜 | C8: =today() -> 46153 | F8: 서울 용산구 한남대로8길 6-17, 1F
B9: 문서제목 | C9: 영이공구 (2026.04) 판매 내역 정산 | F9: 대표자명 | G9: 이교영 (인)
B10: 수신 | C10: 안진양 대표님 (영이공구) | F10: team@wooof.co.kr
B13: 1. 귀사의 무궁한 발전과 건승을 기원합니다.
B14: 2. 아래와 같이 판매의 내역을 공유드리며, 확인 후 이상이 없으신 경우 지급처리를 위한 전자계산서 발행을 요청드립니다.
D16: - 아 래 -
B18: 품목 | C18: 세부항목 | E18: 진행기간 | F18: 판매금액 | G18: 공구수수료 | H18: 합계
B19: 4월 판매액 | C19: 베럴즈 아웃도어대전 카시트 및 스텝온옵션 | E19: 4/9 - 4/19 | F19: ='판매내역집계'!F21+'판매내역집계'!F59 -> 4837800 | G19: 0.2 | H19: =F19*G19 -> 967560
C20: 베럴즈 아웃도어대전 산책용품 (목줄/리쉬) | E20: 4/9 - 4/19 | F20: ='판매내역집계'!F47+'판매내역집계'!F34 -> 3238200 | G20: 0.2 | H20: =F20*G20 -> 647640
C21: 베럴즈 아웃도어대전 이케코백 | E21: 4/9 - 4/19 | F21: ='판매내역집계'!F54 -> 5349750 | G21: 0.2 | H21: =F21*G21 -> 1069950
C22: 베럴즈 아웃도어대전 포포타올 | E22: 4/9 - 진행중 | F22: ='판매내역집계'!F57 -> 2767420 | G22: 0.2 | H22: =F22*G22 -> 553484
C23: 콘디 냉감블랭킷 공구 | E23: 4/3 - 진행중 | F23: ='판매내역집계'!F15 -> 35464900 | G23: 0.2 | H23: =F23*G23 -> 7092980
C24: 도톤 아웃도어 스프레이 공구 | E24: 4/13 - 진행중 | F24: ='판매내역집계'!F63 -> 3680500 | G24: 0.2 | H24: =F24*G24 -> 736100
C25: 합계 | F25: =SUM(F19:F24) -> 55338570 | H25: =SUM(H19:H24) -> 11067714
B27: 품목 | C27: 세부항목 | F27: 지출광고비 | G27: 부담비용 | H27: 합계
B28: 4월 광고비 정산 | C28: 카시트 광고비 | F28: 395313 | G28: 0.5 | H28: =F28*G28 -> 197656.5
C29: 포포타올 광고비 | F29: 264859 | G29: 0.5 | H29: =F29*G29 -> 132429.5
C30: 합계 | F30: =SUM(F28) -> 395313 | H30: =SUM(H28:H29) -> 330086
F32: 판매수수료 합계 | H32: =H25 -> 11067714
F33: 광고비 공제(-) | H33: =H30 -> 330086
E35: 총 합계액 (부가세 포함) | H35: =H32-H33 -> 10737628
B37: * 4/1-4/30 배송완료 내역 및 구매확정(스마트스토어) 내역 기준입니다.
B38: * 4/30 일 기준으로 매출 세금계산서 정발행해 주시면 익월 15일 까지 지정된 계좌로 지급 예정입니다.

Sheet 판매내역집계
A1: 202604 | B1: 영이공구 판매내역 집계
B2: 스마트스토어 : 4/1-4/30 [구매확정] 기준 집계
B3: 우프자사몰 : 4/1-4/30 [배송완료] 기준 집계
A5: 제품 | B5: 구매옵션 | C5: 정상가 | D5: 공구판매가 | E5: 판매수량 | F5: 공구매출계 | G5: 공구수수료
A6: 콘디 | B6: 블루화이트 1개 | C6: 32300 | D6: 26900 | E6: 230 | F6: =D6*E6 -> 6187000 | G6: =F6*20% -> 1237400
B7: 블루화이트 2개 | C7: =32300*2 -> 64600 | D7: 51900 | E7: 56 | F7: =D7*E7 -> 2906400 | G7: =F7*20% -> 581280
B8: 블루화이트 3개 | C8: =32300*3 -> 96900 | D8: 71900 | E8: 17 | F8: =D8*E8 -> 1222300 | G8: =F8*20% -> 244460
B9: 블랙화이트 1개 | C9: 32300 | D9: 26900 | E9: 151 | F9: =D9*E9 -> 4061900 | G9: =F9*20% -> 812380
B10: 블랙화이트 2개 | C10: =32300*2 -> 64600 | D10: 51900 | E10: 37 | F10: =D10*E10 -> 1920300 | G10: =F10*20% -> 384060
B11: 블랙화이트 3개 | C11: =32300*3 -> 96900 | D11: 71900 | E11: 14 | F11: =D11*E11 -> 1006600 | G11: =F11*20% -> 201320
B12: 블루화이트 1개 + 블랙화이트 1개 | C12: =32300*2 -> 64600 | D12: 51900 | E12: 228 | F12: =D12*E12 -> 11833200 | G12: =F12*20% -> 2366640
B13: 블루화이트 2개 + 블랙화이트 1개 | C13: =32300*3 -> 96900 | D13: 71900 | E13: 46 | F13: =D13*E13 -> 3307400 | G13: =F13*20% -> 661480
B14: 블루화이트 1개 + 블랙화이트 2개 | C14: =32300*3 -> 96900 | D14: 71900 | E14: 42 | F14: =D14*E14 -> 3019800 | G14: =F14*20% -> 603960
B15: 합계 | E15: =SUM(E6:E14) -> 821 | F15: =SUM(F6:F14) -> 35464900 | G15: =SUM(G6:G14) -> 7092980
A16: 카시트 | B16: 컬러: 블랙 세트 | C16: 129000 | D16: 99300 | E16: 3 | F16: =D16*E16 -> 297900 | G16: =F16*20% -> 59580
B17: 컬러: 블루 세트 | C17: 129000 | D17: 99300 | E17: 8 | F17: =D17*E17 -> 794400 | G17: =F17*20% -> 158880
B18: 컬러: 아이보리 세트 | C18: 129000 | D18: 99300 | E18: 11 | F18: =D18*E18 -> 1092300 | G18: =F18*20% -> 218460
B19: 컬러: 오렌지 세트 | C19: 129000 | D19: 99300 | E19: 15 | F19: =D19*E19 -> 1489500 | G19: =F19*20% -> 297900
B20: 컬러: 카키 세트 | C20: 129000 | D20: 99300 | E20: 9 | F20: =D20*E20 -> 893700 | G20: =F20*20% -> 178740
B21: 합계 | E21: =SUM(E16:E20) -> 46 | F21: =SUM(F16:F20) -> 4567800 | G21: =SUM(G16:G20) -> 913560
A22: 리쉬 | B22: 컬러: 베지프렌즈 / 길이: 1.2M | C22: 19000 | D22: 13300 | E22: 6 | F22: =D22*E22 -> 79800 | G22: =F22*20% -> 15960
B23: 컬러: 베지프렌즈 / 길이: 2M | C23: 22000 | D23: 15400 | E23: 6 | F23: =D23*E23 -> 92400 | G23: =F23*20% -> 18480
B24: 컬러: 체크라일락 / 길이: 1.2M | C24: 19000 | D24: 13300 | E24: 11 | F24: =D24*E24 -> 146300 | G24: =F24*20% -> 29260
B25: 컬러: 체크라일락 / 길이: 2M | C25: 22000 | D25: 15400 | E25: 7 | F25: =D25*E25 -> 107800 | G25: =F25*20% -> 21560
B26: 컬러: 체크레드 / 길이: 1.2M | C26: 19000 | D26: 13300 | E26: 16 | F26: =D26*E26 -> 212800 | G26: =F26*20% -> 42560
B27: 컬러: 체크레드 / 길이: 2M | C27: 22000 | D27: 15400 | E27: 9 | F27: =D27*E27 -> 138600 | G27: =F27*20% -> 27720
B28: 컬러: 체크블랙 / 길이: 1.2M | C28: 19000 | D28: 13300 | E28: 14 | F28: =D28*E28 -> 186200 | G28: =F28*20% -> 37240
B29: 컬러: 체크블랙 / 길이: 2M | C29: 22000 | D29: 15400 | E29: 13 | F29: =D29*E29 -> 200200 | G29: =F29*20% -> 40040
B30: 컬러: 체크블루 / 길이: 1.2M | C30: 19000 | D30: 13300 | E30: 10 | F30: =D30*E30 -> 133000 | G30: =F30*20% -> 26600
B31: 컬러: 체크블루 / 길이: 2M | C31: 22000 | D31: 15400 | E31: 7 | F31: =D31*E31 -> 107800 | G31: =F31*20% -> 21560
B32: 컬러: 체크옐로우 / 길이: 1.2M | C32: 19000 | D32: 13300 | E32: 7 | F32: =D32*E32 -> 93100 | G32: =F32*20% -> 18620
B33: 컬러: 체크옐로우 / 길이: 2M | C33: 22000 | D33: 15400 | E33: 6 | F33: =D33*E33 -> 92400 | G33: =F33*20% -> 18480
B34: 합계 | E34: =SUM(E22:E33) -> 112 | F34: =SUM(F22:F33) -> 1590400 | G34: =SUM(G22:G33) -> 318080
A35: 목줄 | B35: 컬러: 베지프렌즈 / 사이즈: M | C35: 22000 | D35: 15400 | E35: 3 | F35: =D35*E35 -> 46200 | G35: =F35*20% -> 9240
B36: 컬러: 베지프렌즈 / 사이즈: S | C36: 22000 | D36: 15400 | E36: 8 | F36: =D36*E36 -> 123200 | G36: =F36*20% -> 24640
B37: 컬러: 체크라일락 / 사이즈: M | C37: 22000 | D37: 15400 | E37: 8 | F37: =D37*E37 -> 123200 | G37: =F37*20% -> 24640
B38: 컬러: 체크라일락 / 사이즈: S | C38: 22000 | D38: 15400 | E38: 8 | F38: =D38*E38 -> 123200 | G38: =F38*20% -> 24640
B39: 컬러: 체크레드 / 사이즈: M | C39: 22000 | D39: 15400 | E39: 11 | F39: =D39*E39 -> 169400 | G39: =F39*20% -> 33880
B40: 컬러: 체크레드 / 사이즈: S | C40: 22000 | D40: 15400 | E40: 16 | F40: =D40*E40 -> 246400 | G40: =F40*20% -> 49280
B41: 컬러: 체크블랙 / 사이즈: M | C41: 22000 | D41: 15400 | E41: 8 | F41: =D41*E41 -> 123200 | G41: =F41*20% -> 24640
...

Sheet 광고비용 집계
A2: 행 레이블 | B2: 합계 : 지출 금액 (KRW) | C2: 합계 | D2: 합계 (50%)
A3: 카시트 광고 01 | B3: 106282 | C3: 395413 | D3: =C3/2 -> 197706.5
A4: 카시트 광고 02 | B4: 104434
A5: 카시트 광고 03 | B5: 184697
A6: 포포타올 | B6: 264859 | C6: 264859 | D6: =C6/2 -> 132429.5
A7: 총합계 | B7: 660272 | C7: 660272 | D7: =SUM(D3:D6) -> 330136
A12: 보고 시작 | B12: 보고 종료 | C12: 광고 이름 | D12: 지출 금액 (KRW) | E12: 노출 | F12: CPM(1,000회 노출당 비용) (KRW) | G12: 도달 | H12: 빈도 | I12: CTR(전체) | J12: 링크 클릭 | K12: CPC(전체) (KRW)
A13: 46113 | B13: 46113 | C13: 카시트 광고 01 | D13: - | E13: - | F13: - | G13: - | H13: - | I13: - | K13: -
A14: 46113 | B14: 46113 | C14: 포포타올 | D14: - | E14: - | F14: - | G14: - | H14: - | I14: - | K14: -
A15: 46113 | B15: 46113 | C15: 카시트 광고 02 | D15: - | E15: - | F15: - | G15: - | H15: - | I15: - | K15: -
A16: 46113 | B16: 46113 | C16: 카시트 광고 03 | D16: - | E16: - | F16: - | G16: - | H16: - | I16: - | K16: -
A17: 46113 | B17: 46113 | C17: 카시트 광고 03 | D17: - | E17: - | F17: - | G17: - | H17: - | I17: - | K17: -
A18: 46114 | B18: 46114 | C18: 카시트 광고 01 | D18: - | E18: - | F18: - | G18: - | H18: - | I18: - | K18: -
A19: 46114 | B19: 46114 | C19: 포포타올 | D19: - | E19: - | F19: - | G19: - | H19: - | I19: - | K19: -
A20: 46114 | B20: 46114 | C20: 카시트 광고 02 | D20: - | E20: - | F20: - | G20: - | H20: - | I20: - | K20: -
A21: 46114 | B21: 46114 | C21: 카시트 광고 03 | D21: - | E21: - | F21: - | G21: - | H21: - | I21: - | K21: -
A22: 46114 | B22: 46114 | C22: 카시트 광고 03 | D22: - | E22: - | F22: - | G22: - | H22: - | I22: - | K22: -
A23: 46115 | B23: 46115 | C23: 카시트 광고 01 | D23: - | E23: - | F23: - | G23: - | H23: - | I23: - | K23: -
A24: 46115 | B24: 46115 | C24: 포포타올 | D24: - | E24: - | F24: - | G24: - | H24: - | I24: - | K24: -
... A61: 46122 | B61: 46122 | C61: 카시트 광고 03 | D61: - | E61: - | F61: - | G61: - | H61: - | I61: - | K61: -
A62: 46122 | B62: 46122 | C62: 카시트 광고 03 | D62: 7536 | E62: 1248 | F62: 6038 | G62: 1248 | H62: 1 | I62: 5 | J62: 55 | K62: 114
A63: 46123 | B63: 46123 | C63: 카시트 광고 01 | D63: - | E63: - | F63: - | G63: - | H63: - | I63: - | K63: -
A64: 46123 | B64: 46123 | C64: 포포타올 | D64: - | E64: - | F64: - | G64: - | H64: - | I64: - | K64: -
A65: 46123 | B65: 46123 | C65: 카시트 광고 02 | D65: - | E65: - | F65: - | G65: - | H65: - | I65: - | K65: -
A66: 46123 | B66: 46123 | C66: 카시트 광고 03 | D66: - | E66: - | F66: - | G66: - | H66: - | I66: - | K66: -
A67: 46123 | B67: 46123 | C67: 카시트 광고 03 | D67: 17312 | E67: 2722 | F67: 6360 | G67: 2619 | H67: 1 | I67: 8 | J67: 188 | K67: 75
A68: 46124 | B68: 46124 | C68: 카시트 광고 01 | D68: - | E68: - | F68: - | G68: - | H68: - | I68: - | K68: -
A69: 46124 | B69: 46124 | C69: 포포타올 | D69: - | E69: - | F69: - | G69: - | H69: - | I69: - | K69: -
A70: 46124 | B70: 46124 | C70: 카시트 광고 02 | D70: - | E70: - | F70: - | G70: - | H70: - | I70: - | K70: -
A71: 46124 | B71: 46124 | C71: 카시트 광고 03 | D71: 5237 | E71: 506 | F71: 10350 | G71: 473 | H71: 1 | I71: 5 | J71: 23 | K71: 228
A72: 46124 | B72: 46124 | C72: 카시트 광고 03 | D72: 16044 | E72: 2865 | F72: 5600 | G72: 2805 | H72: 1 | I72: 10 | J72: 243 | K72: 57
A73: 46125 | B73: 46125 | C73: 카시트 광고 01 | D73: - | E73: - | F73: - | G73: - | H73: - | I73: - | K73: -
A74: 46125 | B74: 46125 | C74: 포포타올 | D74: - | E74: - | F74: - | G74: - | H74: - | I74: - | K74: -
A75: 46125 | B75: 46125 | C75: 카시트 광고 02 | D75: - | E75: - | F75: - | G75: - | H75: - | I75: - | K75: -
A76: 46125 | B76: 46125 | C76: 카시트 광고 03 | D76: 182 | E76: 25 | F76: 7280 | G76: 24 | H76: 1 | I76: - | K76: -
A77: 46125 | B77: 46125 | C77: 카시트 광고 03 | D77: 19644 | E77: 2662 | F77: 7379 | G77: 2575 | H77: 1 | I77: 6 | J77: 143 | K77: 116
A78: 46126 | B78: 46126 | C78: 카시트 광고 01 | D78: - | E78: - | F78: - | G78: - | H78: - | I78: - | K78: -
A79: 46126 | B79: 46126 | C79: 포포타올 | D79: - | E79: - | F79: - | G79: - | H79: - | I79: - | K79: -
A80: 46126 | B80: 46126 | C80: 카시트 광고 02 | D80: - | E80: - | F80: - | G80: - | H80: - | I80: - | K80: -
A81: 46126 | B81: 46126 | C81: 카시트 광고 03 | D81: - | E81: - | F81: - | G81: - | H81: - | I81: - | K81: -
...

Sheet DB) 스마트스토어(4월구매확정)
A1: 상품주문번호 | B1: 주문번호 | C1: 구매확정일 | D1: 판매채널 | E1: 주문상태 | F1: 구매자명 | G1: 구매자ID | H1: 수취인명 | I1: 발송처리일 | J1: 배송방법 | K1: 택배사 | L1: 송장번호 | M1: 배송완료일 | N1: 상품번호 | O1: 상품명 | P1: 상품종류 | Q1: 옵션정보 | R1: 수량 | S1: 상품가격 | T1: 옵션가격 | U1: 최종 상품별 할인액 | V1: 판매자 부담 할인액 | W1: 최종 상품별 총 주문금액 | X1: 판매자 상품코드 | Y1: 판매자 내부코드1 | Z1: 판매자 내부코드2 | AA1: 배송비 묶음번호 | AB1: 배송비 형태 | AC1: 배송비 유형 | AD1: 배송비 합계 | AE1: 제주/도서 추가배송비 | AF1: 배송비 할인액 | AG1: 결제일 | AH1: 결제수단 | AI1: 결제위치 | AJ1: 네이버페이 주문관리 수수료 | AK1: 매출연동 수수료 | AL1: 정산예정금액
A2: 2026041934753031 | B2: 2026041989633841 | C2: 2026.04.30 21:55 | D2: 스마트스토어 | E2: 구매확정 | F2: 윤성희 | G2: 1zzz*** | H2: 윤성희 | I2: 2026.04.29 15:21 | J2: 택배,등기,소포 | K2: 로젠택배 | L2: 92234560191 | M2: 2026.04.30 11:14 | N2: 9928170688 | O2: 카시트 스텝온 추가: 추가 | P2: 추가구성상품 | Q2: 카시트 스텝온 추가: 추가 | R2: 1 | S2: \15,000 | T2: \0 | U2: \0 | V2: \0 | W2: \15,000 | AA2: 2026041994677638 | AB2: 무료 | AC2: 무료 | AD2: \0 | AE2: \0 | AF2: \0 | AG2: ######## | AH2: 신용카드 간편결제 | AI2: MOBILE | AJ2: -409 | AK2: -150 | AL2: \14,441
A3: 2026041934753021 | B3: 2026041989633841 | C3: 2026.04.30 21:55 | D3: 스마트스토어 | E3: 구매확정 | F3: 윤성희 | G3: 1zzz*** | H3: 윤성희 | I3: 2026.04.29 15:21 | J3: 택배,등기,소포 | K3: 로젠택배 | L3: 92234560191 | M3: 2026.04.30 11:14 | N3: 9928170688 | O3: [영이 공구x베럴즈] 강아지 카시트 세트 5종 특가 | P3: 조합형옵션상품 | Q3: 컬러: 아이보리 세트 | R3: 1 | S3: \129,000 | T3: \0 | U3: \29,700 | V3: \29,700 | W3: \99,300 | AA3: 2026041994677638 | AB3: 무료 | AC3: 무료 | AD3: \0 | AE3: \0 | AF3: \0 | AG3: ######## | AH3: 신용카드 간편결제 | AI3: MOBILE | AJ3: -2708 | AK3: -993 | AL3: \95,599
A4: 2026041456562591 | B4: 2026041474568991 | C4: 2026.04.30 18:58 | D4: 스마트스토어 | E4: 구매확정 | F4: 박서영 | G4: hiki**** | H4: 박서영 | I4: 2026.04.28 15:12 | J4: 택배,등기,소포 | K4: 로젠택배 | L4: 92234495581 | M4: 2026.04.29 12:00 | N4: 9927394880 | O4: [영이 공구x베럴즈] PAW PAW TOWEL 특가 | P4: 조합형옵션상품 | Q4: 1~5개 | R4: 1 | S4: \9,500 | T4: \0 | U4: \2,190 | V4: \2,190 | W4: \7,310 | AA4: 2026041482888987 | AB4: 선결제 | AC4: 조건부무료 | AD4: \3,000 | AE4: \0 | AF4: \0 | AG4: ######## | AH4: 신용카드 간편결제 | AI4: MOBILE | AJ4: -199 | AK4: -73 | AL4: \7,038
A5: 2026041564766931 | B5: 2026041579890581 | C5: 2026.04.30 06:15 | D5: 스마트스토어 | E5: 구매확정 | F5: 허수민 | G5: rryo***** | H5: 허 수민 | I5: 2026.04.28 15:12 | J5: 택배,등기,소포 | K5: 로젠택배 | L5: 92234495474 | M5: 2026.04.29 09:40 | N5: 9927394880 | O5: [영이 공구x베럴즈] PAW PAW TOWEL 특가 | P5: 조합형옵션상품 | Q5: 1~5개 | R5: 1 | S5: \9,500 | T5: \0 | U5: \2,190 | V5: \2,190 | W5: \7,310 | AA5: 2026041583909495 | AB5: 선결제 | AC5: 조건부무료 | AD5: \3,000 | AE5: \0 | AF5: \0 | AG5: ######## | AH5: 신용카드 간편결제 | AI5: MOBILE | AJ5: -199 | AK5: -73 | AL5: \7,038
A6: 2026041569265811 | B6: 2026041582875271 | C6: 2026.04.29 22:16 | D6: 스마트스토어 | E6: 구매확정 | F6: Lum Hiu Ching | G6: iamx*** | H6: Lum Hiu Ching | I6: 2026.04.28 15:12 | J6: 택배,등기,소포 | K6: 로젠택배 | L6: 92234495415 | M6: 2026.04.29 11:24 | N6: 9927394880 | O6: [영이 공구x베럴즈] PAW PAW TOWEL 특가 | P6: 조합형옵션상품 | Q6: 1~5개 | R6: 1 | S6: \9,500 | T6: \0 | U6: \2,190 | V6: \2,190 | W6: \7,310 | AA6: 2026041584463729 | AB6: 선결제 | AC6: 조건부무료 | AD6: \3,000 | AE6: \0 | AF6: \0 | AG6: ######## | AH6: 신용카드 간편결제 | AI6: MOBILE | AJ6: -199 | AK6: -73 | AL6: \7,038
A7: 2026041452016561 | B7: 2026041471662491 | C7: 2026.04.24 03:16 | D7: 스마트스토어 | E7: 구매확정 | F7: 전은화 | G7: jeon******** | H7: 전은화 | I7: 2026.04.15 18:33 | J7: 택배,등기,소포 | K7: 로젠택배 | L7: 92234045901 | M7: 2026.04.16 16:17 | N7: 9927394880 | O7: [영이 공구x베럴즈] PAW PAW TOWEL 특가 | P7: 단일상품 | Q7: 1~5개 | R7: 1 | S7: \9,500 | T7: \0 | U7: \2,190 | V7: \2,190 | W7: \7,310 | AA7: 2026041482330948 | AB7: 선결제 | AC7: 조건부무료 | AD7: \3,000 | AE7: \0 | AF7: \0 | AG7: ######## | AH7: 신용카드 간편결제 | AI7: MOBILE | AJ7: -198 | AK7: -219 | AL7: \6,893
A8: 2026041454764451 | B8: 2026041473435981 | C8: 2026.04.24 03:11 | D8: 스마트스토어 | E8: 구매확정 | F8: 허은옥 | G8: wu**** | H8: 허은옥 | I8: 2026.04.15 18:33 | J8: 택배,등기,소포 | K8: 로젠택배 | L8: 92234045864 | M8: 2026.04.16 16:20 | N8: 9927394880 | O8: [영이 공구x베럴즈] PAW PAW TOWEL 특가 | P8: 조합형옵션상품 | Q8: 1~5개 | R8: 1 | S8: \9,500 | T8: \0 | U8: \2,090 | V8: \2,090 | W8: \7,410 | AA8: 2026041482671153 | AB8: 선결제 | AC8: 조건부무료 | AD8: \3,000 | AE8: \0 | AF8: \0 | AG8: ######## | AH8: 신용카드 간편결제 | AI8: MOBILE | AJ8: -201 | AK8: -74 | AL8: \7,135
A9: 2026041448145611 | B9: 2026041469065501 | C9: 2026.04.24 02:41 | D9: 스마트스토어 | E9: 구매확정 | F9: 지은이 | G9: wldm******* | H9: 지은이 | I9: 2026.04.15 18:33 | J9: 택배,등기,소포 | K9: 로젠택배 | L9: 92234045923 | M9: 2026.04.16 13:15 | N9: 9927394880 | O9: [영이 공구x베럴즈] PAW PAW TOWEL 특가 | P9: 단일상품 | Q9: 1~5개 | R9: 1 | S9: \9,500 | T9: \0 | U9: \2,090 | V9: \2,090 | W9: \7,410 | AA9: 2.0260415e+15 | AB9: 선결제 | AC9: 조건부무료 | AD9: \3,000 | AE9: \0 | AF9: \0 | AG9: ######## | AH9: 신용카드 간편결제 | AI9: MOBILE | AJ9: -202 | AK9: -74 | AL9: \7,134
A10: 2026041451836401 | B10: 2026041471546751 | C10: 2026.04.24 02:39 | D10: 스마트스토어 | E10: 구매확정 | F10: 김샛별 | G10: ksb9*** | H10: 김샛별 | I10: 2026.04.15 18:33 | J10: 택배,등기,소포 | K10: 로젠택배 | L10: 92234045912 | M10: 2026.04.16 13:10 | N10: 9927394880 | O10: [영이 공구x베럴즈] PAW PAW TOWEL 특가 | P10: 단일상품 | Q10: 1~5개 | R10: 1 | S10: \9,500 | T10: \0 | U10: \2,090 | V10: \4,180 | W10: \7,410 | AA10: 2026041482310085 | AB10: 선결제 | AC10: 조건부무료 | AD10: \3,000 | AE10: \0 | AF10: \0 | AG10: ######## | AH10: 신용카드 | AI10: MOBILE | AJ10: -201 | AK10: -74 | AL10: \7,135
A11: 2026041454163981 | B11: 2026041473059111 | C11: 2026.04.24 02:39 | D11: 스마트스토어 | E11: 구매확정 | F11: 강혜진 | G11: kkan****** | H11: 강혜진 | I11: 2026.04.15 18:33 | J11: 택배,등기,소포 | K11: 로젠택배 | L11: 92234045875 | M11: 2026.04.16 13:15 | N11: 9927394880 | O11: [영이 공구x베럴즈] PAW PAW TOWEL 특가 | P11: 조합형옵션상품 | Q11: 1~5개 | R11: 1 | S11: \9,500 | T11: \0 | U11: \2,190 | V11: \2,190 | W11: \7,310 | AA11: 2026041482598466 | AB11: 선결제 | AC11: 조건부무료 | AD11: \3,000 | AE11: \0 | AF11: \0 | AG11: ######## | AH11: 신용카드 간편결제 | AI11: MOBILE | AJ11: -199 | AK11: -73 | AL11: \7,038
A12: 2026041453929791 | B12: 2026041472908131 | C12: 2026.04.24 02:39 | D12: 스마트스토어 | E12: 구매확정 | F12: 채혜진 | G12: asas**** | H12: 채혜진 | I12: 2026.04.15 18:33 | J12: 택배,등기,소포 | K12: 로젠택배 | L12: 92234045890 | M12: 2026.04.16 11:12 | N12: 9927394880 | O12: [영이 공구x베럴즈] PAW PAW TOWEL 특가 | P12: 조합형옵션상품 | Q12: 1~5개 | R12: 1 | S12: \9,500 | T12: \0 | U12: \2,190 | V12: \2,190 | W12: \7,310 | AA12: 2026041482569554 | AB12: 선결제 | AC12: 조건부무료 | AD12: \3,000 | AE12: \0 | AF12: \0 | AG12: ######## | AH12: 신용카드 간편결제 | AI12: MOBILE | AJ12: -199 | AK12: -73 | AL12: \7,038
A13: 2026041455334931 | B13: 2026041473796161 | C13: 2026.04.20 21:17 | D13: 스마트스토어 | E13: 구매확정 | F13: 이우빈 | G13: wobi*** | H13: 이우빈 | I13: 2026.04.15 18:33 | J13: 택배,등기,소포 | K13: 로젠택배 | L13: 92234045853 | M13: 2026.04.16 13:15 | N13: 9927394880 | O13: [영이 공구x베럴즈] PAW PAW TOWEL 특가 | P13: 조합형옵션상품 | Q13: 1~5개 | R13: 1 | S13: \9,500 | T13: \0 | U13: \2,090 | V13: \2,090 | W13: \7,410 | AA13: 2026041482739786 | AB13: 선결제 | AC13: 조건부무료 | AD13: \3,000 | AE13: \0 | AF13: \0 | AG13: ######## | AH13: 신용카드 간편결제 | AI13: MOBILE | AJ13: -202 | AK13: -74 | AL13: \7,134
A14: 2026041454085241 | B14: 2026041473007271 | C14: 2026.04.19 08:10 | D14: 스마트스토어 | E14: 구매확정 | F14: 심은영 | G14: cott**** | H14: 심은영 | I14: 2026.04.15 18:33 | J14: 택배,등기,소포 | K14: 로젠택배 | L14: 92234045886 | M14: 2026.04.16 12:45 | N14: 9927394880 | O14: [영이 공구x베럴즈] PAW PAW TOWEL 특가 | P14: 조합형옵션상품 | Q14: 1~5개 | R14: 1 | S14: \9,500 | T14: \0 | U14: \2,190 | V14: \2,190 | W14: \7,310 | AA14: 2026041482589189 | AB14: 선결제 | AC14: 조건부무료 | AD14: \3,000 | AE14: \0 | AF14: \0 | AG14: ######## | AH14: 신용카드 | AI14: MOBILE | AJ14: -199 | AK14: -73 | AL14: \7,038
A15: 2026041239219381 | B15: 2026041293937681 | C15: 2026.04.17 09:47 | D15: 스마트스토어 | E15: 구매확정 | F15: 한승주 | G15: flyb*** | H15: 한승주 | I15: 2026.04.13 14:01 | J15: 택배,등기,소포 | K15: 로젠택배 | L15: 92233941870 | M15: 2026.04.14 18:30 | N15: 9927394880 | O15: [영이 공구x베럴즈] PAW PAW TOWEL 특가 | P15: 단일상품 | Q15: 1~5개 | R15: 1 | S15: \9,500 | T15: \0 | U15: \2,190 | V15: \2,190 | W15: \7,310 | AA15: 2026041269328916 | AB15: 무료 | AC15: 조건부무료 | AD15: \0 | AE15: \0 | AF15: \0 | AG15: ######## | AH15: 머니결제 | AI15: MOBILE | AJ15: -199 | AK15: -73 | AL15: \7,038
A16: 2026040920978891 | B16: 2026040920421571 | C16: 2026.04.11 17:09 | D16: 스마트스토어 | E16: 구매확정 | F16: 정다은 | G16: art_***** | H16: 정다은 | I16: 2026.04.09 15:15 | J16: 택배,등기,소포 | K16: 로젠택배 | L16: 92233864590 | M16: 2026.04.10 13:09 | N16: 9927394880 | O16: [영이 공구x베럴즈] PAW PAW TOWEL 특가 | P16: 단일상품 | Q16: 1~5개 | R16: 1 | S16: \9,500 | T16: \0 | U16: \2,190 | V16: \2,190 | W16: \7,310 | AA16: 2026040955332009 | AB16: 무료 | AC16: 조건부무료 | AD16: \0 | AE16: \0 | AF16: \0 | AG16: ######## | AH16: 머니결제 | AI16: MOBILE | AJ16: -199 | AK16: -219 | AL16: \6,892
A17: 2026041574324691 | B17: 2026041586187891 | C17: 2026.04.30 21:32 | D17: 스마트스토어 | E17: 구매확정 | F17: 류진희 | G17: jini**** | H17: 류진희 | I17: 2026.04.28 15:12 | J17: 택배,등기,소포 | K17: 로젠택배 | L17: 92234495135 | M17: 2026.04.29 12:00 | N17: 9927394880 | O17: [영이 공구x베럴즈] PAW PAW TOWEL 특가 | P17: 조합형옵션상품 | Q17: 1~5개 | R17: 2 | S17: \9,500 | T17: \0 | U17: \4,280 | V17: \4,280 | W17: \14,720 | AA17: 2026041585066545 | AB17: 선결제 | AC17: 조건부무료 | AD17: \3,000 | AE17: \0 | AF17: \0 | AG17: ######## | AH17: 신용카드 간편결제 | AI17: MOBILE | AJ17: -401 | AK17: -147 | AL17: \14,172
A18: 2026041457922741 | B18: 2026041475423321 | C18: 2026.04.30 09:46 | D18: 스마트스토어 | E18: 구매확정 | F18: 박영혜 | G18: kjhy***** | H18: 박영혜 | I18: 2026.04.28 15:12 | J18: 택배,등기,소포 | K18: 로젠택배 | L18: 92234493606 | M18: 2026.04.29 09:40 | N18: 9927394880 | O18: [영이 공구x베럴즈] PAW PAW TOWEL 특가 | P18: 조합형옵션상품 | Q18: 1~5개 | R18: 2 | S18: \9,500 | T18: \0 | U18: \4,280 | V18: \4,280 | W18: \14,720 | AA18: 2.0260415e+15 | AB18: 선결제 | AC18: 조건부무료 | AD18: \3,000 | AE18: \0 | AF18: \0 | AG18: ######## | AH18: 신용카드 간편결제 | AI18: MOBILE | AJ18: -400 | AK18: -147 | AL18: \14,173
A19: 2026041458095871 | B19: 2026041475532031 | C19: 2026.04.30 08:24 | D19: 스마트스토어 | E19: 구매확정 | F19: 김민경 | G19: alsd*** | H19: 김민경 | I19: 2026.04.28 15:12 | J19: 택배,등기,소포 | K19: 로젠택배 | L19: 92234493643 | M19: 2026.04.29 16:36 | N19: 9927394880 | O19: [영이 공구x베럴즈] PAW PAW TOWEL 특가 | P19: 조합형옵션상품 | Q19: 1~5개 | R19: 2 | S19: \9,500 | T19: \0 | U19: \4,180 | V19: \4,180 | W19: \14,820 | AA19: 2026041483074288 | AB19: 선결제 | AC19: 조건부무료 | AD19: \3,000 | AE19: \0 | AF19: \0 | AG19: ######## | AH19: 신용카드 간편결제 | AI19: MOBILE | AJ19: -404 | AK19: -148 | AL19: \14,268
A20: 2026041563223931 | B20: 2026041578804831 | C20: 2026.04.30 06:17 | D20: 스마트스토어 | E20: 구매확정 | F20: 안송희 | G20: dkre***** | H20: 안송희 | I20: 2026.04.28 15:12 | J20: 택배,등기,소포 | K20: 로젠택배 | L20: 92234494192 | M20: 2026.04.29 14:16 | N20: 9927394880 | O20: [영이 공구x베럴즈] PAW PAW TOWEL 특가 | P20: 조합형옵션상품 | Q20: 1~5개 | R20: 2 | S20: \9,500 | T20: \0 | U20: \4,280 | V20: \4,280 | W20: \14,720 | AA20: 2.0260416e+15 | AB20: 선결제 | AC20: 조건부무료 | AD20: \3,000 | AE20: \0 | AF20: \0 | AG20: ######## | AH20: 신용카드 간편결제 | AI20: MOBILE | AJ20: -401 | AK20: -147 | AL20: \14,172
A21: 2026041458487911 | B21: 2026041475779181 | C21: 2026.04.29 14:24 | D21: 스마트스토어 | E21: 구매확정 | F21: 이하연 | G21: hayo****** | H21: 이하연 | I21: 2026.04.28 15:12 | J21: 택배,등기,소포 | K21: 로젠택배 | L21: 92234493691 | M21: 2026.04.29 11:25 | N21: 9927394880 | O21: [영이 공구x베럴즈] PAW PAW TOWEL 특가 | P21: 조합형옵션상품 | Q21: 1~5개 | R21: 2 | S21: \9,500 | T21: \0 | U21: \4,180 | V21: \4,180 | W21: \14,820 | AA21: 2026041483121993 | AB21: 선결제 | AC21: 조건부무료 | AD21: \3,000 | AE21: \0 | AF21: \0 | AG21: ######## | AH21: 신용카드 간편결제 | AI21: MOBILE | AJ21: -404 | AK21: -148 | AL21: \14,268
A22: 2026041455345491 | B22: 2026041473802621 | C22: 2026.04.24 03:11 | D22: 스마트스토어 | E22: 구매확정 | F22: 김지현 | G22: ske3**** | H22: 김지현 | I22: 2026.04.15 18:33 | J22: 택배,등기,소포 | K22: 로젠택배 | L22: 92234045481 | M22: 2026.04.16 15:08 | N22: 9927394880 | O22: [영이 공구x베럴즈] PAW PAW TOWEL 특가 | P22: 조합형옵션상품 | Q22: 1~5개 | R22: 2 | S22: \9,500 | T22: \0 | U22: \4,280 | V22: \4,280 | W22: \14,720 | AA22: 2026041482741652 | AB22: 선결제 | AC22: 조건부무료 | AD22: \3,000 | AE22: \0 | AF22: \0 | AG22: ######## | AH22: 신용카드 간편결제 | AI22: MOBILE | AJ22: -401 | AK22: -147 | AL22: \14,172
A23: 2026041450951111 | B23: 2026041470967851 | C23: 2026.04.24 02:36 | D23: 스마트스토어 | E23: 구매확정 | F23: 성은지 | G23: sung******** | H23: 성은지 | I23: 2026.04.15 18:33 | J23: 택배,등기,소포 | K23: 로젠택배 | L23: 92234045234 | M23: 2026.04.16 13:15 | N23: 9927394880 | O23: [영이 공구x베럴즈] PAW PAW TOWEL 특가 | P23: 단일상품 | Q23: 1~5개 | R23: 2 | S23: \9,500 | T23: \0 | U23: \4,280 | V23: \4,280 | W23: \14,720 | AA23: 2026041482198069 | AB23: 선결제 | AC23: 조건부무료 | AD23: \3,000 | AE23: \0 | AF23: \0 | AG23: ######## | AH23: 신용카드 간편결제 | AI23: MOBILE | AJ23: -401 | AK23: -147 | AL23: \14,172
A24: 2026041451527641 | B24: 2026041471343551 | C24: 2026.04.24 02:35 | D24: 스마트스토어 | E24: 구매확정 | F24: 권경선 | G24: gywl**** | H24: 권경선 | I24: 2026.04.15 18:33 | J24: 택배,등기,소포 | K24: 로젠택배 | L24: 92234045282 | M24: 2026.04.16 16:20 | N24: 9927394880 | O24: [영이 공구x베럴즈] PAW PAW TOWEL 특가 | P24: 단일상품 | Q24: 1~5개 | R24: 2 | S24: \9,500 | T24: \0 | U24: \4,180 | V24: \4,180 | W24: \14,820 | AA24: 2.0260415e+15 | AB24: 선결제 | AC24: 조건부무료 | AD24: \3,000 | AE24: \0 | AF24: \0 | AG24: ######## | AH24: 신용카드 간편결제 | AI24: MOBILE | AJ24: -404 | AK24: -148 | AL24: \14,268
A25: 2026041959831721 | B25: 2026041916753661 | C25: 2026.04.30 02:25 | D25: 스마트스토어 | E25: 구매확정 | F25: 정윤하 | G25: re**** | H25: 정윤하 | I25: 2026.04.21 15:27 | J25: 택배,등기,소포 | K25: 로젠택배 | L25: 92234241271 | M25: 2026.04.22 11:16 | N25: 10565999120 | O25: [영이 공구x베럴즈] 이케코백 5종 특가 | P25: 조합형옵션상품 | Q25: 사이즈: ML / 색상: 체크 블루 | R25: 1 | S25: \119,000 | T25: \7,500 | U25: \29,750 | V25: \29,750 | W25: \96,750 | AA25: 2026041996323233 | AB25: 무료 | AC25: 조건부무료 | AD25: \0 | AE25: \0 | AF25: \0 | AG25: ######## | AH25: 신용카드 간편결제 | AI25: MOBILE | AJ25: -2638 | AK25: -967 | AL25: \93,145
A26: 2026041813540091 | B26: 2026041875160741 | C26: 2026.04.24 22:17 | D26: 스마트스토어 | E26: 구매확정 | F26: 김미경 | G26: jsk8*** | H26: 김미경 | I26: 2026.04.20 16:45 | J26: 택배,등기,소포 | K26: 로젠택배 | L26: 92234205781 | M26: 2026.04.21 13:13 | N26: 8680767721 | O26: [영이 공구x베럴즈] 마틴게일 목줄 (6종) | P26: 조합형옵션상품 | Q26: 컬러: 베지프렌즈 / 사이즈: M | R26: 1 | S26: \22,000 | T26: \0 | U26: \6,600 | V26: \6,600 | W26: \15,400 | AA26: 2026041893296522 | AB26: 무료 | AC26: 조건부무료 | AD26: \0 | AE26: \0 | AF26: \0 | AG26: ######## | AH26: 신용카드 간편결제 | AI26: MOBILE | AJ26: -420 | AK26: -154 | AL26: \14,826
A27: 2026041621295811 | B27: 2026041620397351 | C27: 2026.04.18 12:57 | D27: 스마트스토어 | E27: 구매확정 | F27: 이금정 | G27: fanc***** | H27: 이금정 | I27: 2026.04.16 16:11 | J27: 택배,등기,소포 | K27: 로젠택배 | L27: 92234100932 | M27: 2026.04.17 16:19 | N27: 10439130559 | O27: [영이 공구x베럴즈] 리쉬 (6종) | P27: 조합형옵션상품 | Q27: 컬러: 베지프렌즈 / 길이: 1.2M | R27: 1 | S27: \19,000 | T27: \0 | U27: \5,700 | V27: \5,700 | W27: \13,300 | AA27: 2026041688259094 | AB27: 무료 | AC27: 조건부무료 | AD27: \0 | AE27: \0 | AF27: \0 | AG27: ######## | AH27: 신용카드 간편결제 | AI27: MOBILE | AJ27: -362 | AK27: -399 | AL27: \12,539
A28: 2026041652943311 | B28: 2026041641332131 | C28: 2026.04.21 08:37 | D28: 스마트스토어 | E28: 구매확정 | F28: 류훈선 | G28: come******** | H28: 류훈선 | I28: 2026.04.17 16:11 | J28: 택배,등기,소포 | K28: 로젠택배 | L28: 92234140084 | M28: 2026.04.18 16:15 | N28: 8680767721 | O28: [영이 공구x베럴즈] 마틴게일 목줄 (6종) | P28: 조합형옵션상품 | Q28: 컬러: 베지프렌즈 / 사이즈: M | R28: 1 | S28: \22,000 | T28: \0 | U28: \6,600 | V28: \6,600 | W28: \15,400 | AA28: 2026041690167727 | AB28: 무료 | AC28: 조건부무료 | AD28: \0 | AE28: \0 | AF28: \0 | AG28: ######## | AH28: 신용카드 간편결제 | AI28: MOBILE | AJ28: -420 | AK28: -154 | AL28: \14,826
A29: 2026041453999501 | B29: 2026041472952691 | C29: 2026.04.24 02:35 | D29: 스마트스토어 | E29: 구매확정 | F29: 조율하 | G29: so74**** | H29: 조율하 | I29: 2026.04.15 18:33 | J29: 택배,등기,소포 | K29: 로젠택배 | L29: 92234045352 | M29: 2026.04.16 13:54 | N29: 9927394880 | O29: [영이 공구x베럴즈] PAW PAW TOWEL 특가 | P29: 조합형옵션상품 | Q29: 1~5개 | R29: 2 | S29: \9,500 | T29: \0 | U29: \4,180 | V29: \4,180 | W29: \14,820 | AA29: 2026041482578079 | AB29: 선결제 | AC29: 조건부무료 | AD29: \3,000 | AE29: \0 | AF29: \0 | AG29: ######## | AH29: 신용카드 간편결제 | AI29: MOBILE | AJ29: -404 | AK29: -148 | AL29: \14,268
A30: 2026041449985561 | B30: 2026041470333321 | C30: 2026.04.22 06:31 | D30: 스마트스토어 | E30: 구매확정 | F30: 박미정 | G30: qwsd**** | H30: 박미정 | I30: 2026.04.15 18:33 | J30: 택배,등기,소포 | K30: 로젠택배 | L30: 92234045186 | M30: 2026.04.16 15:08 | N30: 9927394880 | O30: [영이 공구x베럴즈] PAW PAW TOWEL 특가 | P30: 단일상품 | Q30: 1~5개 | R30: 2 | S30: \9,500 | T30: \0 | U30: \4,280 | V30: \4,280 | W30: \14,720 | AA30: 2026041482077055 | AB30: 선결제 | AC30: 조건부무료 | AD30: \3,000 | AE30: \0 | AF30: \0 | AG30: ######## | AH30: 신용카드 간편결제 | AI30: MOBILE | AJ30: -401 | AK30: -147 | AL30: \14,172
A31: 2026041455671551 | B31: 2026041474006181 | C31: 2026.04.21 22:48 | D31: 스마트스토어 | E31: 구매확정 | F31: 김송이 | G31: ks**** | H31: 김송이 | I31: 2026.04.15 18:33 | J31: 택배,등기,소포 | K31: 로젠택배 | L31: 92234045525 | M31: 2026.04.16 15:08 | N31: 9927394880 | O31: [영이 공구x베럴즈] PAW PAW TOWEL 특가 | P31: 조합형옵션상품 | Q31: 1~5개 | R31: 2 | S31: \9,500 | T31: \0 | U31: \4,280 | V31: \4,280 | W31: \14,720 | AA31: 2026041482780571 | AB31: 선결제 | AC31: 조건부무료 | AD31: \3,000 | AE31: \0 | AF31: \0 | AG31: ######## | AH31: 계좌 간편결제 | AI31: MOBILE | AJ31: -400 | AK31: -147 | AL31: \14,173
A32: 2026041453367061 | B32: 2026041472542821 | C32: 2026.04.19 11:25 | D32: 스마트스토어 | E32: 구매확정 | F32: 김혜정 | G32: chri***** | H32: 김혜정 | I32: 2026.04.15 18:33 | J32: 택배,등기,소포 | K32: 로젠택배 | L32: 92234045326 | M32: 2026.04.16 16:09 | N32: 9927394880 | O32: [영이 공구x베럴즈] PAW PAW TOWEL 특가 | P32: 단일상품 | Q32: 1~5개 | R32: 2 | S32: \9,500 | T32: \0 | U32: \4,280 | V32: \4,280 | W32: \14,720 | AA32: 2026041482499265 | AB32: 선결제 | AC32: 조건부무료 | AD32: \3,000 | AE32: \0 | AF32: \0 | AG32: ######## | AH32: 포인트결제 | AI32: MOBILE | AJ32: -401 | AK32: -147 | AL32: \14,172
A33: 2026041455797031 | B33: 2026041474084481 | C33: 2026.04.18 17:07 | D33: 스마트스토어 | E33: 구매확정 | F33: 김선민 | G33: alsd***** | H33: 김선민 | I33: 2026.04.15 15:28 | J33: 택배,등기,소포 | K33: 로젠택배 | L33: 91970128106 | M33: 2026.04.16 15:08 | N33: 9927394880 | O33: [영이 공구x베럴즈] PAW PAW TOWEL 특가 | P33: 조합형옵션상품 | Q33: 1~5개 | R33: 2 | S33: \9,500 | T33: \0 | U33: \4,280 | V33: \4,280 | W33: \14,720 | AA33: 2026041482795388 | AB33: 선결제 | AC33: 조건부무료 | AD33: \3,000 | AE33: \0 | AF33: \0 | AG33: ######## | AH33: 신용카드 간편결제 | AI33: MOBILE | AJ33: -401 | AK33: -147 | AL33: \14,172
A34: 2026041450986701 | B34: 2026041470990721 | C34: 2026.04.18 15:13 | D34: 스마트스토어 | E34: 구매확정 | F34: 유지연 | G34: ziyu*** | H34: 유지연 | I34: 2026.04.15 18:33 | J34: 택배,등기,소포 | K34: 로젠택배 | L34: 92234045245 | M34: 2026.04.16 11:19 | N34: 9927394880 | O34: [영이 공구x베럴즈] PAW PAW TOWEL 특가 | P34: 단일상품 | Q34: 1~5개 | R34: 2 | S34: \9,500 | T34: \0 | U34: \4,280 | V34: \4,280 | W34: \14,720 | AA34: 2026041482202561 | AB34: 선결제 | AC34: 조건부무료 | AD34: \3,000 | AE34: \0 | AF34: \0 | AG34: ######## | AH34: 머니결제 | AI34: MOBILE | AJ34: -401 | AK34: -147 | AL34: \14,172
A35: 2026040918128651 | B35: 2026040918538281 | C35: 2026.04.18 01:35 | D35: 스마트스토어 | E35: 구매확정 | F35: 김호진 | G35: khj7**** | H35: 박현주 | I35: 2026.04.09 13:15 | J35: 택배,등기,소포 | K35: 로젠택배 | L35: 92233858566 | M35: 2026.04.10 13:11 | N35: 9927394880 | O35: [영이 공구x베럴즈] PAW PAW TOWEL 특가 | P35: 단일상품 | Q35: 1~5개 | R35: 2 | S35: \9,500 | T35: \0 | U35: \4,180 | V35: \4,180 | W35: \14,820 | AA35: 2026040954973943 | AB35: 무료 | AC35: 조건부무료 | AD35: \0 | AE35: \0 | AF35: \0 | AG35: ######## | AH35: 신용카드 간편결제 | AI35: PC | AJ35: -404 | AK35: -148 | AL35: \14,268
A36: 2026041451185841 | B36: 2026041471120581 | C36: 2026.04.17 18:32 | D36: 스마트스토어 | E36: 구매확정 | F36: 박은진 | G36: mwej***** | H36: 박은진 | I36: 2026.04.15 18:33 | J36: 택배,등기,소포 | K36: 로젠택배 | L36: 92234045256 | M36: 2026.04.17 13:26 | N36: 9927394880 | O36: [영이 공구x베럴즈] PAW PAW TOWEL 특가 | P36: 단일상품 | Q36: 1~5개 | R36: 2 | S36: \9,500 | T36: \0 | U36: \4,280 | V36: \4,280 | W36: \14,720 | AA36: 2026041482227649 | AB36: 선결제 | AC36: 조건부무료 | AD36: \3,000 | AE36: \0 | AF36: \0 | AG36: ######## | AH36: 신용카드 간편결제 | AI36: MOBILE | AJ36: -401 | AK36: -147 | AL36: \14,172
... A49: 2026041621295801 | B49: 2026041620397351 | C49: 2026.04.18 12:57 | D49: 스마트스토어 | E49: 구매확정 | F49: 이금정 | G49: fanc***** | H49: 이금정 | I49: 2026.04.16 16:11 | J49: 택배,등기,소포 | K49: 로젠택배 | L49: 92234100932 | M49: 2026.04.17 16:19 | N49: 8680767721 | O49: [영이 공구x베럴즈] 마틴게일 목줄 (6종) | P49: 조합형옵션상품 | Q49: 컬러: 베지프렌즈 / 사이즈: S | R49: 1 | S49: \22,000 | T49: \0 | U49: \6,600 | V49: \6,600 | W49: \15,400 | AA49: 2026041688259094 | AB49: 무료 | AC49: 조건부무료 | AD49: \0 | AE49: \0 | AF49: \0 | AG49: ######## | AH49: 신용카드 간편결제 | AI49: MOBILE | AJ49: -419 | AK49: -462 | AL49: \14,519
A50: 2026040925316821 | B50: 2026040923257001 | C50: 2026.04.18 01:59 | D50: 스마트스토어 | E50: 구매확정 | F50: 김혜미 | G50: gpal**** | H50: 김혜미 | I50: 2026.04.09 15:15 | J50: 택배,등기,소포 | K50: 로젠택배 | L50: 92233872286 | M50: 2026.04.10 09:11 | N50: 8680767721 | O50: [영이 공구x베럴즈] 마틴게일 목줄 (6종) | P50: 조합형옵션상품 | Q50: 컬러: 베지프렌즈 / 사이즈: S | R50: 1 | S50: \22,000 | T50: \0 | U50: \6,600 | V50: \6,600 | W50: \15,400 | AA50: 2.026041e+15 | AB50: 무료 | AC50: 조건부무료 | AD50: \0 | AE50: \0 | AF50: \0 | AG50: ######## | AH50: 신용카드 간편결제 | AI50: MOBILE | AJ50: -419 | AK50: -154 | AL50: \14,827
A51: 2026041763639211 | B51: 2026041748306411 | C51: 2026.04.18 22:03 | D51: 스마트스토어 | E51: 구매확정 | F51: 김혜원 | G51: 1222****** | H51: 호평한화 | I51: 2026.04.17 16:11 | J51: 택배,등기,소포 | K51: 로젠택배 | L51: 92234140202 | M51: 2026.04.18 13:09 | N51: 10439130559 | O51: [영이 공구x베럴즈] 리쉬 (6종) | P51: 조합형옵션상품 | Q51: 컬러: 베지프렌즈 / 길이: 1.2M | R51: 1 | S51: \19,000 | T51: \0 | U51: \5,800 | V51: \5,800 | W51: \13,200 | AA51: 2026041790819257 | AB51: 무료 | AC51: 조건부무료 | AD51: \0 | AE51: \0 | AF51: \0 | AG51: ######## | AH51: 신용카드 간편결제 | AI51: MOBILE | AJ51: -360 | AK51: -396 | AL51: \12,444
A52: 2026041939642201 | B52: 2026041992974441 | C52: 2026.04.24 23:04 | D52: 스마트스토어 | E52: 구매확정 | F52: 김운주 | G52: s404**** | H52: 김운주 | I52: 2026.04.20 14:49 | J52: 택배,등기,소포 | K52: 로젠택배 | L52: 92234206256 | M52: 2026.04.22 11:40 | N52: 10565999120 | O52: [영이 공구x베럴즈] 이케코백 5종 특가 | P52: 조합형옵션상품 | Q52: 사이즈: ML / 색상: 체크 블루 | R52: 1 | S52: \119,000 | T52: \7,500 | U52: \29,850 | V52: \29,850 | W52: \96,650 | AA52: 2.026042e+15 | AB52: 선결제 | AC52: 조건부무료 | AD52: \3,000 | AE52: \3,000 | AF52: \0 | AG52: ######## | AH52: 머니결제 | AI52: MOBILE | AJ52: -2636 | AK52: -966 | AL52: \93,048
...

Sheet DB) 콘디(4월배송완료)
A1: 주문번호 | B1: 주문일시 | C1: 결제일시(입금확인일) | D1: 주문자명 | E1: 주문상품명(옵션포함) | F1: 수량
A2: 20260403-0000039 | B2: 2026.4.3 10:57 | C2: 2026.4.3 10:57 | D2: 김세윤 | E2: [영이공구특가 이벤트 상품] CONDY 접촉 냉감 쿨매트 듀라론 쿨링 블랭킷 (2컬러)(색상 및 수량=블루화이트 1개 + 블랙화이트 1개- 정가 : 64600원) | F2: 1
A3: 20260403-0000046 | B3: 2026.4.3 10:58 | C3: 2026.4.3 10:58 | D3: 박소정 | E3: [영이공구특가 이벤트 상품] CONDY 접촉 냉감 쿨매트 듀라론 쿨링 블랭킷 (2컬러)(색상 및 수량=블루화이트 1개 + 블랙화이트 1개- 정가 : 64600원) | F3: 1
A4: 20260403-0000052 | B4: 2026.4.3 11:00 | C4: 2026.4.3 11:00 | D4: 정지혜 | E4: [영이공구특가 이벤트 상품] CONDY 접촉 냉감 쿨매트 듀라론 쿨링 블랭킷 (2컬러)(색상 및 수량=블루화이트 1개 + 블랙화이트 1개- 정가 : 64600원) | F4: 1
A5: 20260403-0000065 | B5: 2026.4.3 11:01 | C5: 2026.4.3 11:01 | D5: 김우선 | E5: [영이공구특가 이벤트 상품] CONDY 접촉 냉감 쿨매트 듀라론 쿨링 블랭킷 (2컬러)(색상 및 수량=블루화이트 2개 - 정가 : 64600원) | F5: 1
A6: 20260403-0000065 | B6: 2026.4.3 11:01 | C6: 2026.4.3 11:01 | D6: 김우선 | E6: [영이공구특가 이벤트 상품] CONDY 접촉 냉감 쿨매트 듀라론 쿨링 블랭킷 (2컬러)(색상 및 수량=블랙화이트 2개 - 정가 : 64600원) | F6: 1
A7: 20260403-0000078 | B7: 2026.4.3 11:02 | C7: 2026.4.3 11:02 | D7: 이수연 | E7: [영이공구특가 이벤트 상품] CONDY 접촉 냉감 쿨매트 듀라론 쿨링 블랭킷 (2컬러)(색상 및 수량=블루화이트 2개 + 블랙화이트 1개 - 정가 : 96900원) | F7: 1
A8: 20260403-0000089 | B8: 2026.4.3 11:02 | C8: 2026.4.3 11:02 | D8: 김가이 | E8: [영이공구특가 이벤트 상품] CONDY 접촉 냉감 쿨매트 듀라론 쿨링 블랭킷 (2컬러)(색상 및 수량=블루화이트 1개 + 블랙화이트 2개 - 정가 : 96900원) | F8: 1
A9: 20260403-0000092 | B9: 2026.4.3 11:02 | C9: 2026.4.3 11:02 | D9: 김지혜 | E9: [영이공구특가 이벤트 상품] CONDY 접촉 냉감 쿨매트 듀라론 쿨링 블랭킷 (2컬러)(색상 및 수량=블루화이트 1개 + 블랙화이트 2개 - 정가 : 96900원) | F9: 1
A10: 20260403-0000105 | B10: 2026.4.3 11:02 | C10: 2026.4.3 11:02 | D10: 정하진 | E10: [영이공구특가 이벤트 상품] CONDY 접촉 냉감 쿨매트 듀라론 쿨링 블랭킷 (2컬러)(색상 및 수량=블루화이트 1개 + 블랙화이트 1개- 정가 : 64600원) | F10: 1
A11: 20260403-0000112 | B11: 2026.4.3 11:02 | C11: 2026.4.3 11:02 | D11: 김슬기 | E11: [영이공구특가 이벤트 상품] CONDY 접촉 냉감 쿨매트 듀라론 쿨링 블랭킷 (2컬러)(색상 및 수량=블루화이트 1개) | F11: 1
A12: 20260403-0000133 | B12: 2026.4.3 11:04 | C12: 2026.4.3 11:04 | D12: 김진영 | E12: [영이공구특가 이벤트 상품] CONDY 접촉 냉감 쿨매트 듀라론 쿨링 블랭킷 (2컬러)(색상 및 수량=블랙화이트 1개) | F12: 1
A13: 20260403-0000151 | B13: 2026.4.3 11:05 | C13: 2026.4.3 11:05 | D13: HYE | E13: [영이공구특가 이벤트 상품] CONDY 접촉 냉감 쿨매트 듀라론 쿨링 블랭킷 (2컬러)(색상 및 수량=블루화이트 1개 + 블랙화이트 1개- 정가 : 64600원) | F13: 1
... A818: 20260429-0000067 | B818: 2026.4.29 7:46 | C818: 2026.4.29 7:46 | D818: 박은해 | E818: [영이공구특가 이벤트 상품] CONDY 접촉 냉감 쿨매트 듀라론 쿨링 블랭킷 (2컬러)(구성 선택=블루화이트 2개) | F818: 1

Sheet DB) 도톤(4월배송완료)
A1: 주문번호 | B1: 주문일시 | C1: 결제일시(입금확인일) | D1: 주문자명 | E1: 주문상품명(옵션포함) | F1: 수량
A2: 20260413-0000075 | B2: 2026.4.13 9:01 | C2: 2026.4.13 8:58 | D2: 박유진 | E2: [영이공구특가 이벤트 상품] 도톤 포레스트 아웃도어 해충방지 스프레이 150ml(수량=공구 3개세트 (36%할인)) | F2: 1
A3: 20260413-0000161 | B3: 2026.4.13 12:39 | C3: 2026.4.13 12:35 | D3: 이아람 | E3: [영이공구특가 이벤트 상품] 도톤 포레스트 아웃도어 해충방지 스프레이 150ml(수량=공구특가 1개 (25%할인)) | F3: 1
A4: 20260413-0000170 | B4: 2026.4.13 12:40 | C4: 2026.4.13 12:37 | D4: 이정은 | E4: [영이공구특가 이벤트 상품] 도톤 포레스트 아웃도어 해충방지 스프레이 150ml(수량=공구 2개세트 (32%할인)) | F4: 1
A5: 20260413-0000182 | B5: 2026.4.13 12:45 | C5: 2026.4.13 12:45 | D5: 성민영 | E5: [영이공구특가 이벤트 상품] 도톤 포레스트 아웃도어 해충방지 스프레이 150ml(수량=공구 3개세트 (36%할인)) | F5: 1
A6: 20260413-0000191 | B6: 2026.4.13 12:58 | C6: 2026.4.13 12:55 | D6: 김진아 | E6: [영이공구특가 이벤트 상품] 도톤 포레스트 아웃도어 해충방지 스프레이 150ml(수량=공구특가 1개 (25%할인)) | F6: 1
A7: 20260413-0000205 | B7: 2026.4.13 13:04 | C7: 2026.4.13 13:01 | D7: 현다예 | E7: [영이공구특가 이벤트 상품] 도톤 포레스트 아웃도어 해충방지 스프레이 150ml(수량=공구특가 1개 (25%할인)) | F7: 1
A8: 20260413-0000215 | B8: 2026.4.13 13:04 | C8: 2026.4.13 13:01 | D8: 김현정 | E8: [영이공구특가 이벤트 상품] 도톤 포레스트 아웃도어 해충방지 스프레이 150ml(수량=공구 3개세트 (36%할인)) | F8: 1
A9: 20260413-0000295 | B9: 2026.4.13 13:34 | C9: 2026.4.13 13:30 | D9: 임하영 | E9: [영이공구특가 이벤트 상품] 도톤 포레스트 아웃도어 해충방지 스프레이 150ml(수량=공구 2개세트 (32%할인)) | F9: 1
A10: 20260413-0000308 | B10: 2026.4.13 13:35 | C10: 2026.4.13 13:31 | D10: 정미희 | E10: [영이공구특가 이벤트 상품] 도톤 포레스트 아웃도어 해충방지 스프레이 150ml(수량=공구특가 1개 (25%할인)) | F10: 1
A11: 20260413-0000310 | B11: 2026.4.13 13:40 | C11: 2026.4.13 13:36 | D11: 유형규 | E11: [영이공구특가 이벤트 상품] 도톤 포레스트 아웃도어 해충방지 스프레이 150ml(수량=공구 2개세트 (32%할인)) | F11: 1
A12: 20260413-0000351 | B12: 2026.4.13 14:12 | C12: 2026.4.13 14:08 | D12: 배문정 | E12: [영이공구특가 이벤트 상품] 도톤 포레스트 아웃도어 해충방지 스프레이 150ml(수량=공구특가 1개 (25%할인)) | F12: 1
A13: 20260413-0000363 | B13: 2026.4.13 14:31 | C13: 2026.4.13 14:26 | D13: 장희진 | E13: [영이공구특가 이벤트 상품] 도톤 포레스트 아웃도어 해충방지 스프레이 150ml(수량=공구 3개세트 (36%할인)) | F13: 1
... A150: 20260429-0000099 | B150: 2026.4.29 9:48 | C150: 2026.4.29 9:48 | D150: 김용아 | E150: [영이공구특가 이벤트 상품] 도톤 포레스트 아웃도어 해충방지 스프레이 150ml(수량=공구특가 1개 (25%할인)) | F150: 1
