Workbook

Sheet 종합정산
B2: [판매내역 종합] | J2: vat포함
B3: 정산 월 | C3: 실판매수량 | D3: 판매정가계 | E3: 할인계 | F3: 실판매계 | G3: 공제 수수료 (공급마진) | H3: 매출계 | I3: 실비 | J3: 이익
B4: 46113 | C4: ='채널별 판매데이터 정리'!K78 -> 307 | D4: ='채널별 판매데이터 정리'!K79 -> 6754000 | E4: =D4-F4 -> 2049740 | F4: ='채널별 판매데이터 정리'!K80 -> 4704260 | G4: ='채널별 판매데이터 정리'!K81 -> 1062325 | H4: =F4-G4 -> 3641935 | I4: =F26 -> 738480 | J4: =H4-I4 -> 2903455
L5: [재고현황] | M5: 자사물류센터 입출고 기준
B6: [정산 방식/ VAT포함] | N6: 4월 1일 | Q6: =N6&" ~ "&W6 -> 4월 1일 ~ 4월 30일 | W6: 4월 30일
B7: 항목 | F7: 비고 | N7: 기초재고 | Q7: 입고 | T7: 출고 | W7: 기말재고
B8: A 수수료 (공급마진) | F8: 각 유통 채널별 공급마진 (위탁은 수수료/ 매입은 공급할인액) 기준 | L8: 품목관리코드 | M8: 품목명 | N8: 전체 | O8: 정상 | P8: 불용 | Q8: 전체 | R8: 입고 | S8: 반품 | T8: 전체 | U8: 판매 | V8: 비매출 | W8: 전체 | X8: 정상 | Y8: 불용
B9: B 매출계 (월별 최종 판매 금액) | F9: 월별 제품 최종판매금액 (정가 - 프로모션 등 할인이 반영된 최종 결제 금액) | L9: 8809879544118 | M9: 도톤 포레스트 워터리스 풋클리너 100ml | N9: =O9+P9 -> 131 | O9: 131 | P9: 0 | Q9: =R9+S9 -> 0 | R9: 0 | T9: =U9+V9 -> 10 | U9: 8 | V9: 2 | W9: =N9+Q9-T9 -> 121 | X9: =W9-Y9 -> 121
B10: C 실비 | F10: 운송료 실비, PG결제 수수료 등 | L10: 8809879544101 | M10: 도톤 포레스트 아웃도어 스프레이 150ml | N10: =O10+P10 -> 337 | O10: 337 | P10: 0 | Q10: =R10+S10 -> 199 | R10: 198 | S10: 1 | T10: =U10+V10 -> 277 | U10: 270 | V10: 7 | W10: =N10+Q10-T10 -> 259 | X10: =W10-Y10 -> 259
B11: D 이익 | F11: 판매 매출 발생 시, “월별 제품 최종 판매 금액”을 기준으로, 인플루언서 공구 수수료를 포함한 각각의 입점 채널별 공급 수수료, 운송료 실비, PG사 결제 수수료를 제외한 금액
M12: 합계 | N12: =SUM(N9:N11) -> 468 | O12: =SUM(O9:O11) -> 468 | P12: =SUM(P9:P11) -> 0 | Q12: =SUM(Q9:Q11) -> 199 | R12: =SUM(R9:R11) -> 198 | S12: =SUM(S9:S11) -> 1 | T12: =SUM(T9:T11) -> 287 | U12: =SUM(U9:U11) -> 278 | ... Y12: =SUM(Y9:Y11) -> 0
B14: 매출계산서발행 | F14: vat포함
B15: 항목 | C15: 구분 | D15: 비율 | E15: 금액 | F15: 비고
B16: 이익분배 | C16: 유씨엘주식회사 | D16: 0.4 | E16: =J4*D16 -> 1161382
C17: 우프컴퍼니(주) | D17: 0.3 | E17: =J4*D17 -> 871036.5
C18: 재계약중 | D18: 0.3 | E18: =J4*D18 -> 871036.5 | F18: 제외
B19: 합계 | D19: =SUM(D16:D18) -> 1 | E19: =SUM(E16:E18) -> 2903455
B21: [실비 : 운임/물류] | F21: vat포함
B22: 2026년 4월 | C22: 물류 실비 산정
C23: 수량(출고건수) | D23: 택배 | E23: 피킹/패킹/부자재 | F23: 총계
B24: 택배(소형) | C24: 181 | D24: 2650 | E24: 1430 | F24: =C24*(D24+E24) -> 738480
B25: 택배(중대형) | D25: 4400 | E25: 1430 | F25: =C25*(D25+E25) -> 0
B26: 합계 | C26: =SUM(C24:C25) -> 181 | F26: =SUM(F24:F25) -> 738480
B27: *입고비용 및 보관비용은 한시적 청구제외 하였으며, 운송실비(당사가 3PL 지불하는 택배운임비 +물류비) 청구기준만 기재되었습니다.
B28: *퀵/용달 등 별도 운송비 발생시에는 개별기재합니다.
F29: vat별도
B30: 항목 | C30: 항목 | D30: 견적(원) | E30: 단위 | F30: 비고
B31: 3PL 단가표 | C31: 보관료 | E31: 월/평당 | F31: 청구제외
C32: 입고비용 | D32: 0 | E32: 건 | F32: 청구제외
C33: 택배운임비 | D33: 2500 | E33: 건 | F33: 로젠택배(소형)
C34: 택배운임비 | D34: 4000 | E34: 건 | F34: 로젠택배(중대형)
C35: 물류비 | D35: 1300 | E35: 건 | F35: 부자재 /피킹/패킹
B38: [메모/특이사항]
B39: 재고이동(오프라인 위탁진열/ 판매시 정산)
B40: 비매출: 협찬, 진열품, 샘플 등의 무상사용
B41: 세금계산서는 정산 월 기준 익익월 10일에 발행 예정입니다.
B42: 정산금액은 정산 월 기준 익월 15일에 입금 예정이며 정산금액 활용안 협의에 따라 변경될 수 있습니다.
B43: 불용이슈: 패키지 손상/파손

Sheet 채널별 판매데이터 정리
B1: 판매기간 2026 4/1 - 4/30
B4: 몽슈슈 | D4: 주요채널: 오프라인 백화점 팝업스토어 | K4: 위탁재고
B5: 순번 | C5: 제품 | D5: 정가 | E5: 공급가 | F5: 기본수수료 | G5: 판매수량 | H5: 프로모션차감 | I5: 매출합계 | J5: 수수료합계 | K5: 정산합계 | L5: 정가합계
B6: 1 | C6: DOTEON Foot Cleaner | D6: 22000 | E6: 13200 | F6: 0.4 | G6: 13 | H6: 17160 | I6: =E6*G6 -> 171600 | K6: 154440 | L6: =D6*G6 -> 286000
B7: 2 | C7: DOTEON Outdoor Spray | D7: 22000 | E7: 13200 | F7: 0.4 | G7: 14 | H7: 18480 | I7: =E7*G7 -> 184800 | K7: 166320 | L7: =D7*G7 -> 308000
C8: 합계 | G8: 27 | H8: 35640 | I8: =SUM(I6:I7) -> 356400 | K8: 320760 | L8: =SUM(L6:L7) -> 594000
B11: 스마트스토어
B12: 순번 | C12: 품목 구성 | D12: 정가 | E12: 프로모션가 | F12: 할인율 | G12: 판매수량 | H12: 매출합계 | I12: 수수료 | J12: 수수료합계 | K12: 정산합계 | L12: 정가합계
B13: 1 | C13: DOTEON Foot Cleaner | D13: 22000 | E13: =D13-(D13*F13) -> 17600 | F13: 0.2 | G13: 0 | H13: =E13*G13 -> 0 | I13: 0.05 | J13: =H13*I13 -> 0 | K13: =H13-J13 -> 0 | L13: =D13*G13 -> 0
B14: 2 | C14: DOTEON Outdoor Spray | D14: 22000 | E14: =D14-(D14*F14) -> 17600 | F14: 0.2 | G14: 3 | H14: =E14*G14 -> 52800 | I14: 0.05 | J14: =H14*I14 -> 2640 | K14: =H14-J14 -> 50160 | L14: =D14*G14 -> 66000
C15: 합계 | G15: =SUM(G13:G14) -> 3 | H15: =SUM(H13:H14) -> 52800 | J15: =SUM(J13:J14) -> 2640 | K15: =H15-J15 -> 50160 | L15: =SUM(L13:L14) -> 66000
B18: 테일릿 | D18: 주요채널: 대리점(오프라인B2B전용 도매유통업) - 소매점 40% + 대리점마진 20% | K18: 매입(판매)
B19: 순번 | C19: 품목 구성 | D19: 정가 | E19: 소매점가 | F19: 소매점수수료 | G19: 대리점가 | H19: 대리점수수료 | I19: 판매수량 | J19: 수수료합계 | K19: 정산합계 | L19: 정가합계
B20: 1 | C20: DOTEON Foot Cleaner | D20: 22000 | E20: =D20-D20*F20 -> 13200 | F20: 0.4 | G20: =E20-E20*H20 -> 10560 | H20: 0.2 | I20: 0 | J20: =D20*0.52*I20 -> 0 | K20: =G20*I20 -> 0 | L20: =D20*I20 -> 0
B21: 2 | C21: DOTEON Outdoor Spray | D21: 22000 | E21: =D21-D21*F21 -> 13200 | F21: 0.4 | G21: =E21-E21*H21 -> 10560 | H21: 0.2 | I21: 0 | J21: =D21*0.52*I21 -> 0 | K21: =G21*I21 -> 0 | L21: =D21*I21 -> 0
C22: 합계 | I22: =SUM(I20:I21) -> 0 | J22: =SUM(J20:J21) -> 0 | K22: =SUM(K20:K21) -> 0 | L22: =SUM(L17:L21) -> 0
B25: 철수마켓 | K25: 판매자위탁배송
B26: 순번 | C26: 품목 구성 | D26: 정가 | E26: 프로모션가 | F26: 공급가 | G26: 수수료율 | H26: 판매수량 | I26: 매출합계 | J26: 수수료합계 | K26: 정산합계 | L26: 정가합계
B27: 1 | C27: DOTEON Foot Cleaner | D27: 22000 | E27: 22000 | F27: =E27-E27*G27 -> 16500 | G27: 0.25 | H27: 0 | I27: =E27*H27 -> 0 | J27: =E27*G27*H27 -> 0 | K27: =I27-J27 -> 0 | L27: =H27*D27 -> 0
C28: 합계 | H28: =SUM(H27:H27) -> 0 | I28: =SUM(I27) -> 0 | J28: =SUM(J27) -> 0 | K28: =SUM(K27) -> 0 | L28: =SUM(L27) -> 0
B31: 몰리스(이마트) | K31: 위탁재고
B32: 순번 | C32: 품목 구성 | D32: 정가 | E32: 프로모션가 | F32: 공급가 | G32: 수수료율 | H32: 판매수량 | I32: 매출합계 | J32: 수수료합계 | K32: 정산합계 | L32: 정가합계
B33: 1 | C33: DOTEON Foot Cleaner | D33: 22000 | E33: 22000 | F33: =E33-E33*G33 -> 15400 | G33: 0.3 | H33: 1 | I33: =E33*H33 -> 22000 | J33: =E33*G33*H33 -> 6600 | K33: =I33-J33 -> 15400 | L33: =D33*H33 -> 22000
B34: 2 | C34: DOTEON Outdoor Spray | D34: 22000 | E34: 22000 | F34: =E34-E34*G34 -> 15400 | G34: 0.3 | H34: 2 | I34: =E34*H34 -> 44000 | J34: =E34*G34*H34 -> 13200 | K34: =I34-J34 -> 30800 | L34: =D34*H34 -> 44000
C35: 합계 | H35: =SUM(H33:H34) -> 3 | I35: =SUM(I33:I34) -> 66000 | J35: =SUM(J33:J34) -> 19800 | K35: =SUM(K33:K34) -> 46200 | L35: =SUM(L33:L34) -> 66000
B38: 오버더센스 | D38: 주요채널: 제주도 반려동물 동반시설 | K38: 위탁재고
B39: 순번 | C39: 품목 구성 | D39: 정가 | E39: 공급가 | F39: 수수료율 | G39: 판매수량 | I39: 매출합계 | J39: 수수료합계 | K39: 정산합계 | L39: 정가합계
B40: 1 | C40: DOTEON Foot Cleaner | D40: 22000 | E40: =D40-D40*F40 -> 14740 | F40: 0.33 | G40: 0
B41: 2 | C41: DOTEON Outdoor Spray | D41: 22000 | E41: =D41-D41*F41 -> 14740 | F41: 0.33 | G41: 0
C42: 합계 | G42: =SUM(G40:G41) -> 0 | K42: =SUM(K40:K41) -> 0 | L42: =SUM(L40:L41) -> 0
B45: 우프자사몰 | D45: 주요채널: 우프앱/자사몰/스마트스토어 | G45: PG | K45: 직매출
B46: 순번 | C46: 품목 구성 | D46: 정가 | E46: 행사가 | F46: 할인율 | G46: 수수료율 | H46: 판매수량 | I46: 매출합계 | J46: 수수료합계 | K46: 정산합계 | L46: 정가합계
B47: 1 | C47: DOTEON Foot Cleaner | D47: 22000 | E47: =D47-D47*F47 -> 17600 | F47: 0.2 | G47: 0.05 | H47: 8 | I47: =E47*H47 -> 140800 | J47: =I47*G47 -> 7040 | K47: =I47-J47 -> 133760 | L47: =D47*H47 -> 176000
B48: 2 | C48: DOTEON Outdoor Spray | D48: 22000 | E48: =D48-D48*F48 -> 17600 | F48: 0.2 | G48: 0.05 | H48: 8 | I48: =E48*H48 -> 140800 | J48: =I48*G48 -> 7040 | K48: =I48-J48 -> 133760 | L48: =D48*H48 -> 176000
C49: 합계 | H49: =SUM(H47:H48) -> 16 | I49: =SUM(I47:I48) -> 281600 | J49: =SUM(J47:J48) -> 14080 | K49: =SUM(K47:K48) -> 267520 | L49: =SUM(L47:L48) -> 352000
B51: 자사몰-공구 | D51: 주요채널: 영이공구(인플루언서) | G51: 공구+PG | K51: 직매출
B52: 순번 | C52: 품목 구성 | D52: 정가 | E52: 행사가 | F52: 할인율 | G52: 공구수수료 | H52: 판매수량 | I52: 매출합계 | J52: 수수료합계 | K52: 정산합계 | L52: 정가합계
B53: 1 | C53: DOTEON Outdoor Spray | D53: 22000 | E53: =D53-D53*F53 -> 16500 | F53: 0.25 | G53: 0.25 | H53: 81 | I53: =E53*H53 -> 1336500 | J53: =I53*G53 -> 334125 | K53: =I53-J53 -> 1002375 | L53: =D53*H53 -> 1782000
B54: 2 | C54: DOTEON Outdoor Spray 2개구매시 | D54: 22000 | E54: =D54-D54*F54 -> 14960 | F54: 0.32 | G54: 0.25 | H54: 108 | I54: =E54*H54 -> 1615680 | J54: =I54*G54 -> 403920 | K54: =I54-J54 -> 1211760 | L54: =D54*H54 -> 2376000
B55: 3 | C55: DOTEON Outdoor Spray 3개구매시 | D55: 22000 | E55: =D55-D55*F55 -> 14080 | F55: 0.36 | G55: 0.25 | H55: 66 | I55: =E55*H55 -> 929280 | J55: =I55*G55 -> 232320 | K55: =I55-J55 -> 696960 | L55: =D55*H55 -> 1452000
...

Sheet DB)입출고목록
C1: 출고건수 (송장기준/건) | F1: 품목 | H1: 입고합 | I1: 출고합
C2: 181 | F2: 도톤 포레스트 워터리스 풋클리너 100ml | H2: 0 | I2: 10
F3: 도톤 포레스트 아웃도어 스프레이 150ml | H3: 199 | I3: 277
H4: =SUBTOTAL(9,H2:H3) -> 199 | I4: =SUBTOTAL(9,I2:I3) -> 287
A7: 출고카운트 | B7: 입출고일자 | C7: 입력일자 | D7: 공급처명 | E7: 바코드번호 | F7: 상품명 | G7: 옵션내용 | H7: 원가 | I7: 입고수량 | J7: 입고금액 | K7: 출고수량 | L7: 출고금액 | M7: 재고작업구분 | N7: 판매처명 | O7: 판매단가 | P7: 판매금액 | Q7: 판매구분 | R7: 내용 | S7: 판매처 주문번호 | T7: 판매상세 (판매 수수료율)
A8: 1 | B8: 46142 | C8: 2026-04-30 오전 9:25:44 | D8: 도톤 | E8: 8809879544101 | F8: 도톤 포레스트 아웃도어 스프레이 150ml | G8: 단일상품 | H8: 0 | I8: 0 | J8: 0 | K8: 2 | L8: 0 | M8: 발송및출고 | N8: 카페24_베럴즈 | O8: 22000 | P8: 44000 | Q8: {=IFERROR(INDEX('DB)입출고매칭용'!$P$2:$P$181,MATCH(1,($C8='DB)입출고매칭용'!$H$2:$H$181)*($B8='DB)입출고매칭용'!$B$2:$B$181)*($K8='DB)입출고매칭용'!$J$2:$J$181),0)),"")} | R8: {=IFERROR(INDEX('DB)입출고매칭용'!$Q$2:$Q$181,MATCH(1,($C8='DB)입출고매칭용'!$H$2:$H$181)*($B8='DB)입출고매칭용'!$B$2:$B$181)*($K8='DB)입출고매칭용'!$J$2:$J$181),0)),"")} | S8: {=IFERROR(INDEX('DB)입출고매칭용'!$R$2:$R$181,MATCH(1,($C8='DB)입출고매칭용'!$H$2:$H$181)*($B8='DB)입출고매칭용'!$B$2:$B$181)*($K8='DB)입출고매칭용'!$J$2:$J$181),0)),"")}
A9: 2 | B9: 46142 | C9: 2026-04-30 오후 4:44:49 | D9: 도톤 | E9: 8809879544101 | F9: 도톤 포레스트 아웃도어 스프레이 150ml | G9: 단일상품 | H9: 0 | I9: 0 | J9: 0 | K9: 1 | L9: 0 | M9: 발송및출고 | N9: 스마트 스토어 (BETTERS) | O9: 22000 | P9: 22000 | Q9: {=IFERROR(INDEX('DB)입출고매칭용'!$P$2:$P$181,MATCH(1,($C9='DB)입출고매칭용'!$H$2:$H$181)*($B9='DB)입출고매칭용'!$B$2:$B$181)*($K9='DB)입출고매칭용'!$J$2:$J$181),0)),"")} -> 판매청구 | R9: {=IFERROR(INDEX('DB)입출고매칭용'!$Q$2:$Q$181,MATCH(1,($C9='DB)입출고매칭용'!$H$2:$H$181)*($B9='DB)입출고매칭용'!$B$2:$B$181)*($K9='DB)입출고매칭용'!$J$2:$J$181),0)),"")} -> 정상판매 | S9: {=IFERROR(INDEX('DB)입출고매칭용'!$R$2:$R$181,MATCH(1,($C9='DB)입출고매칭용'!$H$2:$H$181)*($B9='DB)입출고매칭용'!$B$2:$B$181)*($K9='DB)입출고매칭용'!$J$2:$J$181),0)),"")} -> 2026043032327861
A10: 3 | B10: 46141 | C10: 2026-04-29 오전 9:55:02 | D10: 도톤 | E10: 8809879544101 | F10: 도톤 포레스트 아웃도어 스프레이 150ml | G10: 단일상품 | H10: 0 | I10: 0 | J10: 0 | K10: 1 | L10: 0 | M10: 발송및출고 | N10: 카페24_베럴즈 | O10: 22000 | P10: 22000 | Q10: {=IFERROR(INDEX('DB)입출고매칭용'!$P$2:$P$181,MATCH(1,($C10='DB)입출고매칭용'!$H$2:$H$181)*($B10='DB)입출고매칭용'!$B$2:$B$181)*($K10='DB)입출고매칭용'!$J$2:$J$181),0)),"")} -> 판매청구 | R10: {=IFERROR(INDEX('DB)입출고매칭용'!$Q$2:$Q$181,MATCH(1,($C10='DB)입출고매칭용'!$H$2:$H$181)*($B10='DB)입출고매칭용'!$B$2:$B$181)*($K10='DB)입출고매칭용'!$J$2:$J$181),0)),"")} -> 정상판매 (공구) | S10: {=IFERROR(INDEX('DB)입출고매칭용'!$R$2:$R$181,MATCH(1,($C10='DB)입출고매칭용'!$H$2:$H$181)*($B10='DB)입출고매칭용'!$B$2:$B$181)*($K10='DB)입출고매칭용'!$J$2:$J$181),0)),"")} -> 20260428-0000100
A11: 4 | B11: 46141 | C11: 2026-04-29 오후 4:07:28 | D11: 도톤 | E11: 8809879544101 | F11: 도톤 포레스트 아웃도어 스프레이 150ml | G11: 단일상품 | H11: 0 | I11: 0 | J11: 0 | K11: 1 | L11: 0 | M11: 발송및출고 | N11: 스마트 스토어 (BETTERS) | O11: 22000 | P11: 22000 | Q11: {=IFERROR(INDEX('DB)입출고매칭용'!$P$2:$P$181,MATCH(1,($C11='DB)입출고매칭용'!$H$2:$H$181)*($B11='DB)입출고매칭용'!$B$2:$B$181)*($K11='DB)입출고매칭용'!$J$2:$J$181),0)),"")} -> 판매청구 | R11: {=IFERROR(INDEX('DB)입출고매칭용'!$Q$2:$Q$181,MATCH(1,($C11='DB)입출고매칭용'!$H$2:$H$181)*($B11='DB)입출고매칭용'!$B$2:$B$181)*($K11='DB)입출고매칭용'!$J$2:$J$181),0)),"")} -> 정상판매 | S11: {=IFERROR(INDEX('DB)입출고매칭용'!$R$2:$R$181,MATCH(1,($C11='DB)입출고매칭용'!$H$2:$H$181)*($B11='DB)입출고매칭용'!$B$2:$B$181)*($K11='DB)입출고매칭용'!$J$2:$J$181),0)),"")} -> 2026042891931141
A12: 5 | B12: 46141 | C12: 2026-04-29 오후 4:07:30 | D12: 도톤 | E12: 8809879544101 | F12: 도톤 포레스트 아웃도어 스프레이 150ml | G12: 단일상품 | H12: 0 | I12: 0 | J12: 0 | K12: 1 | L12: 0 | M12: 발송및출고 | N12: 카페24_베럴즈 | O12: 22000 | P12: 22000 | Q12: {=IFERROR(INDEX('DB)입출고매칭용'!$P$2:$P$181,MATCH(1,($C12='DB)입출고매칭용'!$H$2:$H$181)*($B12='DB)입출고매칭용'!$B$2:$B$181)*($K12='DB)입출고매칭용'!$J$2:$J$181),0)),"")} -> 판매청구 | R12: {=IFERROR(INDEX('DB)입출고매칭용'!$Q$2:$Q$181,MATCH(1,($C12='DB)입출고매칭용'!$H$2:$H$181)*($B12='DB)입출고매칭용'!$B$2:$B$181)*($K12='DB)입출고매칭용'!$J$2:$J$181),0)),"")} -> 정상판매 (공구) | S12: {=IFERROR(INDEX('DB)입출고매칭용'!$R$2:$R$181,MATCH(1,($C12='DB)입출고매칭용'!$H$2:$H$181)*($B12='DB)입출고매칭용'!$B$2:$B$181)*($K12='DB)입출고매칭용'!$J$2:$J$181),0)),"")} -> 20260429-0000099
A13: 6 | B13: 46141 | C13: 2026-04-29 오후 4:07:33 | D13: 도톤 | E13: 8809879544101 | F13: 도톤 포레스트 아웃도어 스프레이 150ml | G13: 단일상품 | H13: 0 | I13: 0 | J13: 0 | K13: 1 | L13: 0 | M13: 발송및출고 | N13: 카페24_베럴즈 | O13: 22000 | P13: 22000 | Q13: {=IFERROR(INDEX('DB)입출고매칭용'!$P$2:$P$181,MATCH(1,($C13='DB)입출고매칭용'!$H$2:$H$181)*($B13='DB)입출고매칭용'!$B$2:$B$181)*($K13='DB)입출고매칭용'!$J$2:$J$181),0)),"")} -> 판매청구 | R13: {=IFERROR(INDEX('DB)입출고매칭용'!$Q$2:$Q$181,MATCH(1,($C13='DB)입출고매칭용'!$H$2:$H$181)*($B13='DB)입출고매칭용'!$B$2:$B$181)*($K13='DB)입출고매칭용'!$J$2:$J$181),0)),"")} -> 정상판매 (공구) | S13: {=IFERROR(INDEX('DB)입출고매칭용'!$R$2:$R$181,MATCH(1,($C13='DB)입출고매칭용'!$H$2:$H$181)*($B13='DB)입출고매칭용'!$B$2:$B$181)*($K13='DB)입출고매칭용'!$J$2:$J$181),0)),"")} -> 20260429-0000122
B14: 46140 | C14: 2026-04-27 오후 6:44:50 | D14: 도톤 | E14: 8809879544101 | F14: 도톤 포레스트 아웃도어 스프레이 150ml | G14: 단일상품 | H14: 0 | I14: 198 | J14: 0 | K14: 0 | L14: 0 | M14: 입고 | O14: 22000 | P14: 0 | Q14: {=IFERROR(INDEX('DB)입출고매칭용'!$P$2:$P$181,MATCH(1,($C14='DB)입출고매칭용'!$H$2:$H$181)*($B14='DB)입출고매칭용'!$B$2:$B$181)*($K14='DB)입출고매칭용'!$J$2:$J$181),0)),"")} | R14: {=IFERROR(INDEX('DB)입출고매칭용'!$Q$2:$Q$181,MATCH(1,($C14='DB)입출고매칭용'!$H$2:$H$181)*($B14='DB)입출고매칭용'!$B$2:$B$181)*($K14='DB)입출고매칭용'!$J$2:$J$181),0)),"")} | S14: {=IFERROR(INDEX('DB)입출고매칭용'!$R$2:$R$181,MATCH(1,($C14='DB)입출고매칭용'!$H$2:$H$181)*($B14='DB)입출고매칭용'!$B$2:$B$181)*($K14='DB)입출고매칭용'!$J$2:$J$181),0)),"")}
A15: 7 | B15: 46139 | C15: 2026-04-27 오전 9:10:56 | D15: 도톤 | E15: 8809879544118 | F15: 도톤 포레스트 워터리스 풋클리너 100ml | G15: 단일상품 | H15: 0 | I15: 0 | J15: 0 | K15: 1 | L15: 0 | M15: 발송및출고 | N15: 카페24_베럴즈 | O15: 22000 | P15: 22000 | Q15: {=IFERROR(INDEX('DB)입출고매칭용'!$P$2:$P$181,MATCH(1,($C15='DB)입출고매칭용'!$H$2:$H$181)*($B15='DB)입출고매칭용'!$B$2:$B$181)*($K15='DB)입출고매칭용'!$J$2:$J$181),0)),"")} -> 판매청구 | R15: {=IFERROR(INDEX('DB)입출고매칭용'!$Q$2:$Q$181,MATCH(1,($C15='DB)입출고매칭용'!$H$2:$H$181)*($B15='DB)입출고매칭용'!$B$2:$B$181)*($K15='DB)입출고매칭용'!$J$2:$J$181),0)),"")} -> 정상판매 | S15: {=IFERROR(INDEX('DB)입출고매칭용'!$R$2:$R$181,MATCH(1,($C15='DB)입출고매칭용'!$H$2:$H$181)*($B15='DB)입출고매칭용'!$B$2:$B$181)*($K15='DB)입출고매칭용'!$J$2:$J$181),0)),"")} -> 20260425-0000045
A16: 8 | B16: 46139 | C16: 2026-04-27 오전 9:11:28 | D16: 도톤 | E16: 8809879544101 | F16: 도톤 포레스트 아웃도어 스프레이 150ml | G16: 단일상품 | H16: 0 | I16: 0 | J16: 0 | K16: 1 | L16: 0 | M16: 발송및출고 | N16: 카페24_베럴즈 | O16: 22000 | P16: 22000 | Q16: {=IFERROR(INDEX('DB)입출고매칭용'!$P$2:$P$181,MATCH(1,($C16='DB)입출고매칭용'!$H$2:$H$181)*($B16='DB)입출고매칭용'!$B$2:$B$181)*($K16='DB)입출고매칭용'!$J$2:$J$181),0)),"")} | R16: {=IFERROR(INDEX('DB)입출고매칭용'!$Q$2:$Q$181,MATCH(1,($C16='DB)입출고매칭용'!$H$2:$H$181)*($B16='DB)입출고매칭용'!$B$2:$B$181)*($K16='DB)입출고매칭용'!$J$2:$J$181),0)),"")} | S16: {=IFERROR(INDEX('DB)입출고매칭용'!$R$2:$R$181,MATCH(1,($C16='DB)입출고매칭용'!$H$2:$H$181)*($B16='DB)입출고매칭용'!$B$2:$B$181)*($K16='DB)입출고매칭용'!$J$2:$J$181),0)),"")}
A17: 9 | B17: 46139 | C17: 2026-04-27 오전 9:12:35 | D17: 도톤 | E17: 8809879544101 | F17: 도톤 포레스트 아웃도어 스프레이 150ml | G17: 단일상품 | H17: 0 | I17: 0 | J17: 0 | K17: 1 | L17: 0 | M17: 발송및출고 | N17: 카페24_베럴즈 | O17: 22000 | P17: 22000 | Q17: {=IFERROR(INDEX('DB)입출고매칭용'!$P$2:$P$181,MATCH(1,($C17='DB)입출고매칭용'!$H$2:$H$181)*($B17='DB)입출고매칭용'!$B$2:$B$181)*($K17='DB)입출고매칭용'!$J$2:$J$181),0)),"")} -> 판매청구 | R17: {=IFERROR(INDEX('DB)입출고매칭용'!$Q$2:$Q$181,MATCH(1,($C17='DB)입출고매칭용'!$H$2:$H$181)*($B17='DB)입출고매칭용'!$B$2:$B$181)*($K17='DB)입출고매칭용'!$J$2:$J$181),0)),"")} -> 정상판매 (공구) | S17: {=IFERROR(INDEX('DB)입출고매칭용'!$R$2:$R$181,MATCH(1,($C17='DB)입출고매칭용'!$H$2:$H$181)*($B17='DB)입출고매칭용'!$B$2:$B$181)*($K17='DB)입출고매칭용'!$J$2:$J$181),0)),"")} -> 20260426-0000115
A18: 10 | B18: 46139 | C18: 2026-04-27 오전 9:12:37 | D18: 도톤 | E18: 8809879544101 | F18: 도톤 포레스트 아웃도어 스프레이 150ml | G18: 단일상품 | H18: 0 | I18: 0 | J18: 0 | K18: 1 | L18: 0 | M18: 발송및출고 | N18: 카페24_베럴즈 | O18: 22000 | P18: 22000 | Q18: {=IFERROR(INDEX('DB)입출고매칭용'!$P$2:$P$181,MATCH(1,($C18='DB)입출고매칭용'!$H$2:$H$181)*($B18='DB)입출고매칭용'!$B$2:$B$181)*($K18='DB)입출고매칭용'!$J$2:$J$181),0)),"")} -> 판매청구 | R18: {=IFERROR(INDEX('DB)입출고매칭용'!$Q$2:$Q$181,MATCH(1,($C18='DB)입출고매칭용'!$H$2:$H$181)*($B18='DB)입출고매칭용'!$B$2:$B$181)*($K18='DB)입출고매칭용'!$J$2:$J$181),0)),"")} -> 정상판매 (공구) | S18: {=IFERROR(INDEX('DB)입출고매칭용'!$R$2:$R$181,MATCH(1,($C18='DB)입출고매칭용'!$H$2:$H$181)*($B18='DB)입출고매칭용'!$B$2:$B$181)*($K18='DB)입출고매칭용'!$J$2:$J$181),0)),"")} -> 20260426-0000091
A19: 11 | B19: 46139 | C19: 2026-04-27 오전 9:12:40 | D19: 도톤 | E19: 8809879544101 | F19: 도톤 포레스트 아웃도어 스프레이 150ml | G19: 단일상품 | H19: 0 | I19: 0 | J19: 0 | K19: 1 | L19: 0 | M19: 발송및출고 | N19: 카페24_베럴즈 | O19: 22000 | P19: 22000 | Q19: {=IFERROR(INDEX('DB)입출고매칭용'!$P$2:$P$181,MATCH(1,($C19='DB)입출고매칭용'!$H$2:$H$181)*($B19='DB)입출고매칭용'!$B$2:$B$181)*($K19='DB)입출고매칭용'!$J$2:$J$181),0)),"")} -> 판매청구 | R19: {=IFERROR(INDEX('DB)입출고매칭용'!$Q$2:$Q$181,MATCH(1,($C19='DB)입출고매칭용'!$H$2:$H$181)*($B19='DB)입출고매칭용'!$B$2:$B$181)*($K19='DB)입출고매칭용'!$J$2:$J$181),0)),"")} -> 정상판매 | S19: {=IFERROR(INDEX('DB)입출고매칭용'!$R$2:$R$181,MATCH(1,($C19='DB)입출고매칭용'!$H$2:$H$181)*($B19='DB)입출고매칭용'!$B$2:$B$181)*($K19='DB)입출고매칭용'!$J$2:$J$181),0)),"")} -> 20260425-0000031
A20: 12 | B20: 46139 | C20: 2026-04-27 오전 9:12:45 | D20: 도톤 | E20: 8809879544101 | F20: 도톤 포레스트 아웃도어 스프레이 150ml | G20: 단일상품 | H20: 0 | I20: 0 | J20: 0 | K20: 1 | L20: 0 | M20: 발송및출고 | N20: 카페24_베럴즈 | O20: 22000 | P20: 22000 | Q20: {=IFERROR(INDEX('DB)입출고매칭용'!$P$2:$P$181,MATCH(1,($C20='DB)입출고매칭용'!$H$2:$H$181)*($B20='DB)입출고매칭용'!$B$2:$B$181)*($K20='DB)입출고매칭용'!$J$2:$J$181),0)),"")} -> 판매청구 | R20: {=IFERROR(INDEX('DB)입출고매칭용'!$Q$2:$Q$181,MATCH(1,($C20='DB)입출고매칭용'!$H$2:$H$181)*($B20='DB)입출고매칭용'!$B$2:$B$181)*($K20='DB)입출고매칭용'!$J$2:$J$181),0)),"")} -> 정상판매 | S20: {=IFERROR(INDEX('DB)입출고매칭용'!$R$2:$R$181,MATCH(1,($C20='DB)입출고매칭용'!$H$2:$H$181)*($B20='DB)입출고매칭용'!$B$2:$B$181)*($K20='DB)입출고매칭용'!$J$2:$J$181),0)),"")} -> 20260425-0000019
A21: 13 | B21: 46139 | C21: 2026-04-27 오전 9:12:51 | D21: 도톤 | E21: 8809879544101 | F21: 도톤 포레스트 아웃도어 스프레이 150ml | G21: 단일상품 | H21: 0 | I21: 0 | J21: 0 | K21: 2 | L21: 0 | M21: 발송및출고 | N21: 카페24_베럴즈 | O21: 22000 | P21: 44000 | Q21: {=IFERROR(INDEX('DB)입출고매칭용'!$P$2:$P$181,MATCH(1,($C21='DB)입출고매칭용'!$H$2:$H$181)*($B21='DB)입출고매칭용'!$B$2:$B$181)*($K21='DB)입출고매칭용'!$J$2:$J$181),0)),"")} | R21: {=IFERROR(INDEX('DB)입출고매칭용'!$Q$2:$Q$181,MATCH(1,($C21='DB)입출고매칭용'!$H$2:$H$181)*($B21='DB)입출고매칭용'!$B$2:$B$181)*($K21='DB)입출고매칭용'!$J$2:$J$181),0)),"")} | S21: {=IFERROR(INDEX('DB)입출고매칭용'!$R$2:$R$181,MATCH(1,($C21='DB)입출고매칭용'!$H$2:$H$181)*($B21='DB)입출고매칭용'!$B$2:$B$181)*($K21='DB)입출고매칭용'!$J$2:$J$181),0)),"")}
A22: 14 | B22: 46139 | C22: 2026-04-27 오전 9:12:55 | D22: 도톤 | E22: 8809879544101 | F22: 도톤 포레스트 아웃도어 스프레이 150ml | G22: 단일상품 | H22: 0 | I22: 0 | J22: 0 | K22: 2 | L22: 0 | M22: 발송및출고 | N22: 카페24_베럴즈 | O22: 22000 | P22: 44000 | Q22: {=IFERROR(INDEX('DB)입출고매칭용'!$P$2:$P$181,MATCH(1,($C22='DB)입출고매칭용'!$H$2:$H$181)*($B22='DB)입출고매칭용'!$B$2:$B$181)*($K22='DB)입출고매칭용'!$J$2:$J$181),0)),"")} | R22: {=IFERROR(INDEX('DB)입출고매칭용'!$Q$2:$Q$181,MATCH(1,($C22='DB)입출고매칭용'!$H$2:$H$181)*($B22='DB)입출고매칭용'!$B$2:$B$181)*($K22='DB)입출고매칭용'!$J$2:$J$181),0)),"")} | S22: {=IFERROR(INDEX('DB)입출고매칭용'!$R$2:$R$181,MATCH(1,($C22='DB)입출고매칭용'!$H$2:$H$181)*($B22='DB)입출고매칭용'!$B$2:$B$181)*($K22='DB)입출고매칭용'!$J$2:$J$181),0)),"")}
A23: 15 | B23: 46139 | C23: 2026-04-27 오전 9:12:59 | D23: 도톤 | E23: 8809879544101 | F23: 도톤 포레스트 아웃도어 스프레이 150ml | G23: 단일상품 | H23: 0 | I23: 0 | J23: 0 | K23: 2 | L23: 0 | M23: 발송및출고 | N23: 카페24_베럴즈 | O23: 22000 | P23: 44000 | Q23: {=IFERROR(INDEX('DB)입출고매칭용'!$P$2:$P$181,MATCH(1,($C23='DB)입출고매칭용'!$H$2:$H$181)*($B23='DB)입출고매칭용'!$B$2:$B$181)*($K23='DB)입출고매칭용'!$J$2:$J$181),0)),"")} | R23: {=IFERROR(INDEX('DB)입출고매칭용'!$Q$2:$Q$181,MATCH(1,($C23='DB)입출고매칭용'!$H$2:$H$181)*($B23='DB)입출고매칭용'!$B$2:$B$181)*($K23='DB)입출고매칭용'!$J$2:$J$181),0)),"")} | S23: {=IFERROR(INDEX('DB)입출고매칭용'!$R$2:$R$181,MATCH(1,($C23='DB)입출고매칭용'!$H$2:$H$181)*($B23='DB)입출고매칭용'!$B$2:$B$181)*($K23='DB)입출고매칭용'!$J$2:$J$181),0)),"")}
A24: 16 | B24: 46139 | C24: 2026-04-27 오전 9:13:03 | D24: 도톤 | E24: 8809879544101 | F24: 도톤 포레스트 아웃도어 스프레이 150ml | G24: 단일상품 | H24: 0 | I24: 0 | J24: 0 | K24: 2 | L24: 0 | M24: 발송및출고 | N24: 카페24_베럴즈 | O24: 22000 | P24: 44000 | Q24: {=IFERROR(INDEX('DB)입출고매칭용'!$P$2:$P$181,MATCH(1,($C24='DB)입출고매칭용'!$H$2:$H$181)*($B24='DB)입출고매칭용'!$B$2:$B$181)*($K24='DB)입출고매칭용'!$J$2:$J$181),0)),"")} | R24: {=IFERROR(INDEX('DB)입출고매칭용'!$Q$2:$Q$181,MATCH(1,($C24='DB)입출고매칭용'!$H$2:$H$181)*($B24='DB)입출고매칭용'!$B$2:$B$181)*($K24='DB)입출고매칭용'!$J$2:$J$181),0)),"")} | S24: {=IFERROR(INDEX('DB)입출고매칭용'!$R$2:$R$181,MATCH(1,($C24='DB)입출고매칭용'!$H$2:$H$181)*($B24='DB)입출고매칭용'!$B$2:$B$181)*($K24='DB)입출고매칭용'!$J$2:$J$181),0)),"")}
A25: 17 | B25: 46139 | C25: 2026-04-27 오전 9:13:06 | D25: 도톤 | E25: 8809879544101 | F25: 도톤 포레스트 아웃도어 스프레이 150ml | G25: 단일상품 | H25: 0 | I25: 0 | J25: 0 | K25: 2 | L25: 0 | M25: 발송및출고 | N25: 스마트 스토어 (BETTERS) | O25: 22000 | P25: 44000 | Q25: {=IFERROR(INDEX('DB)입출고매칭용'!$P$2:$P$181,MATCH(1,($C25='DB)입출고매칭용'!$H$2:$H$181)*($B25='DB)입출고매칭용'!$B$2:$B$181)*($K25='DB)입출고매칭용'!$J$2:$J$181),0)),"")} -> 판매청구 | R25: {=IFERROR(INDEX('DB)입출고매칭용'!$Q$2:$Q$181,MATCH(1,($C25='DB)입출고매칭용'!$H$2:$H$181)*($B25='DB)입출고매칭용'!$B$2:$B$181)*($K25='DB)입출고매칭용'!$J$2:$J$181),0)),"")} -> 정상판매 | S25: {=IFERROR(INDEX('DB)입출고매칭용'!$R$2:$R$181,MATCH(1,($C25='DB)입출고매칭용'!$H$2:$H$181)*($B25='DB)입출고매칭용'!$B$2:$B$181)*($K25='DB)입출고매칭용'!$J$2:$J$181),0)),"")} -> 2026042577184211
A26: 18 | B26: 46136 | C26: 2026-04-24 오후 2:38:14 | D26: 도톤 | E26: 8809879544118 | F26: 도톤 포레스트 워터리스 풋클리너 100ml | G26: 단일상품 | H26: 0 | I26: 0 | J26: 0 | K26: 1 | L26: 0 | M26: 발송및출고 | N26: 카페24_베럴즈_b2b | O26: 22000 | P26: 22000 | Q26: {=IFERROR(INDEX('DB)입출고매칭용'!$P$2:$P$181,MATCH(1,($C26='DB)입출고매칭용'!$H$2:$H$181)*($B26='DB)입출고매칭용'!$B$2:$B$181)*($K26='DB)입출고매칭용'!$J$2:$J$181),0)),"")} | R26: {=IFERROR(INDEX('DB)입출고매칭용'!$Q$2:$Q$181,MATCH(1,($C26='DB)입출고매칭용'!$H$2:$H$181)*($B26='DB)입출고매칭용'!$B$2:$B$181)*($K26='DB)입출고매칭용'!$J$2:$J$181),0)),"")} | S26: {=IFERROR(INDEX('DB)입출고매칭용'!$R$2:$R$181,MATCH(1,($C26='DB)입출고매칭용'!$H$2:$H$181)*($B26='DB)입출고매칭용'!$B$2:$B$181)*($K26='DB)입출고매칭용'!$J$2:$J$181),0)),"")}
... A172: 164 | B172: 46125 | C172: 2026-04-13 오전 11:00:03 | D172: 도톤 | E172: 8809879544101 | F172: 도톤 포레스트 아웃도어 스프레이 150ml | G172: 단일상품 | H172: 0 | I172: 0 | J172: 0 | K172: 3 | L172: 0 | M172: 발송및출고 | N172: 카페24_베럴즈 | O172: 22000 | P172: 66000 | Q172: {=IFERROR(INDEX('DB)입출고매칭용'!$P$2:$P$181,MATCH(1,($C172='DB)입출고매칭용'!$H$2:$H$181)*($B172='DB)입출고매칭용'!$B$2:$B$181)*($K172='DB)입출고매칭용'!$J$2:$J$181),0)),"")} | R172: {=IFERROR(INDEX('DB)입출고매칭용'!$Q$2:$Q$181,MATCH(1,($C172='DB)입출고매칭용'!$H$2:$H$181)*($B172='DB)입출고매칭용'!$B$2:$B$181)*($K172='DB)입출고매칭용'!$J$2:$J$181),0)),"")} | S172: {=IFERROR(INDEX('DB)입출고매칭용'!$R$2:$R$181,MATCH(1,($C172='DB)입출고매칭용'!$H$2:$H$181)*($B172='DB)입출고매칭용'!$B$2:$B$181)*($K172='DB)입출고매칭용'!$J$2:$J$181),0)),"")}
B173: 46125 | C173: 2026-04-13 오후 2:13:11 | D173: 도톤 | E173: 8809879544101 | F173: 도톤 포레스트 아웃도어 스프레이 150ml | G173: 단일상품 | H173: 0 | I173: 1 | J173: 0 | K173: 0 | L173: 0 | M173: 발송취소 | N173: 카페24_베럴즈 | O173: 22000 | P173: 0 | Q173: {=IFERROR(INDEX('DB)입출고매칭용'!$P$2:$P$181,MATCH(1,($C173='DB)입출고매칭용'!$H$2:$H$181)*($B173='DB)입출고매칭용'!$B$2:$B$181)*($K173='DB)입출고매칭용'!$J$2:$J$181),0)),"")} | R173: {=IFERROR(INDEX('DB)입출고매칭용'!$Q$2:$Q$181,MATCH(1,($C173='DB)입출고매칭용'!$H$2:$H$181)*($B173='DB)입출고매칭용'!$B$2:$B$181)*($K173='DB)입출고매칭용'!$J$2:$J$181),0)),"")} | S173: {=IFERROR(INDEX('DB)입출고매칭용'!$R$2:$R$181,MATCH(1,($C173='DB)입출고매칭용'!$H$2:$H$181)*($B173='DB)입출고매칭용'!$B$2:$B$181)*($K173='DB)입출고매칭용'!$J$2:$J$181),0)),"")}
A174: 165 | B174: 46125 | C174: 2026-04-13 오후 2:16:17 | D174: 도톤 | E174: 8809879544101 | F174: 도톤 포레스트 아웃도어 스프레이 150ml | G174: 단일상품 | H174: 0 | I174: 0 | J174: 0 | K174: 1 | L174: 0 | M174: 발송및출고 | N174: 카페24_베럴즈 | O174: 22000 | P174: 22000 | Q174: {=IFERROR(INDEX('DB)입출고매칭용'!$P$2:$P$181,MATCH(1,($C174='DB)입출고매칭용'!$H$2:$H$181)*($B174='DB)입출고매칭용'!$B$2:$B$181)*($K174='DB)입출고매칭용'!$J$2:$J$181),0)),"")} -> 판매청구 | R174: {=IFERROR(INDEX('DB)입출고매칭용'!$Q$2:$Q$181,MATCH(1,($C174='DB)입출고매칭용'!$H$2:$H$181)*($B174='DB)입출고매칭용'!$B$2:$B$181)*($K174='DB)입출고매칭용'!$J$2:$J$181),0)),"")} -> 정상판매 (공구) | S174: {=IFERROR(INDEX('DB)입출고매칭용'!$R$2:$R$181,MATCH(1,($C174='DB)입출고매칭용'!$H$2:$H$181)*($B174='DB)입출고매칭용'!$B$2:$B$181)*($K174='DB)입출고매칭용'!$J$2:$J$181),0)),"")} -> 20260413-0000052
A175: 166 | B175: 46125 | C175: 2026-04-13 오후 2:37:30 | D175: 도톤 | E175: 8809879544101 | F175: 도톤 포레스트 아웃도어 스프레이 150ml | G175: 단일상품 | H175: 0 | I175: 0 | J175: 0 | K175: 1 | L175: 0 | M175: 발송및출고 | N175: 카페24_베럴즈 | O175: 22000 | P175: 22000 | Q175: {=IFERROR(INDEX('DB)입출고매칭용'!$P$2:$P$181,MATCH(1,($C175='DB)입출고매칭용'!$H$2:$H$181)*($B175='DB)입출고매칭용'!$B$2:$B$181)*($K175='DB)입출고매칭용'!$J$2:$J$181),0)),"")} -> 판매청구 | R175: {=IFERROR(INDEX('DB)입출고매칭용'!$Q$2:$Q$181,MATCH(1,($C175='DB)입출고매칭용'!$H$2:$H$181)*($B175='DB)입출고매칭용'!$B$2:$B$181)*($K175='DB)입출고매칭용'!$J$2:$J$181),0)),"")} -> 정상판매 (공구) | S175: {=IFERROR(INDEX('DB)입출고매칭용'!$R$2:$R$181,MATCH(1,($C175='DB)입출고매칭용'!$H$2:$H$181)*($B175='DB)입출고매칭용'!$B$2:$B$181)*($K175='DB)입출고매칭용'!$J$2:$J$181),0)),"")} -> 20260413-0000308
A176: 167 | B176: 46125 | C176: 2026-04-13 오후 3:05:25 | D176: 도톤 | E176: 8809879544101 | F176: 도톤 포레스트 아웃도어 스프레이 150ml | G176: 단일상품 | H176: 0 | I176: 0 | J176: 0 | K176: 3 | L176: 0 | M176: 발송및출고 | N176: 카페24_베럴즈 | O176: 22000 | P176: 66000 | Q176: {=IFERROR(INDEX('DB)입출고매칭용'!$P$2:$P$181,MATCH(1,($C176='DB)입출고매칭용'!$H$2:$H$181)*($B176='DB)입출고매칭용'!$B$2:$B$181)*($K176='DB)입출고매칭용'!$J$2:$J$181),0)),"")} | R176: {=IFERROR(INDEX('DB)입출고매칭용'!$Q$2:$Q$181,MATCH(1,($C176='DB)입출고매칭용'!$H$2:$H$181)*($B176='DB)입출고매칭용'!$B$2:$B$181)*($K176='DB)입출고매칭용'!$J$2:$J$181),0)),"")} | S176: {=IFERROR(INDEX('DB)입출고매칭용'!$R$2:$R$181,MATCH(1,($C176='DB)입출고매칭용'!$H$2:$H$181)*($B176='DB)입출고매칭용'!$B$2:$B$181)*($K176='DB)입출고매칭용'!$J$2:$J$181),0)),"")}
A177: 168 | B177: 46125 | C177: 2026-04-13 오후 3:05:36 | D177: 도톤 | E177: 8809879544101 | F177: 도톤 포레스트 아웃도어 스프레이 150ml | G177: 단일상품 | H177: 0 | I177: 0 | J177: 0 | K177: 1 | L177: 0 | M177: 발송및출고 | N177: 카페24_베럴즈 | O177: 22000 | P177: 22000 | Q177: {=IFERROR(INDEX('DB)입출고매칭용'!$P$2:$P$181,MATCH(1,($C177='DB)입출고매칭용'!$H$2:$H$181)*($B177='DB)입출고매칭용'!$B$2:$B$181)*($K177='DB)입출고매칭용'!$J$2:$J$181),0)),"")} -> 판매청구 | R177: {=IFERROR(INDEX('DB)입출고매칭용'!$Q$2:$Q$181,MATCH(1,($C177='DB)입출고매칭용'!$H$2:$H$181)*($B177='DB)입출고매칭용'!$B$2:$B$181)*($K177='DB)입출고매칭용'!$J$2:$J$181),0)),"")} -> 정상판매 (공구) | S177: {=IFERROR(INDEX('DB)입출고매칭용'!$R$2:$R$181,MATCH(1,($C177='DB)입출고매칭용'!$H$2:$H$181)*($B177='DB)입출고매칭용'!$B$2:$B$181)*($K177='DB)입출고매칭용'!$J$2:$J$181),0)),"")} -> 20260413-0000205
A178: 169 | B178: 46125 | C178: 2026-04-13 오후 3:05:40 | D178: 도톤 | E178: 8809879544101 | F178: 도톤 포레스트 아웃도어 스프레이 150ml | G178: 단일상품 | H178: 0 | I178: 0 | J178: 0 | K178: 1 | L178: 0 | M178: 발송및출고 | N178: 카페24_베럴즈 | O178: 22000 | P178: 22000 | Q178: {=IFERROR(INDEX('DB)입출고매칭용'!$P$2:$P$181,MATCH(1,($C178='DB)입출고매칭용'!$H$2:$H$181)*($B178='DB)입출고매칭용'!$B$2:$B$181)*($K178='DB)입출고매칭용'!$J$2:$J$181),0)),"")} -> 판매청구 | R178: {=IFERROR(INDEX('DB)입출고매칭용'!$Q$2:$Q$181,MATCH(1,($C178='DB)입출고매칭용'!$H$2:$H$181)*($B178='DB)입출고매칭용'!$B$2:$B$181)*($K178='DB)입출고매칭용'!$J$2:$J$181),0)),"")} -> 정상판매 (공구) | S178: {=IFERROR(INDEX('DB)입출고매칭용'!$R$2:$R$181,MATCH(1,($C178='DB)입출고매칭용'!$H$2:$H$181)*($B178='DB)입출고매칭용'!$B$2:$B$181)*($K178='DB)입출고매칭용'!$J$2:$J$181),0)),"")} -> 20260413-0000191
A179: 170 | B179: 46125 | C179: 2026-04-13 오후 3:05:44 | D179: 도톤 | E179: 8809879544101 | F179: 도톤 포레스트 아웃도어 스프레이 150ml | G179: 단일상품 | H179: 0 | I179: 0 | J179: 0 | K179: 1 | L179: 0 | M179: 발송및출고 | N179: 카페24_베럴즈 | O179: 22000 | P179: 22000 | Q179: {=IFERROR(INDEX('DB)입출고매칭용'!$P$2:$P$181,MATCH(1,($C179='DB)입출고매칭용'!$H$2:$H$181)*($B179='DB)입출고매칭용'!$B$2:$B$181)*($K179='DB)입출고매칭용'!$J$2:$J$181),0)),"")} -> 판매청구 | R179: {=IFERROR(INDEX('DB)입출고매칭용'!$Q$2:$Q$181,MATCH(1,($C179='DB)입출고매칭용'!$H$2:$H$181)*($B179='DB)입출고매칭용'!$B$2:$B$181)*($K179='DB)입출고매칭용'!$J$2:$J$181),0)),"")} -> 정상판매 (공구) | S179: {=IFERROR(INDEX('DB)입출고매칭용'!$R$2:$R$181,MATCH(1,($C179='DB)입출고매칭용'!$H$2:$H$181)*($B179='DB)입출고매칭용'!$B$2:$B$181)*($K179='DB)입출고매칭용'!$J$2:$J$181),0)),"")} -> 20260413-0000161
A180: 171 | B180: 46125 | C180: 2026-04-13 오후 3:05:50 | D180: 도톤 | E180: 8809879544101 | F180: 도톤 포레스트 아웃도어 스프레이 150ml | G180: 단일상품 | H180: 0 | I180: 0 | J180: 0 | K180: 2 | L180: 0 | M180: 발송및출고 | N180: 카페24_베럴즈 | O180: 22000 | P180: 44000 | Q180: {=IFERROR(INDEX('DB)입출고매칭용'!$P$2:$P$181,MATCH(1,($C180='DB)입출고매칭용'!$H$2:$H$181)*($B180='DB)입출고매칭용'!$B$2:$B$181)*($K180='DB)입출고매칭용'!$J$2:$J$181),0)),"")} | R180: {=IFERROR(INDEX('DB)입출고매칭용'!$Q$2:$Q$181,MATCH(1,($C180='DB)입출고매칭용'!$H$2:$H$181)*($B180='DB)입출고매칭용'!$B$2:$B$181)*($K180='DB)입출고매칭용'!$J$2:$J$181),0)),"")} | S180: {=IFERROR(INDEX('DB)입출고매칭용'!$R$2:$R$181,MATCH(1,($C180='DB)입출고매칭용'!$H$2:$H$181)*($B180='DB)입출고매칭용'!$B$2:$B$181)*($K180='DB)입출고매칭용'!$J$2:$J$181),0)),"")}
A181: 172 | B181: 46125 | C181: 2026-04-13 오후 3:05:55 | D181: 도톤 | E181: 8809879544101 | F181: 도톤 포레스트 아웃도어 스프레이 150ml | G181: 단일상품 | H181: 0 | I181: 0 | J181: 0 | K181: 2 | L181: 0 | M181: 발송및출고 | N181: 카페24_베럴즈 | O181: 22000 | P181: 44000 | Q181: {=IFERROR(INDEX('DB)입출고매칭용'!$P$2:$P$181,MATCH(1,($C181='DB)입출고매칭용'!$H$2:$H$181)*($B181='DB)입출고매칭용'!$B$2:$B$181)*($K181='DB)입출고매칭용'!$J$2:$J$181),0)),"")} | R181: {=IFERROR(INDEX('DB)입출고매칭용'!$Q$2:$Q$181,MATCH(1,($C181='DB)입출고매칭용'!$H$2:$H$181)*($B181='DB)입출고매칭용'!$B$2:$B$181)*($K181='DB)입출고매칭용'!$J$2:$J$181),0)),"")} | S181: {=IFERROR(INDEX('DB)입출고매칭용'!$R$2:$R$181,MATCH(1,($C181='DB)입출고매칭용'!$H$2:$H$181)*($B181='DB)입출고매칭용'!$B$2:$B$181)*($K181='DB)입출고매칭용'!$J$2:$J$181),0)),"")}
A182: 173 | B182: 46125 | C182: 2026-04-13 오후 3:05:59 | D182: 도톤 | E182: 8809879544101 | F182: 도톤 포레스트 아웃도어 스프레이 150ml | G182: 단일상품 | H182: 0 | I182: 0 | J182: 0 | K182: 2 | L182: 0 | M182: 발송및출고 | N182: 카페24_베럴즈 | O182: 22000 | P182: 44000 | Q182: {=IFERROR(INDEX('DB)입출고매칭용'!$P$2:$P$181,MATCH(1,($C182='DB)입출고매칭용'!$H$2:$H$181)*($B182='DB)입출고매칭용'!$B$2:$B$181)*($K182='DB)입출고매칭용'!$J$2:$J$181),0)),"")} | R182: {=IFERROR(INDEX('DB)입출고매칭용'!$Q$2:$Q$181,MATCH(1,($C182='DB)입출고매칭용'!$H$2:$H$181)*($B182='DB)입출고매칭용'!$B$2:$B$181)*($K182='DB)입출고매칭용'!$J$2:$J$181),0)),"")} | S182: {=IFERROR(INDEX('DB)입출고매칭용'!$R$2:$R$181,MATCH(1,($C182='DB)입출고매칭용'!$H$2:$H$181)*($B182='DB)입출고매칭용'!$B$2:$B$181)*($K182='DB)입출고매칭용'!$J$2:$J$181),0)),"")}
A183: 174 | B183: 46121 | C183: 2026-04-09 오후 1:22:35 | D183: 도톤 | E183: 8809879544118 | F183: 도톤 포레스트 워터리스 풋클리너 100ml | G183: 단일상품 | H183: 0 | I183: 0 | J183: 0 | K183: 2 | L183: 0 | M183: 발송및출고 | N183: 카페24_베럴즈 | O183: 22000 | P183: 44000 | Q183: {=IFERROR(INDEX('DB)입출고매칭용'!$P$2:$P$181,MATCH(1,($C183='DB)입출고매칭용'!$H$2:$H$181)*($B183='DB)입출고매칭용'!$B$2:$B$181)*($K183='DB)입출고매칭용'!$J$2:$J$181),0)),"")} -> 판매청구 | R183: {=IFERROR(INDEX('DB)입출고매칭용'!$Q$2:$Q$181,MATCH(1,($C183='DB)입출고매칭용'!$H$2:$H$181)*($B183='DB)입출고매칭용'!$B$2:$B$181)*($K183='DB)입출고매칭용'!$J$2:$J$181),0)),"")} -> 정상판매 | S183: {=IFERROR(INDEX('DB)입출고매칭용'!$R$2:$R$181,MATCH(1,($C183='DB)입출고매칭용'!$H$2:$H$181)*($B183='DB)입출고매칭용'!$B$2:$B$181)*($K183='DB)입출고매칭용'!$J$2:$J$181),0)),"")} -> 20260408-0000379
A184: 175 | B184: 46121 | C184: 2026-04-09 오후 1:22:35 | D184: 도톤 | E184: 8809879544118 | F184: 도톤 포레스트 워터리스 풋클리너 100ml | G184: 단일상품 | H184: 0 | I184: 0 | J184: 0 | K184: 2 | L184: 0 | M184: 발송및출고 | N184: 카페24_베럴즈 | O184: 22000 | P184: 44000 | Q184: {=IFERROR(INDEX('DB)입출고매칭용'!$P$2:$P$181,MATCH(1,($C184='DB)입출고매칭용'!$H$2:$H$181)*($B184='DB)입출고매칭용'!$B$2:$B$181)*($K184='DB)입출고매칭용'!$J$2:$J$181),0)),"")} -> 판매청구 | R184: {=IFERROR(INDEX('DB)입출고매칭용'!$Q$2:$Q$181,MATCH(1,($C184='DB)입출고매칭용'!$H$2:$H$181)*($B184='DB)입출고매칭용'!$B$2:$B$181)*($K184='DB)입출고매칭용'!$J$2:$J$181),0)),"")} -> 정상판매 | S184: {=IFERROR(INDEX('DB)입출고매칭용'!$R$2:$R$181,MATCH(1,($C184='DB)입출고매칭용'!$H$2:$H$181)*($B184='DB)입출고매칭용'!$B$2:$B$181)*($K184='DB)입출고매칭용'!$J$2:$J$181),0)),"")} -> 20260408-0000379
A185: 176 | B185: 46120 | C185: 2026-04-08 오후 12:51:54 | D185: 도톤 | E185: 8809879544118 | F185: 도톤 포레스트 워터리스 풋클리너 100ml | G185: 단일상품 | H185: 0 | I185: 0 | J185: 0 | K185: 1 | L185: 0 | M185: 발송및출고 | N185: 카페24_베럴즈 | O185: 22000 | P185: 22000 | Q185: {=IFERROR(INDEX('DB)입출고매칭용'!$P$2:$P$181,MATCH(1,($C185='DB)입출고매칭용'!$H$2:$H$181)*($B185='DB)입출고매칭용'!$B$2:$B$181)*($K185='DB)입출고매칭용'!$J$2:$J$181),0)),"")} -> 판매청구 | R185: {=IFERROR(INDEX('DB)입출고매칭용'!$Q$2:$Q$181,MATCH(1,($C185='DB)입출고매칭용'!$H$2:$H$181)*($B185='DB)입출고매칭용'!$B$2:$B$181)*($K185='DB)입출고매칭용'!$J$2:$J$181),0)),"")} -> 0 | S185: {=IFERROR(INDEX('DB)입출고매칭용'!$R$2:$R$181,MATCH(1,($C185='DB)입출고매칭용'!$H$2:$H$181)*($B185='DB)입출고매칭용'!$B$2:$B$181)*($K185='DB)입출고매칭용'!$J$2:$J$181),0)),"")} -> 20260407-0000171
... A190: 181 | B190: 46113 | C190: 2026-04-01 오후 3:23:21 | D190: 도톤 | E190: 8809879544101 | F190: 도톤 포레스트 아웃도어 스프레이 150ml | G190: 단일상품 | H190: 0 | I190: 0 | J190: 0 | K190: 1 | L190: 0 | M190: 발송및출고 | N190: 카페24_베럴즈_b2b | O190: 22000 | P190: 22000 | Q190: {=IFERROR(INDEX('DB)입출고매칭용'!$P$2:$P$181,MATCH(1,($C190='DB)입출고매칭용'!$H$2:$H$181)*($B190='DB)입출고매칭용'!$B$2:$B$181)*($K190='DB)입출고매칭용'!$J$2:$J$181),0)),"")} -> 미청구 | R190: {=IFERROR(INDEX('DB)입출고매칭용'!$Q$2:$Q$181,MATCH(1,($C190='DB)입출고매칭용'!$H$2:$H$181)*($B190='DB)입출고매칭용'!$B$2:$B$181)*($K190='DB)입출고매칭용'!$J$2:$J$181),0)),"")} -> 위탁이동 - 몰리스하남 | S190: {=IFERROR(INDEX('DB)입출고매칭용'!$R$2:$R$181,MATCH(1,($C190='DB)입출고매칭용'!$H$2:$H$181)*($B190='DB)입출고매칭용'!$B$2:$B$181)*($K190='DB)입출고매칭용'!$J$2:$J$181),0)),"")} -> 20260401-0000042

Sheet DB)입출고매칭용
A1: 공급처명 | B1: 주문일자 | C1: 판매처상품코드 | D1: 판매처상품명 | E1: 판매처명 | F1: 송장번호 | G1: 주문상품출고일시 | H1: 발송일자 | I1: 상품옵션 | J1: 주문수량 | K1: 주문자 | L1: 수령자 | M1: 재고매칭(1)바코드번호 | N1: 재고매칭(1)상품명 | O1: 재고매칭(1)주문수량 | P1: 판매구분 | Q1: 내용 | R1: 판매처주문번호 | S1: 판매상세 (판매 수수료율)
A2: 도톤 | B2: 46142 | C2: P000BMBG | D2: [영이공구특가 이벤트 상품] 도톤 포레스트 아웃도어 해충방지 스프레이 150ml | E2: 카페24_베럴즈 | F2: 92234581143 | G2: 2026-04-30 오전 9:25:44 | H2: 2026-04-30 오전 9:25:44 | I2: 수량=공구 2개세트 (32%할인) | J2: 1 | K2: ="최*솔" -> 최*솔 | L2: ="최*솔" -> 최*솔 | M2: 8809879544101 | N2: 도톤 포레스트 아웃도어 스프레이 150ml | O2: 2 | P2: 판매청구 | Q2: 정상판매 (공구) | R2: ="20260429-0000187" -> 20260429-0000187
A3: 도톤 | B3: 46142 | C3: 12423379709 | D3: 도톤 포레스트 아웃도어 스프레이 150ml 강아지 해충방지 진드기 | E3: 스마트 스토어 (BETTERS) | F3: 92234617171 | G3: 2026-04-30 오후 4:44:49 | H3: 2026-04-30 오후 4:44:49 | J3: 1 | K3: ="장*은" -> 장*은 | L3: ="장*은" -> 장*은 | M3: 8809879544101 | N3: 도톤 포레스트 아웃도어 스프레이 150ml | O3: 1 | P3: 판매청구 | Q3: 정상판매 | R3: ="2026043032327861" -> 2026043032327861
A4: 도톤 | B4: 46141 | C4: P000BMBG | D4: [영이공구특가 이벤트 상품] 도톤 포레스트 아웃도어 해충방지 스프레이 150ml | E4: 카페24_베럴즈 | F4: 92234538362 | G4: 2026-04-29 오전 9:55:02 | H4: 2026-04-29 오전 9:55:02 | I4: 수량=공구특가 1개 (25%할인) | J4: 1 | K4: ="윤*은" -> 윤*은 | L4: ="윤*은" -> 윤*은 | M4: 8809879544101 | N4: 도톤 포레스트 아웃도어 스프레이 150ml | O4: 1 | P4: 판매청구 | Q4: 정상판매 (공구) | R4: ="20260428-0000100" -> 20260428-0000100
A5: 도톤 | B5: 46141 | C5: 12423379709 | D5: 도톤 포레스트 아웃도어 스프레이 150ml 강아지 해충방지 진드기 | E5: 스마트 스토어 (BETTERS) | F5: 92234560261 | G5: 2026-04-29 오후 4:07:28 | H5: 2026-04-29 오후 4:07:28 | J5: 1 | K5: ="정*주" -> 정*주 | L5: ="정*주" -> 정*주 | M5: 8809879544101 | N5: 도톤 포레스트 아웃도어 스프레이 150ml | O5: 1 | P5: 판매청구 | Q5: 정상판매 | R5: ="2026042891931141" -> 2026042891931141
A6: 도톤 | B6: 46141 | C6: P000BMBG | D6: [영이공구특가 이벤트 상품] 도톤 포레스트 아웃도어 해충방지 스프레이 150ml | E6: 카페24_베럴즈 | F6: 92234560250 | G6: 2026-04-29 오후 4:07:30 | H6: 2026-04-29 오후 4:07:30 | I6: 수량=공구특가 1개 (25%할인) | J6: 1 | K6: ="김*아" -> 김*아 | L6: ="김*아" -> 김*아 | M6: 8809879544101 | N6: 도톤 포레스트 아웃도어 스프레이 150ml | O6: 1 | P6: 판매청구 | Q6: 정상판매 (공구) | R6: ="20260429-0000099" -> 20260429-0000099
A7: 도톤 | B7: 46141 | C7: P000BMBG | D7: [영이공구특가 이벤트 상품] 도톤 포레스트 아웃도어 해충방지 스프레이 150ml | E7: 카페24_베럴즈 | F7: 92234560246 | G7: 2026-04-29 오후 4:07:33 | H7: 2026-04-29 오후 4:07:33 | I7: 수량=공구특가 1개 (25%할인) | J7: 1 | K7: ="정*진" -> 정*진 | L7: ="정*진" -> 정*진 | M7: 8809879544101 | N7: 도톤 포레스트 아웃도어 스프레이 150ml | O7: 1 | P7: 판매청구 | Q7: 정상판매 (공구) | R7: ="20260429-0000122" -> 20260429-0000122
A8: 도톤 | B8: 46139 | C8: P000BLYX | D8: 도톤 포레스트 워터리스 풋클리너 강아지 발세정제 100ml | E8: 카페24_베럴즈 | F8: 92234417343 | G8: 2026-04-27 오전 9:10:56 | H8: 2026-04-27 오전 9:10:56 | J8: 1 | K8: ="김*명" -> 김*명 | L8: ="김*명" -> 김*명 | M8: 8809879544118 | N8: 도톤 포레스트 워터리스 풋클리너 100ml | O8: 1 | P8: 판매청구 | Q8: 정상판매 | R8: ="20260425-0000045" -> 20260425-0000045
A9: 도톤 | B9: 46139 | C9: P000BMBG | D9: [영이공구특가 이벤트 상품] 도톤 포레스트 아웃도어 해충방지 스프레이 150ml | E9: 카페24_베럴즈 | F9: 92234417332 | G9: 2026-04-27 오전 9:13:03 | H9: 2026-04-27 오전 9:13:03 | I9: 수량=공구 2개세트 (32%할인) | J9: 1 | K9: ="김*지" -> 김*지 | L9: ="김*지" -> 김*지 | M9: 8809879544101 | N9: 도톤 포레스트 아웃도어 스프레이 150ml | O9: 2 | P9: 판매청구 | Q9: 정상판매 (공구) | R9: ="20260426-0000011" -> 20260426-0000011
A10: 도톤 | B10: 46139 | C10: P000BMBG | D10: [영이공구특가 이벤트 상품] 도톤 포레스트 아웃도어 해충방지 스프레이 150ml | E10: 카페24_베럴즈 | F10: 92234417306 | G10: 2026-04-27 오전 9:12:59 | H10: 2026-04-27 오전 9:12:59 | I10: 수량=공구 2개세트 (32%할인) | J10: 1 | K10: ="이*정" -> 이*정 | L10: ="이*정" -> 이*정 | M10: 8809879544101 | N10: 도톤 포레스트 아웃도어 스프레이 150ml | O10: 2 | P10: 판매청구 | Q10: 정상판매 (공구) | R10: ="20260426-0000062" -> 20260426-0000062
A11: 도톤 | B11: 46139 | C11: P000BMBG | D11: [영이공구특가 이벤트 상품] 도톤 포레스트 아웃도어 해충방지 스프레이 150ml | E11: 카페24_베럴즈 | F11: 92234417251 | G11: 2026-04-27 오전 9:12:55 | H11: 2026-04-27 오전 9:12:55 | I11: 수량=공구 2개세트 (32%할인) | J11: 1 | K11: ="이*은" -> 이*은 | L11: ="이*은" -> 이*은 | M11: 8809879544101 | N11: 도톤 포레스트 아웃도어 스프레이 150ml | O11: 2 | P11: 판매청구 | Q11: 정상판매 (공구) | R11: ="20260426-0000221" -> 20260426-0000221
A12: 도톤 | B12: 46139 | C12: P000BMBG | D12: [영이공구특가 이벤트 상품] 도톤 포레스트 아웃도어 해충방지 스프레이 150ml | E12: 카페24_베럴즈 | F12: 92234417214 | G12: 2026-04-27 오전 9:12:51 | H12: 2026-04-27 오전 9:12:51 | I12: 수량=공구 2개세트 (32%할인) | J12: 1 | K12: ="김*경" -> 김*경 | L12: ="박*수" -> 박*수 | M12: 8809879544101 | N12: 도톤 포레스트 아웃도어 스프레이 150ml | O12: 2 | P12: 판매청구 | Q12: 정상판매 (공구) | R12: ="20260427-0000031" -> 20260427-0000031
A13: 도톤 | B13: 46139 | C13: P000BMBG | D13: [영이공구특가 이벤트 상품] 도톤 포레스트 아웃도어 해충방지 스프레이 150ml | E13: 카페24_베럴즈 | F13: 92234417203 | G13: 2026-04-27 오전 9:11:28 | H13: 2026-04-27 오전 9:11:29 | I13: 수량=공구특가 1개 (25%할인) | J13: 1 | K13: ="김*연" -> 김*연 | L13: ="김*연" -> 김*연 | M13: 8809879544101 | N13: 도톤 포레스트 아웃도어 스프레이 150ml | O13: 1 | P13: 판매청구 | Q13: 정상판매 (공구) | R13: ="20260427-0000052" -> 20260427-0000052
A14: 도톤 | B14: 46139 | C14: 12423379709 | D14: 도톤 포레스트 아웃도어 스프레이 150ml 강아지 해충방지 진드기 | E14: 스마트 스토어 (BETTERS) | F14: 92234417634 | G14: 2026-04-27 오전 9:13:06 | H14: 2026-04-27 오전 9:13:06 | J14: 2 | K14: ="김*주" -> 김*주 | L14: ="김*주" -> 김*주 | M14: 8809879544101 | N14: 도톤 포레스트 아웃도어 스프레이 150ml | O14: 2 | P14: 판매청구 | Q14: 정상판매 | R14: ="2026042577184211" -> 2026042577184211
A15: 도톤 | B15: 46139 | C15: P000BLYY | D15: 도톤 포레스트 아웃도어 스프레이 150ml 강아지 해충방지 진드기 | E15: 카페24_베럴즈 | F15: 92234417660 | G15: 2026-04-27 오전 9:12:45 | H15: 2026-04-27 오전 9:12:45 | J15: 1 | K15: ="*" -> * | L15: ="*" -> * | M15: 8809879544101 | N15: 도톤 포레스트 아웃도어 스프레이 150ml | O15: 1 | P15: 판매청구 | Q15: 정상판매 | R15: ="20260425-0000019" -> 20260425-0000019
A16: 도톤 | B16: 46139 | C16: P000BLYY | D16: 도톤 포레스트 아웃도어 스프레이 150ml 강아지 해충방지 진드기 | E16: 카페24_베럴즈 | F16: 92234417656 | G16: 2026-04-27 오전 9:12:40 | H16: 2026-04-27 오전 9:12:40 | J16: 1 | K16: ="양*아" -> 양*아 | L16: ="양*아" -> 양*아 | M16: 8809879544101 | N16: 도톤 포레스트 아웃도어 스프레이 150ml | O16: 1 | P16: 판매청구 | Q16: 정상판매 | R16: ="20260425-0000031" -> 20260425-0000031
A17: 도톤 | B17: 46139 | C17: P000BMBG | D17: [영이공구특가 이벤트 상품] 도톤 포레스트 아웃도어 해충방지 스프레이 150ml | E17: 카페24_베럴즈 | F17: 92234417586 | G17: 2026-04-27 오전 9:12:37 | H17: 2026-04-27 오전 9:12:37 | I17: 수량=공구특가 1개 (25%할인) | J17: 1 | K17: ="박*선" -> 박*선 | L17: ="박*선" -> 박*선 | M17: 8809879544101 | N17: 도톤 포레스트 아웃도어 스프레이 150ml | O17: 1 | P17: 판매청구 | Q17: 정상판매 (공구) | R17: ="20260426-0000091" -> 20260426-0000091
A18: 도톤 | B18: 46139 | C18: P000BMBG | D18: [영이공구특가 이벤트 상품] 도톤 포레스트 아웃도어 해충방지 스프레이 150ml | E18: 카페24_베럴즈 | F18: 92234417435 | G18: 2026-04-27 오전 9:12:35 | H18: 2026-04-27 오전 9:12:35 | I18: 수량=공구특가 1개 (25%할인) | J18: 1 | K18: ="한*연" -> 한*연 | L18: ="한*연" -> 한*연 | M18: 8809879544101 | N18: 도톤 포레스트 아웃도어 스프레이 150ml | O18: 1 | P18: 판매청구 | Q18: 정상판매 (공구) | R18: ="20260426-0000115" -> 20260426-0000115
A19: 도톤 | B19: 46136 | C19: P000BMBG | D19: [영이공구특가 이벤트 상품] 도톤 포레스트 아웃도어 해충방지 스프레이 150ml | E19: 카페24_베럴즈 | F19: 92234383113 | G19: 2026-04-24 오후 2:38:37 | H19: 2026-04-24 오후 2:38:37 | I19: 수량=공구 2개세트 (32%할인) | J19: 1 | K19: ="채*민" -> 채*민 | L19: ="채*민" -> 채*민 | M19: 8809879544101 | N19: 도톤 포레스트 아웃도어 스프레이 150ml | O19: 2 | P19: 판매청구 | Q19: 정상판매 (공구) | R19: ="20260424-0000051" -> 20260424-0000051
A20: 도톤 | B20: 46136 | C20: P000BMBG | D20: [영이공구특가 이벤트 상품] 도톤 포레스트 아웃도어 해충방지 스프레이 150ml | E20: 카페24_베럴즈 | F20: 92234383102 | G20: 2026-04-24 오후 2:38:40 | H20: 2026-04-24 오후 2:38:40 | I20: 수량=공구 2개세트 (32%할인) | J20: 1 | K20: ="오*아" -> 오*아 | L20: ="오*아" -> 오*아 | M20: 8809879544101 | N20: 도톤 포레스트 아웃도어 스프레이 150ml | O20: 2 | P20: 판매청구 | Q20: 정상판매 (공구) | R20: ="20260424-0000065" -> 20260424-0000065
A21: 도톤 | B21: 46136 | C21: P000BMBG | D21: [영이공구특가 이벤트 상품] 도톤 포레스트 아웃도어 해충방지 스프레이 150ml | E21: 카페24_베럴즈 | F21: 92234367061 | G21: 2026-04-24 오후 2:38:30 | H21: 2026-04-24 오후 2:38:30 | I21: 수량=공구 2개세트 (32%할인) | J21: 1 | K21: ="김*희" -> 김*희 | L21: ="김*희" -> 김*희 | M21: 8809879544101 | N21: 도톤 포레스트 아웃도어 스프레이 150ml | O21: 2 | P21: 판매청구 | Q21: 정상판매 (공구) | R21: ="20260423-0000261" -> 20260423-0000261
A22: 도톤 | B22: 46136 | C22: P000BLYY | D22: 도톤 포레스트 아웃도어 스프레이 150ml 강아지 해충방지 진드기 | E22: 카페24_베럴즈_b2b | F22: 92234367050 | G22: 2026-04-24 오후 2:38:14 | H22: 2026-04-24 오후 2:38:15 | J22: 1 | K22: ="도*(네****인)" -> 도*(네****인) | L22: ="이*기" -> 이*기 | M22: 8809879544101 | N22: 도톤 포레스트 아웃도어 스프레이 150ml | O22: 1 | P22: 미청구 | Q22: 네이버브랜드커넥트(시딩) | R22: ="20260424-0000043" -> 20260424-0000043
A23: 도톤 | B23: 46136 | C23: P000BLYX | D23: 도톤 포레스트 워터리스 풋클리너 강아지 발세정제 100ml | E23: 카페24_베럴즈_b2b | F23: 92234367050 | G23: 2026-04-24 오후 2:38:14 | H23: 2026-04-24 오후 2:38:15 | J23: 1 | K23: ="도*(네****인)" -> 도*(네****인) | L23: ="이*기" -> 이*기 | M23: 8809879544118 | N23: 도톤 포레스트 워터리스 풋클리너 100ml | O23: 1 | P23: 미청구 | Q23: 네이버브랜드커넥트(시딩) | R23: ="20260424-0000043" -> 20260424-0000043
A24: 도톤 | B24: 46135 | C24: P000BMBG | D24: [영이공구특가 이벤트 상품] 도톤 포레스트 아웃도어 해충방지 스프레이 150ml | E24: 카페24_베럴즈 | F24: 92234346783 | G24: 2026-04-23 오후 2:36:49 | H24: 2026-04-23 오후 2:36:49 | I24: 수량=공구 2개세트 (32%할인) | J24: 1 | K24: ="엄*리" -> 엄*리 | L24: ="엄*리" -> 엄*리 | M24: 8809879544101 | N24: 도톤 포레스트 아웃도어 스프레이 150ml | O24: 2 | P24: 판매청구 | Q24: 정상판매 (공구) | R24: ="20260423-0000201" -> 20260423-0000201
A25: 도톤 | B25: 46135 | C25: P000BMBG | D25: [영이공구특가 이벤트 상품] 도톤 포레스트 아웃도어 해충방지 스프레이 150ml | E25: 카페24_베럴즈 | F25: 92234346772 | G25: 2026-04-23 오후 2:36:46 | H25: 2026-04-23 오후 2:36:46 | I25: 수량=공구 2개세트 (32%할인) | J25: 1 | K25: ="김*연" -> 김*연 | L25: ="김*연" -> 김*연 | M25: 8809879544101 | N25: 도톤 포레스트 아웃도어 스프레이 150ml | O25: 2 | P25: 판매청구 | Q25: 정상판매 (공구) | R25: ="20260423-0000164" -> 20260423-0000164
A26: 도톤 | B26: 46135 | C26: P000BMBG | D26: [영이공구특가 이벤트 상품] 도톤 포레스트 아웃도어 해충방지 스프레이 150ml | E26: 카페24_베럴즈 | F26: 92234329515 | G26: 2026-04-23 오후 2:38:06 | H26: 2026-04-23 오후 2:38:06 | I26: 수량=공구 2개세트 (32%할인) | J26: 1 | K26: ="윤*영" -> 윤*영 | L26: ="윤*영" -> 윤*영 | M26: 8809879544101 | N26: 도톤 포레스트 아웃도어 스프레이 150ml | O26: 2 | P26: 판매청구 | Q26: 정상판매 (공구) | R26: ="20260422-0000144" -> 20260422-0000144
A27: 도톤 | B27: 46135 | C27: P000BMBG | D27: [영이공구특가 이벤트 상품] 도톤 포레스트 아웃도어 해충방지 스프레이 150ml | E27: 카페24_베럴즈 | F27: 92234346805 | G27: 2026-04-23 오후 2:36:26 | H27: 2026-04-23 오후 2:36:26 | I27: 수량=공구특가 1개 (25%할인) | J27: 1 | K27: ="박*혜" -> 박*혜 | L27: ="박*혜" -> 박*혜 | M27: 8809879544101 | N27: 도톤 포레스트 아웃도어 스프레이 150ml | O27: 1 | P27: 판매청구 | Q27: 정상판매 (공구) | R27: ="20260423-0000102" -> 20260423-0000102
A28: 도톤 | B28: 46135 | C28: P000BMBG | D28: [영이공구특가 이벤트 상품] 도톤 포레스트 아웃도어 해충방지 스프레이 150ml | E28: 카페24_베럴즈 | F28: 92234329541 | G28: 2026-04-23 오후 2:36:18 | H28: 2026-04-23 오후 2:36:18 | I28: 수량=공구특가 1개 (25%할인) | J28: 1 | K28: ="윤*정" -> 윤*정 | L28: ="윤*정" -> 윤*정 | M28: 8809879544101 | N28: 도톤 포레스트 아웃도어 스프레이 150ml | O28: 1 | P28: 판매청구 | Q28: 정상판매 (공구) | R28: ="20260423-0000014" -> 20260423-0000014
A29: 도톤 | B29: 46134 | C29: P000BMBG | D29: [영이공구특가 이벤트 상품] 도톤 포레스트 아웃도어 해충방지 스프레이 150ml | E29: 카페24_베럴즈 | F29: 92234309016 | G29: 2026-04-22 오후 2:42:52 | H29: 2026-04-22 오후 2:42:52 | I29: 수량=공구 2개세트 (32%할인) | J29: 1 | K29: ="함*민" -> 함*민 | L29: ="함*민" -> 함*민 | M29: 8809879544101 | N29: 도톤 포레스트 아웃도어 스프레이 150ml | O29: 2 | P29: 판매청구 | Q29: 정상판매 (공구) | R29: ="20260422-0000082" -> 20260422-0000082
A30: 도톤 | B30: 46134 | C30: P000BMBG | D30: [영이공구특가 이벤트 상품] 도톤 포레스트 아웃도어 해충방지 스프레이 150ml | E30: 카페24_베럴즈 | F30: 92234299404 | G30: 2026-04-22 오전 11:56:16 | H30: 2026-04-22 오전 11:56:16 | I30: 수량=공구 2개세트 (32%할인) | J30: 1 | K30: ="황*순" -> 황*순 | L30: ="황*순" -> 황*순 | M30: 8809879544101 | N30: 도톤 포레스트 아웃도어 스프레이 150ml | O30: 2 | P30: 판매청구 | Q30: 정상판매 (공구) | R30: ="20260421-0000231" -> 20260421-0000231
A31: 도톤 | B31: 46134 | C31: P000BMBG | D31: [영이공구특가 이벤트 상품] 도톤 포레스트 아웃도어 해충방지 스프레이 150ml | E31: 카페24_베럴즈 | F31: 92234299393 | G31: 2026-04-22 오전 11:56:20 | H31: 2026-04-22 오전 11:56:20 | I31: 수량=공구 3개세트 (36%할인) | J31: 1 | K31: ="홍*영" -> 홍*영 | L31: ="홍*영" -> 홍*영 | M31: 8809879544101 | N31: 도톤 포레스트 아웃도어 스프레이 150ml | O31: 3 | P31: 판매청구 | Q31: 정상판매 (공구) | R31: ="20260422-0000024" -> 20260422-0000024
A32: 도톤 | B32: 46134 | C32: P000BMBG | D32: [영이공구특가 이벤트 상품] 도톤 포레스트 아웃도어 해충방지 스프레이 150ml | E32: 카페24_베럴즈 | F32: 92234309042 | G32: 2026-04-22 오후 2:42:48 | H32: 2026-04-22 오후 2:42:48 | I32: 수량=공구특가 1개 (25%할인) | J32: 1 | K32: ="이*슬" -> 이*슬 | L32: ="이*슬" -> 이*슬 | M32: 8809879544101 | N32: 도톤 포레스트 아웃도어 스프레이 150ml | O32: 1 | P32: 판매청구 | Q32: 정상판매 (공구) | R32: ="20260422-0000092" -> 20260422-0000092
A33: 도톤 | B33: 46134 | C33: P000BMBG | D33: [영이공구특가 이벤트 상품] 도톤 포레스트 아웃도어 해충방지 스프레이 150ml | E33: 카페24_베럴즈 | F33: 92234299474 | G33: 2026-04-22 오전 11:56:13 | H33: 2026-04-22 오전 11:56:13 | I33: 수량=공구특가 1개 (25%할인) | J33: 1 | K33: ="임*주" -> 임*주 | L33: ="임*주" -> 임*주 | M33: 8809879544101 | N33: 도톤 포레스트 아웃도어 스프레이 150ml | O33: 1 | P33: 판매청구 | Q33: 정상판매 (공구) | R33: ="20260421-0000244" -> 20260421-0000244
A34: 도톤 | B34: 46134 | C34: P000BMBG | D34: [영이공구특가 이벤트 상품] 도톤 포레스트 아웃도어 해충방지 스프레이 150ml | E34: 카페24_베럴즈 | F34: 92234299441 | G34: 2026-04-22 오전 11:56:09 | H34: 2026-04-22 오전 11:56:09 | I34: 수량=공구특가 1개 (25%할인) | J34: 1 | K34: ="조*은" -> 조*은 | L34: ="조*은" -> 조*은 | M34: 8809879544101 | N34: 도톤 포레스트 아웃도어 스프레이 150ml | O34: 1 | P34: 판매청구 | Q34: 정상판매 (공구) | R34: ="20260422-0000037" -> 20260422-0000037
A35: 도톤 | B35: 46134 | C35: P000BMBG | D35: [영이공구특가 이벤트 상품] 도톤 포레스트 아웃도어 해충방지 스프레이 150ml | E35: 카페24_베럴즈 | F35: 92234299426 | G35: 2026-04-22 오전 11:56:06 | H35: 2026-04-22 오전 11:56:06 | I35: 수량=공구특가 1개 (25%할인) | J35: 1 | K35: ="윤*비" -> 윤*비 | L35: ="윤*비" -> 윤*비 | M35: 8809879544101 | N35: 도톤 포레스트 아웃도어 스프레이 150ml | O35: 1 | P35: 판매청구 | Q35: 정상판매 (공구) | R35: ="20260422-0000068" -> 20260422-0000068
A36: 도톤 | B36: 46133 | C36: P000BMBG | D36: [영이공구특가 이벤트 상품] 도톤 포레스트 아웃도어 해충방지 스프레이 150ml | E36: 카페24_베럴즈 | F36: 92234266095 | G36: 2026-04-21 오후 2:51:26 | H36: 2026-04-21 오후 2:51:26 | I36: 수량=공구 3개세트 (36%할인) | J36: 1 | K36: ="박*하" -> 박*하 | L36: ="박*하" -> 박*하 | M36: 8809879544101 | N36: 도톤 포레스트 아웃도어 스프레이 150ml | O36: 3 | P36: 판매청구 | Q36: 정상판매 (공구) | R36: ="20260421-0000082" -> 20260421-0000082
A37: 도톤 | B37: 46133 | C37: P000BMBG | D37: [영이공구특가 이벤트 상품] 도톤 포레스트 아웃도어 해충방지 스프레이 150ml | E37: 카페24_베럴즈 | F37: 92234266084 | G37: 2026-04-21 오후 2:51:22 | H37: 2026-04-21 오후 2:51:22 | I37: 수량=공구 2개세트 (32%할인) | J37: 1 | K37: ="장*아" -> 장*아 | L37: ="장*아" -> 장*아 | M37: 8809879544101 | N37: 도톤 포레스트 아웃도어 스프레이 150ml | O37: 2 | P37: 판매청구 | Q37: 정상판매 (공구) | R37: ="20260421-0000101" -> 20260421-0000101
A38: 도톤 | B38: 46133 | C38: P000BMBG | D38: [영이공구특가 이벤트 상품] 도톤 포레스트 아웃도어 해충방지 스프레이 150ml | E38: 카페24_베럴즈 | F38: 92234266073 | G38: 2026-04-21 오후 2:51:29 | H38: 2026-04-21 오후 2:51:29 | I38: 수량=공구 3개세트 (36%할인) | J38: 1 | K38: ="박*하" -> 박*하 | L38: ="박*하" -> 박*하 | M38: 8809879544101 | N38: 도톤 포레스트 아웃도어 스프레이 150ml | O38: 3 | P38: 판매청구 | Q38: 정상판매 (공구) | R38: ="20260421-0000121" -> 20260421-0000121
A39: 도톤 | B39: 46133 | C39: P000BMBG | D39: [영이공구특가 이벤트 상품] 도톤 포레스트 아웃도어 해충방지 스프레이 150ml | E39: 카페24_베럴즈 | F39: 92234266062 | G39: 2026-04-21 오후 2:51:18 | H39: 2026-04-21 오후 2:51:18 | I39: 수량=공구 2개세트 (32%할인) | J39: 1 | K39: ="이*윤" -> 이*윤 | L39: ="이*윤" -> 이*윤 | M39: 8809879544101 | N39: 도톤 포레스트 아웃도어 스프레이 150ml | O39: 2 | P39: 판매청구 | Q39: 정상판매 (공구) | R39: ="20260421-0000164" -> 20260421-0000164
A40: 도톤 | B40: 46133 | C40: P000BMBG | D40: [영이공구특가 이벤트 상품] 도톤 포레스트 아웃도어 해충방지 스프레이 150ml | E40: 카페24_베럴즈 | F40: 92234241293 | G40: 2026-04-21 오후 2:09:33 | H40: 2026-04-21 오후 2:09:33 | I40: 수량=공구 2개세트 (32%할인) | J40: 1 | K40: ="임*묵" -> 임*묵 | L40: ="최*순" -> 최*순 | M40: 8809879544101 | N40: 도톤 포레스트 아웃도어 스프레이 150ml | O40: 2 | P40: 판매청구 | Q40: 정상판매 (공구) | R40: ="20260421-0000069" -> 20260421-0000069
...

Sheet DB)카페24
A2: 집계기간: 26.4.1-4.30 | C2: 품목 | D2: 수량 | E2: 혜택적용 (프로모션 및 공구할인) | F2: 판매가격 | G2: 판매가합 | H2: 정가기준
A3: 기준: 배송완료 | C3: 풋클리너 판매수량 | D3: 8 | E3: 기본(봄산책할인전 -20%) | F3: =22000*80% -> 17600 | G3: =D3*F3 -> 140800 | H3: =22000*D3 -> 176000
C4: 스프레이 판매수량 | D4: 8 | E4: 기본(봄산책할인전 -20%) | F4: =22000*80% -> 17600 | G4: =D4*F4 -> 140800 | H4: =22000*D4 -> 176000
C5: 스프레이 공구판매 (1ea) | D5: 81 | E5: 1개단위 x 81 (-25%) | F5: =22000*(100-25)% -> 16500 | G5: =D5*F5 -> 1336500 | H5: =22000*D5 -> 1782000
C6: 스프레이 공구판매 (2ea) | D6: =54*2 -> 108 | E6: 2개단위 x 54 (-32%) | F6: =22000*(100-32)% -> 14960 | G6: =D6*F6 -> 1615680 | H6: =22000*D6 -> 2376000
C7: 스프레이 공구판매 (3ea) | D7: 66 | E7: 3개단위 x 22 (-36%) | F7: =22000*(100-36)% -> 14080 | G7: =D7*F7 -> 929280 | H7: =22000*D7 -> 1452000
C8: 합계 | D8: =SUBTOTAL(9,D3:D7) -> 271 | G8: =SUBTOTAL(9,G3:G7) -> 4163060 | H8: =SUBTOTAL(9,H3:H7) -> 5962000
A12: 주문일시 | B12: 주문번호 | C12: 수령인 | D12: 수량 | E12: 상품명(우프(기본)) | F12: 상품옵션(기본) | G12: 배송시작일 | H12: 배송완료일 | I12: 주문 상태 | J12: 비고
A13: 46117.961 | B13: 20260405-0000653 | C13: 이지은 | D13: 1 | E13: 도톤 포레스트 아웃도어 스프레이 150ml 강아지 해충방지 진드기 | F13: 봄산책기획전 (-20%) | G13: 46118.633 | H13: 46119.708 | I13: 배송 완료 | J13: 정상판매
A14: 46119.543 | B14: 20260407-0000171 | C14: 김혜란 | D14: 1 | E14: 도톤 포레스트 워터리스 풋클리너 강아지 발세정제 100ml | F14: 봄산책기획전 (-20%) | G14: 46120.536 | H14: 46121.6 | I14: 배송 완료 | J14: 정상판매
A15: 46120.808 | B15: 20260408-0000379 | C15: 유지현 | D15: 2 | E15: 도톤 포레스트 워터리스 풋클리너 강아지 발세정제 100ml | F15: 봄산책기획전 (-20%) | G15: 46121.554 | H15: 46122.641 | I15: 배송 완료 | J15: 정상판매
A16: 46120.808 | B16: 20260408-0000379 | C16: 유지현 | D16: 2 | E16: 도톤 포레스트 워터리스 풋클리너 강아지 발세정제 100ml | F16: 봄산책기획전 (-20%) | G16: 46121.554 | H16: 46122.641 | I16: 배송 완료 | J16: 정상판매
A17: 46124.596 | B17: 20260412-0000139 | C17: 정하원 | D17: 2 | E17: 도톤 포레스트 아웃도어 스프레이 150ml 강아지 해충방지 진드기 | F17: 봄산책기획전 (-20%) | G17: 46125.585 | H17: 46126.448 | I17: 배송 완료 | J17: 정상판매
A18: 46125.339 | B18: 20260413-0000052 | C18: 배문정 | E18: [영이공구특가 이벤트 상품] 도톤 포레스트 아웃도어 해충방지 스프레이 150ml | F18: 수량=공구특가 1개 (25%할인) | I18: 취소 완료
A19: 46125.375 | B19: 20260413-0000069 | C19: 성민영 | E19: [영이공구특가 이벤트 상품] 도톤 포레스트 아웃도어 해충방지 스프레이 150ml | F19: 수량=공구 3개세트 (35%할인) | I19: 취소 완료
A20: 46125.376 | B20: 20260413-0000075 | C20: 박유진 | D20: 1 | E20: [영이공구특가 이벤트 상품] 도톤 포레스트 아웃도어 해충방지 스프레이 150ml | F20: 수량=공구 3개세트 (36%할인) | G20: 46125.585 | H20: 46126.954 | I20: 배송 완료 | J20: 정상판매
A21: 46125.504 | B21: 20260413-0000156 | C21: 김진아 | E21: [영이공구특가 이벤트 상품] 도톤 포레스트 아웃도어 해충방지 스프레이 150ml | F21: 수량=공구특가 1개 (25%할인) | I21: 취소 완료
A22: 46125.527 | B22: 20260413-0000161 | C22: 이아람 | D22: 1 | E22: [영이공구특가 이벤트 상품] 도톤 포레스트 아웃도어 해충방지 스프레이 150ml | F22: 수량=공구특가 1개 (25%할인) | G22: 46125.678 | H22: 46127.302 | I22: 배송 완료 | J22: 정상판매
A23: 46125.528 | B23: 20260413-0000170 | C23: 이정은 | D23: 1 | E23: [영이공구특가 이벤트 상품] 도톤 포레스트 아웃도어 해충방지 스프레이 150ml | F23: 수량=공구 2개세트 (32%할인) | G23: 46125.678 | H23: 46126.791 | I23: 배송 완료 | J23: 정상판매
A24: 46125.532 | B24: 20260413-0000182 | C24: 성민영 | D24: 1 | E24: [영이공구특가 이벤트 상품] 도톤 포레스트 아웃도어 해충방지 스프레이 150ml | F24: 수량=공구 3개세트 (36%할인) | G24: 46125.586 | H24: 46126.722 | I24: 배송 완료 | J24: 정상판매
A25: 46125.541 | B25: 20260413-0000191 | C25: 김진아 | D25: 1 | E25: [영이공구특가 이벤트 상품] 도톤 포레스트 아웃도어 해충방지 스프레이 150ml | F25: 수량=공구특가 1개 (25%할인) | G25: 46125.678 | H25: 46133.124 | I25: 배송 완료 | J25: 정상판매
A26: 46125.545 | B26: 20260413-0000205 | C26: 현다예 | D26: 1 | E26: [영이공구특가 이벤트 상품] 도톤 포레스트 아웃도어 해충방지 스프레이 150ml | F26: 수량=공구특가 1개 (25%할인) | G26: 46125.679 | H26: 46130.56 | I26: 배송 완료 | J26: 정상판매
A27: 46125.545 | B27: 20260413-0000215 | C27: 김현정 | D27: 1 | E27: [영이공구특가 이벤트 상품] 도톤 포레스트 아웃도어 해충방지 스프레이 150ml | F27: 수량=공구 3개세트 (36%할인) | G27: 46125.679 | H27: 46129.707 | I27: 배송 완료 | J27: 정상판매
A28: 46125.565 | B28: 20260413-0000295 | C28: 임하영 | D28: 1 | E28: [영이공구특가 이벤트 상품] 도톤 포레스트 아웃도어 해충방지 스프레이 150ml | F28: 수량=공구 2개세트 (32%할인) | G28: 46125.679 | H28: 46129.647 | I28: 배송 완료 | J28: 정상판매
A29: 46125.566 | B29: 20260413-0000308 | C29: 정미희 | D29: 1 | E29: [영이공구특가 이벤트 상품] 도톤 포레스트 아웃도어 해충방지 스프레이 150ml | F29: 수량=공구특가 1개 (25%할인) | G29: 46125.679 | H29: 46127.982 | I29: 배송 완료 | J29: 정상판매
A30: 46125.57 | B30: 20260413-0000310 | C30: 임푸 | D30: 1 | E30: [영이공구특가 이벤트 상품] 도톤 포레스트 아웃도어 해충방지 스프레이 150ml | F30: 수량=공구 2개세트 (32%할인) | G30: 46125.679 | H30: 46126.503 | I30: 배송 완료 | J30: 정상판매
A31: 46125.592 | B31: 20260413-0000351 | C31: 배문정 | D31: 1 | E31: [영이공구특가 이벤트 상품] 도톤 포레스트 아웃도어 해충방지 스프레이 150ml | F31: 수량=공구특가 1개 (25%할인) | G31: 46125.594 | H31: 46127.64 | I31: 배송 완료 | J31: 정상판매
A32: 46125.605 | B32: 20260413-0000363 | C32: 장희진 | D32: 1 | E32: [영이공구특가 이벤트 상품] 도톤 포레스트 아웃도어 해충방지 스프레이 150ml | F32: 수량=공구 3개세트 (36%할인) | G32: 46126.664 | H32: 46127.85 | I32: 배송 완료 | J32: 정상판매
A33: 46125.605 | B33: 20260413-0000377 | C33: 성현정 | D33: 1 | E33: [영이공구특가 이벤트 상품] 도톤 포레스트 아웃도어 해충방지 스프레이 150ml | F33: 수량=공구특가 1개 (25%할인) | G33: 46126.664 | H33: 46128.666 | I33: 배송 완료 | J33: 정상판매
... A55: 46125.807 | B55: 20260413-0000654 | C55: 박은선 | D55: 1 | E55: [영이공구특가 이벤트 상품] 도톤 포레스트 아웃도어 해충방지 스프레이 150ml | F55: 수량=공구특가 1개 (25%할인) | G55: 46126.664 | H55: 46127.739 | I55: 배송 완료 | J55: 정상판매
A56: 46125.814 | B56: 20260413-0000660 | C56: 이상은 | D56: 1 | E56: 도톤 포레스트 아웃도어 스프레이 150ml 강아지 해충방지 진드기 | G56: 46126.664 | H56: 46127.459 | I56: 배송 완료 | J56: 정상판매
A57: 46125.821 | B57: 20260413-0000674 | C57: 김성원 | D57: 1 | E57: [영이공구특가 이벤트 상품] 도톤 포레스트 아웃도어 해충방지 스프레이 150ml | F57: 수량=공구특가 1개 (25%할인) | G57: 46126.664 | H57: 46129.414 | I57: 배송 완료 | J57: 정상판매
A58: 46125.83 | B58: 20260413-0000691 | C58: 이샛별 | D58: 1 | E58: [영이공구특가 이벤트 상품] 도톤 포레스트 아웃도어 해충방지 스프레이 150ml | F58: 수량=공구특가 1개 (25%할인) | G58: 46126.664 | H58: 46133.36 | I58: 배송 완료 | J58: 정상판매
A59: 46125.832 | B59: 20260413-0000717 | C59: 강설아 | D59: 1 | E59: [영이공구특가 이벤트 상품] 도톤 포레스트 아웃도어 해충방지 스프레이 150ml | F59: 수량=공구특가 1개 (25%할인) | G59: 46126.664 | H59: 46130.459 | I59: 배송 완료 | J59: 정상판매
A60: 46125.845 | B60: 20260413-0000772 | C60: 장민애 | D60: 1 | E60: [영이공구특가 이벤트 상품] 도톤 포레스트 아웃도어 해충방지 스프레이 150ml | F60: 수량=공구특가 1개 (25%할인) | G60: 46126.664 | H60: 46130.506 | I60: 배송 완료 | J60: 정상판매
A61: 46125.88 | B61: 20260413-0000807 | C61: 최다은 | D61: 1 | E61: [영이공구특가 이벤트 상품] 도톤 포레스트 아웃도어 해충방지 스프레이 150ml | F61: 수량=공구특가 1개 (25%할인) | G61: 46126.664 | H61: 46131.638 | I61: 배송 완료 | J61: 정상판매
A62: 46125.898 | B62: 20260413-0000822 | C62: 서예리 | D62: 1 | E62: [영이공구특가 이벤트 상품] 도톤 포레스트 아웃도어 해충방지 스프레이 150ml | F62: 수량=공구 3개세트 (36%할인) | G62: 46126.664 | H62: 46127.643 | I62: 배송 완료 | J62: 정상판매
A63: 46125.899 | B63: 20260413-0000837 | C63: 임애희 | D63: 1 | E63: [영이공구특가 이벤트 상품] 도톤 포레스트 아웃도어 해충방지 스프레이 150ml | F63: 수량=공구특가 1개 (25%할인) | G63: 46126.664 | H63: 46129.75 | I63: 배송 완료 | J63: 정상판매
A64: 46125.905 | B64: 20260413-0000840 | C64: 정다원 | D64: 1 | E64: [영이공구특가 이벤트 상품] 도톤 포레스트 아웃도어 해충방지 스프레이 150ml | F64: 수량=공구 2개세트 (32%할인) | G64: 46126.664 | H64: 46127.488 | I64: 배송 완료 | J64: 정상판매
A65: 46125.912 | B65: 20260413-0000853 | C65: 주레오 | D65: 1 | E65: [영이공구특가 이벤트 상품] 도톤 포레스트 아웃도어 해충방지 스프레이 150ml | F65: 수량=공구 3개세트 (36%할인) | G65: 46126.664 | H65: 46131.539 | I65: 배송 완료 | J65: 정상판매
...

Sheet DB)스마트스토어
A1: 상품주문번호 | B1: 주문번호 | C1: 구매확정일 | D1: 판매채널 | E1: 주문상태 | F1: 구매자명 | G1: 구매자ID | H1: 수취인명 | I1: 발송처리일 | J1: 배송방법 | K1: 택배사 | L1: 송장번호 | M1: 배송완료일 | N1: 상품번호 | O1: 상품명 | P1: 상품종류 | Q1: 옵션정보 | R1: 수량 | S1: 상품가격 | T1: 옵션가격 | U1: 최종 상품별 할인액 | V1: 판매자 부담 할인액 | W1: 최종 상품별 총 주문금액 | X1: 판매자 상품코드 | Y1: 판매자 내부코드1 | Z1: 판매자 내부코드2 | AA1: 배송비 묶음번호 | AB1: 배송비 형태 | AC1: 배송비 유형 | AD1: 배송비 합계 | AE1: 제주/도서 추가배송비 | AF1: 배송비 할인액 | AG1: 결제일 | AH1: 결제수단 | AI1: 결제위치 | AJ1: 네이버페이 주문관리 수수료 | AK1: 매출연동 수수료 | AL1: 정산예정금액
A2: 2026042516531611 | B2: 2026042577184211 | C2: 46141.266 | D2: 스마트스토어 | E2: 구매확정 | F2: 김민주 | G2: min_****** | H2: 김민주 | I2: 46139.657 | J2: 택배,등기,소포 | K2: 로젠택배 | L2: 92234417634 | M2: 46140.661 | N2: 12423379709 | O2: 도톤 포레스트 아웃도어 스프레이 150ml 강아지 해충방지 진드기 | P2: 단일상품 | R2: 2 | S2: 22000 | T2: 0 | U2: 4400 | V2: 4400 | W2: 39600 | AA2: 2026042520644564 | AB2: 무료 | AC2: 무료 | AD2: 0 | AE2: 0 | AF2: 0 | AG2: 46137.307 | AH2: 신용카드 간편결제 | AI2: MOBILE | AJ2: -1080 | AK2: -396 | AL2: 38124
A3: 2026041567896181 | B3: 2026041581973751 | C3: 46131.369 | D3: 스마트스토어 | E3: 구매확정 | F3: 유정님 | G3: sin0****** | H3: 유정님 | I3: 46127.795 | J3: 택배,등기,소포 | K3: 로젠택배 | L3: 91970180540 | M3: 46128.673 | N3: 12423379709 | O3: 도톤 포레스트 아웃도어 스프레이 150ml 강아지 해충방지 진드기 | P3: 단일상품 | R3: 1 | S3: 22000 | T3: 0 | U3: 100 | V3: 100 | W3: 21900 | AA3: 2026041584299342 | AB3: 무료 | AC3: 무료 | AD3: 0 | AE3: 0 | AF3: 0 | AG3: 46127.406 | AH3: 신용카드 간편결제 | AI3: MOBILE | AJ3: -597 | AK3: -219 | AL3: 21084
O7: 집계: 26.4.1 - 4.30 (구매확정 기준)
O9: 상품 | P9: 합계수량 | Q9: 정상가계 | R9: 혜택 | S9: 판매가계
O10: 도톤 포레스트 아웃도어 스프레이 150ml | P10: 3 | Q10: =22000*P10 -> 66000 | R10: 20%할인(봄산책) | S10: =22000*80%*P10 -> 52800
O11: 도톤 포레스트 워터리스 풋클리너 100ml | P11: 0 | Q11: =22000*P11 -> 0 | S11: =22000*R11 -> 0
O12: total | P12: =SUM(P10:P11) -> 3 | Q12: =SUM(Q10:Q11) -> 66000 | S12: =SUM(S10:S11) -> 52800

Sheet DB) 행사

Sheet DB)사업자몰B2B
A1: 주문일시 | B1: 주문번호 | C1: 수령인 | D1: 수량 | E1: 상품명(우프(기본)) | F1: 상품옵션(기본) | G1: 배송시작일 | H1: 배송완료일 | I1: 주문자 휴대전화 끝자리
C5: 실판매수량 | D5: =SUM(D2:D4) -> 0
C6: 판매정가 | D6: 22000
C7: 소매점공급가 | D7: =D6*60% -> 13200
C8: 합계 | D8: =D5*D7 -> 0

Sheet DB)이마트몰리스
A1: 이마트(몰리스하남) 4월 판매집계
A2: 점포코드 | B2: 업태코드 | C2: 업태명 | D2: 점포명 | E2: 업체코드 | F2: 업체명 | G2: 상품코드 | H2: 상품명 | I2: 납품일자 | J2: 발주일자 | K2: 문서번호 | L2: 납품구분 | M2: 발주량 | N2: 납품량 | O2: 발주금액 | P2: 납품금액 | Q2: 원가 | R2: 매입구분 | S2: 센터코드 | T2: 센터명 | U2: LOT | V2: 매입형태 | W2: 매입구분명 | X2: 원상품코드
A3: 5304 | B3: 1100 | C3: 이마트 | D3: 몰리스STF하남점 | E3: 1610931 | F3: 우프컴퍼니 | G3: 8809879544101 | H3: 도톤 포레스트 아웃도어 스프레이 150ml | I3: 20260408 | J3: 20260408 | K3: 6089858022 | L3: 직납 | M3: 1 | N3: 1 | O3: 14000 | P3: 14000 | Q3: 14000 | R3: 59 | S3: 5304 | T3: 몰리스STF하남점 | U3: 1 | V3: 정상 | W3: 특행/배달
A4: 5304 | B4: 1100 | C4: 이마트 | D4: 몰리스STF하남점 | E4: 1610931 | F4: 우프컴퍼니 | G4: 8809879544101 | H4: 도톤 포레스트 아웃도어 스프레이 150ml | I4: 20260406 | J4: 20260406 | K4: 6089771110 | L4: 직납 | M4: 1 | N4: 1 | O4: 14000 | P4: 14000 | Q4: 14000 | R4: 59 | S4: 5304 | T4: 몰리스STF하남점 | U4: 1 | V4: 정상 | W4: 특행/배달
A5: 5304 | B5: 1100 | C5: 이마트 | D5: 몰리스STF하남점 | E5: 1610931 | F5: 우프컴퍼니 | G5: 8809879544118 | H5: 도톤 포레스트 워터리스 풋클리너 100ml | I5: 20260406 | J5: 20260406 | K5: 6089779677 | L5: 직납 | M5: 1 | N5: 1 | O5: 14000 | P5: 14000 | Q5: 14000 | R5: 59 | S5: 5304 | T5: 몰리스STF하남점 | U5: 1 | V5: 정상 | W5: 특행/배달
L10: 품목 | M10: 수량합계 | N10: 정가 | O10: 공급가(부가세포함) | P10: 공급가합
L11: 도톤 포레스트 아웃도어 스프레이 150ml | M11: 2 | N11: 22000 | O11: =14000+1400 -> 15400 | P11: =M11*O11 -> 30800
L12: 도톤 포레스트 워터리스 풋클리너 100ml | M12: 1 | N12: 22000 | O12: =14000+1400 -> 15400 | P12: =M12*O12 -> 15400
L13: 합계 | M13: =SUM(M11:M12) -> 3 | P13: =SUM(P11:P12) -> 46200

Sheet DB) 컬리
A1: 컬리 4월
A2: 집계: 구매확정 기준
A3: 개별주문번호 | B3: 대표주문번호 | C3: 주문상태 | D3: 주문일시 | E3: 상품번호 | F3: 상품명 | G3: 옵션명 | H3: 옵션번호 | I3: 딜코드 | J3: 판매자코드 | K3: 권장소비자가 | L3: 판매가 | M3: 수량 | N3: 주문금액 | O3: 택배사 | P3: 운송장번호 | Q3: 주문자명 | R3: 수취인명 | S3: 배송유형 | T3: 발주확인일 | U3: 발송처리일 | V3: 배송완료일 | W3: 예약확정일 | X3: 예약일 | Y3: 설치사용완료일 | Z3: 구매확정일 | AA3: 픽업시작일 | AB3: 픽업종료일 | AC3: 픽업매장 | AD3: 미픽업반송대상 | AE3: 개인통관고유번호 | AF3: 상품ID | AG3: 주문ID
