Workbook

Sheet 종합정산
B2: [판매내역 종합] | J2: vat포함
B3: 정산 월 | C3: 실판매수량 | D3: 판매정가계 | E3: 프로모션공제 | F3: 총계 | G3: 공제 수수료 (공급마진) | H3: 매출계 | I3: 실비 | J3: 이익
B4: 45992 | C4: ='채널별 판매데이터 정리'!K62 -> 5 | D4: ='채널별 판매데이터 정리'!K63 -> 110000 | E4: =D4-F4 -> 5500 | F4: ='채널별 판매데이터 정리'!K64 -> 104500 | G4: ='채널별 판매데이터 정리'!K65 -> 35200 | H4: =F4-G4 -> 69300 | I4: =F24 -> 4080 | J4: =H4-I4 -> 65220
L5: [재고현황] | M5: 자사물류센터 입출고 기준
B6: [정산 방식/ VAT포함] | N6: 12월 1일 | Q6: =N6&" ~ "&W6 -> 12월 1일 ~ 12월 31일 | W6: 12월 31일
B7: 항목 | F7: 비고 | N7: 기초재고 | Q7: 입고 | T7: 출고 | W7: 기말재고
B8: A 수수료 (공급마진) | F8: 각 유통 채널별 공급마진 (위탁은 수수료/ 매입은 공급할인액) 기준 | L8: 품목관리코드 | M8: 품목명 | N8: 전체 | O8: 정상 | P8: 불용 | Q8: 전체 | R8: 입고 | S8: 반품 | T8: 전체 | U8: 판매 | V8: 비매출 | W8: 전체 | X8: 정상 | Y8: 불용
B9: B 매출계 (월별 최종 판매 금액) | F9: 월별 제품 최종판매금액 (정가 - 프로모션 등 할인이 반영된 최종 결제 금액) | L9: 8809879544118 | M9: 도톤 포레스트 워터리스 풋클리너 100ml | N9: =O9+P9 -> 299 | O9: 299 | P9: 0 | R9: 0 | T9: =U9+V9 -> 1 | U9: 1 | V9: 0 | W9: =N9+Q9-T9 -> 298 | X9: 298
B10: C 실비 | F10: 운송료 실비, PG결제 수수료 등 | L10: 8809879544101 | M10: 도톤 포레스트 아웃도어 스프레이 150ml | N10: =O10+P10 -> 489 | O10: 489 | P10: 0 | T10: =U10+V10 -> 0 | U10: 0 | V10: 0 | W10: =X10-Y10 -> 489 | X10: 489
B11: D 이익 | F11: 판매 매출 발생 시, “월별 제품 최종 판매 금액”을 기준으로, 인플루언서 공구 수수료를 포함한 각각의 입점 채널별 공급 수수료, 운송료 실비, PG사 결제 수수료를 제외한 금액
M12: 합계 | N12: =SUM(N9:N11) -> 788 | O12: =SUM(O9:O11) -> 788 | P12: =SUM(P9:P11) -> 0 | Q12: =SUM(Q9:Q11) -> 0 | R12: =SUM(R9:R11) -> 0 | S12: =SUM(S9:S11) -> 0 | T12: =SUM(T9:T11) -> 1 | U12: =SUM(U9:U11) -> 1 | ... Y12: =SUM(Y9:Y11) -> 0
B14: 매출계산서발행 | F14: vat포함
B15: 항목 | C15: 구분 | D15: 비율 | E15: 금액 | F15: 비고
B16: 이익분배 | C16: 유씨엘주식회사 | D16: 0.4 | E16: =J4*40% -> 26088
C17: 우프컴퍼니(주) | D17: 0.3 | E17: =J4*30% -> 19566
C18: (주)메리고라운드 | D18: 0.3 | E18: =J4*D18 -> 19566
B19: 합계 | D19: =SUM(D16:D18) -> 1 | E19: =SUM(E16:E18) -> 65220
B21: [실비 : 운임/물류] | F21: vat포함
B22: 정산 월 | C22: 물류 실비 산정
C23: 수량(출고건수) | D23: 택배 | E23: 피킹/패킹/부자재 | F23: 총계
B24: 45992 | C24: 1 | D24: 2650 | E24: 1430 | F24: =C24*(D24+E24) -> 4080
B25: *입고비용 및 보관비용은 청구제외 하였으며, 운송실비(당사가 3PL 지불하는 택배운임비 +물류비) 청구기준만 기재합니다. *소형물류기준
B26: *퀵/용달 등 별도 운송비 발생시에는 개별기재합니다.
F27: vat별도
B28: 항목 | C28: 항목 | D28: 견적(원) | E28: 단위 | F28: 비고
B29: 3PL 단가표 | C29: 보관료 | E29: 월/평당 | F29: 청구제외
C30: 입고비용 | D30: 0 | E30: 건 | F30: 청구제외
C31: 택배운임비 | D31: 2500 | E31: 건 | F31: 로젠택배(소형)
C32: 물류비 | D32: 1300 | E32: 건 | F32: 부자재 /피킹/패킹
B35: [메모/특이사항]
B36: 재고이동(오프라인 위탁진열/ 판매시 정산)
B37: 비매출: 협찬, 진열품, 샘플 등의 무상사용
B38: 세금계산서는 정산 월 기준 익익월 10일에 발행 예정입니다.
B39: 정산금액은 정산 월 기준 익월 15일에 입금 예정이며 정산금액 활용안 협의에 따라 변경될 수 있습니다.
B40: 불용이슈: 패키지 손상/파손

Sheet 채널별 판매데이터 정리
B1: 판매기간 2025 12/1 - 12/31
B4: 몽슈슈 | D4: 주요채널: 오프라인 백화점 팝업스토어 | K4: 위탁재고
B5: 순번 | C5: 제품 | D5: 정가 | E5: 공급가 | F5: 수수료율 | G5: 판매수량 | H5: 할인 | I5: 매출합계 | J5: 수수료합계 | K5: 정산합계 | L5: 정가합계
B6: 1 | C6: DOTEON Foot Cleaner | D6: 22000 | E6: 13200 | F6: 0.4 | G6: ='DB)몽슈슈'!I3 -> 1 | H6: 없음 | I6: =D6*G6 -> 22000 | J6: =D6*F6*G6 -> 8800 | K6: =I6-J6 -> 13200 | L6: =D6*G6 -> 22000
B7: 2 | C7: DOTEON Outdoor Spray | D7: 22000 | E7: 13200 | F7: 0.4 | G7: ='DB)몽슈슈'!I4 -> 3 | H7: 없음 | I7: =D7*G7 -> 66000 | J7: =D7*F7*G7 -> 26400 | K7: =I7-J7 -> 39600 | L7: =D7*G7 -> 66000
C8: 합계 | G8: =SUM(G6:G7) -> 4 | I8: =SUM(I6:I7) -> 88000 | J8: =SUM(J6:J7) -> 35200 | K8: =SUM(K6:K7) -> 52800 | L8: =SUM(L6:L7) -> 88000
B11: 공구 진행 | K11: 매입(판매)
B12: 순번 | C12: 품목 구성 | D12: 정가 | E12: 프로모션가 | F12: 할인율 | G12: 판매수량 | H12: 판매가합계 | I12: 수수료 | J12: 수수료합계 | K12: 매출합계 | L12: 정가합계 | M12: 총판매수량(낱)
B13: 1 | C13: 단품1개 | D13: 22000 | E13: 16500 | F13: 0.25 | H13: =E13*G13 -> 0 | I13: 0.2 | J13: =H13*I13 -> 0 | K13: =H13-J13 -> 0 | L13: =D13*G13 -> 0 | M13: =G13 -> 0
B14: 2 | C14: 단품2개 | D14: 44000 | E14: 29900 | F14: 0.32 | H14: =E14*G14 -> 0 | I14: 0.2 | J14: =H14*I14 -> 0 | K14: =H14-J14 -> 0 | L14: =D14*G14 -> 0 | M14: =2*G14 -> 0
B15: 3 | C15: 단품3개 | D15: 66000 | E15: 42200 | F15: 0.36 | H15: =E15*G15 -> 0 | I15: 0.2 | J15: =H15*I15 -> 0 | K15: =H15-J15 -> 0 | L15: =D15*G15 -> 0 | M15: =3*G15 -> 0
B16: 4 | C16: 혼합1+2 | D16: 66000 | E16: 42900 | F16: 0.35 | H16: =E16*G16 -> 0 | I16: 0.2 | J16: =H16*I16 -> 0 | K16: =H16-J16 -> 0 | L16: =D16*G16 -> 0 | M16: =3*G16 -> 0
B17: 5 | C17: 혼합3+3 | D17: 132000 | E17: 79200 | F17: 0.4 | H17: =E17*G17 -> 0 | I17: 0.2 | J17: =H17*I17 -> 0 | K17: =H17-J17 -> 0 | L17: =D17*G17 -> 0 | M17: =6*G17 -> 0
C18: 합계 | G18: =SUM(G13:G17) -> 0 | H18: =SUM(H13:H17) -> 0 | J18: =SUM(J13:J17) -> 0 | K18: =H18-J18 -> 0 | L18: =SUM(L13:L17) -> 0 | M18: =SUM(M13:M17) -> 0
B21: 테일릿 | D21: 주요채널: 대리점(오프라인B2B전용 도매유통업) - 소매점 40% + 대리점마진 20% | K21: 매입(판매)
B22: 순번 | C22: 품목 구성 | D22: 정가 | E22: 소매점가 | F22: 소매점수수료 | G22: 대리점가 | H22: 대리점수수료 | I22: 판매수량 | J22: 수수료합계 | K22: 정산합계 | L22: 정가합계
B23: 1 | C23: DOTEON Foot Cleaner | D23: 22000 | E23: =D23-D23*F23 -> 13200 | F23: 0.4 | G23: =E23-E23*H23 -> 10560 | H23: 0.2 | I23: 0 | J23: =D23*0.52*I23 -> 0 | K23: =G23*I23 -> 0 | L23: =D23*I23 -> 0
B24: 2 | C24: DOTEON Outdoor Spray | D24: 22000 | E24: =D24-D24*F24 -> 13200 | F24: 0.4 | G24: =E24-E24*H24 -> 10560 | H24: 0.2 | I24: 0 | J24: =D24*0.52*I24 -> 0 | K24: =G24*I24 -> 0 | L24: =D24*I24 -> 0
C25: 합계 | I25: =SUM(I23:I24) -> 0 | J25: =SUM(J23:J24) -> 0 | K25: =SUM(K23:K24) -> 0 | L25: =SUM(L20:L24) -> 0
B28: 철수마켓 | K28: 판매자위탁배송
B29: 순번 | C29: 품목 구성 | D29: 정가 | E29: 프로모션가 | F29: 공급가 | G29: 수수료율 | H29: 판매수량 | I29: 매출합계 | J29: 수수료합계 | K29: 정산합계 | L29: 정가합계
B30: 1 | C30: DOTEON Foot Cleaner | D30: 22000 | E30: 22000 | F30: =E30-E30*G30 -> 16500 | G30: 0.25 | I30: =E30*H30 -> 0 | J30: =E30*G30*H30 -> 0 | K30: =I30-J30 -> 0 | L30: =H30*D30 -> 0
C31: 합계 | H31: =SUM(H30:H30) -> 0 | I31: =SUM(I30) -> 0 | J31: =SUM(J30) -> 0 | K31: =SUM(K30) -> 0 | L31: =SUM(L30) -> 0
B34: 몰리스(이마트) | K34: 위탁재고
B35: 순번 | C35: 품목 구성 | D35: 정가 | E35: 프로모션가 | F35: 공급가 | G35: 수수료율 | H35: 판매수량 | I35: 매출합계 | J35: 수수료합계 | K35: 정산합계 | L35: 정가합계
B36: 1 | C36: DOTEON Foot Cleaner | D36: 22000 | E36: 22000 | F36: =E36-E36*G36 -> 15400 | G36: 0.3 | H36: 0 | I36: =E36*H36 -> 0 | J36: =E36*G36*H36 -> 0
B37: 2 | C37: DOTEON Outdoor Spray | D37: 22000 | E37: 22000 | F37: =E37-E37*G37 -> 15400 | G37: 0.3 | H37: 0 | I37: =E37*H37 -> 0 | J37: =E37*G37*H37 -> 0
C38: 합계 | H38: =SUM(H36:H37) -> 0 | K38: =SUM(K36:K37) -> 0
B41: 오버더센스 | D41: 주요채널: 제주도 반려동물 동반시설 | K41: 위탁재고
B42: 순번 | C42: 품목 구성 | D42: 정가 | E42: 공급가 | F42: 수수료율 | G42: 판매수량 | I42: 매출합계 | J42: 수수료합계 | K42: 정산합계 | L42: 정가합계
B43: 1 | C43: DOTEON Foot Cleaner | D43: 22000 | E43: =D43-D43*F43 -> 14740 | F43: 0.33 | G43: 0
B44: 2 | C44: DOTEON Outdoor Spray | D44: 22000 | E44: =D44-D44*F44 -> 14740 | F44: 0.33 | G44: 0
C45: 합계 | G45: =SUM(G43:G44) -> 0 | K45: =SUM(K43:K44) -> 0
B48: 우프자사몰 | D48: 주요채널: 우프앱/자사몰/스마트스토어 | K48: 직매출
B49: 순번 | C49: 품목 구성 | D49: 정가 | E49: 프로모션가 | F49: 할인율 | G49: 판매수량 | H49: 할인합계 | I49: 매출합계 | J49: 수수료합계 | K49: 정산합계 | L49: 정가합계
B50: 1 | C50: DOTEON Foot Cleaner | D50: 22000 | E50: =D50-D50*F50 -> 16500 | F50: 0.25 | G50: 1 | H50: =D50*F50*G50 -> 5500 | I50: =E50*G50 -> 16500 | J50: 0 | K50: =I50-J50 -> 16500 | L50: =D50*G50 -> 22000
B51: 2 | C51: DOTEON Outdoor Spray | D51: 22000 | E51: =D51-D51*F51 -> 16500 | F51: 0.25 | H51: =D51*F51*G51 -> 0 | I51: =E51*G51 -> 0 | J51: 0 | K51: =I51-J51 -> 0 | L51: =D51*G51 -> 0
C52: 합계 | G52: =SUM(G50:G51) -> 1 | H52: =SUM(H50:H51) -> 5500 | I52: =SUM(I50:I51) -> 16500 | J52: 0 | K52: =SUM(K50:K51) -> 16500 | L52: =SUM(L50:L51) -> 22000
B55: 컬리
B56: 순번 | C56: 품목 구성 | D56: 정가 | E56: 할인가 | F56: 할인율 | G56: 수수료율 | H56: 판매수량 | I56: 매출합계 | J56: 수수료합계 | K56: 정산합계 | L56: 정가합계
...

Sheet DB)입출고목록
A1: 출고카운트 | B1: 입출고일자 | C1: 입력일자 | D1: 공급처명 | E1: 바코드번호 | F1: 상품명 | G1: 옵션내용 | H1: 입고수량 | I1: 입고금액 | J1: 출고수량 | K1: 출고금액 | L1: 재고작업구분 | M1: 판매처명 | N1: 판매단가 | O1: 판매금액 | P1: 입출고구분 | Q1: 판매구분 | R1: 내용 | S1: 판매상세 (주문번호) | T1: 판매상세 (위탁판매 수수료율)
A2: 1 | B2: 45995 | C2: 2025-12-04 오후 12:33:25 | D2: 도톤 | E2: 8809879544118 | F2: 도톤 포레스트 워터리스 풋클리너 100ml | G2: 단일상품 | H2: 0 | I2: 0 | J2: 1 | K2: 0 | L2: 발송및출고 | M2: 카페24_베럴즈 | N2: 22000 | O2: 22000 | P2: 출고 | Q2: 판매청구 | R2: 자사몰판매 | S2: 20251203-0000132
A3: 2
A4: 3
A5: 4
A6: 5
A7: 6
A8: 7
A9: 8
A11: 출고건수 | B11: 1

Sheet DB)카페24
A1: 주문일시 | B1: 주문번호 | C1: 수령인 | D1: 수량 | E1: 상품명(우프(기본))
A5: 주문일시 | B5: 주문번호 | C5: 수령인 | D5: 수량 | E5: 상품명(우프(기본)) | F5: 상품옵션(기본) | G5: 판매가 | H5: 상품구매금액 | I5: 상품별 할인금액 | J5: 상품 쿠폰 할인금액 | K5: 할인합계
A6: 45994.9 | B6: 20251203-0000132 | C6: 손선미 | D6: 1 | E6: 도톤 포레스트 워터리스 풋클리너 강아지 발세정제 100ml | G6: 22000 | H6: 22000 | I6: 5500 | K6: =I6*D6 -> 5500 | M6: 25% 블랙프라이데이 할인
D10: =SUM(D6:D9) -> 1 | H10: =SUM(H6:H9) -> 22000 | K10: =SUM(K6:K9) -> 5500 | M10: =H10-K10 -> 16500

Sheet DB) 컬리
A1: 대표 주문 번호 | B1: 주문채널 | C1: 마스터 상품 코드 | D1: 마스터 상품명 | E1: 거래 일자 | F1: 결제 상태 | G1: 구매확정일 | H1: 정산 예정일 | I1: 판매가 | J1: 판매자부담(상품할인) | K1: 판매자부담(쿠폰할인) | L1: 판매자배송(수수료율)% 부가세제외 | M1: 판매수수료(VAT 포함) | N1: 판매수수료(VAT 제외) | O1: 판매수수료(VAT) | P1: 배송비 | Q1: 반품배송비 | R1: 기타반품비용 | S1: 취소수수료 | T1: 클레임번호 | U1: 최종 정산 금액
A2: 2398021500158 | B2: 컬리 | C2: M00000676604 | D2: 내역없음
G5: 합계 | I5: =SUM(I1:I2) -> 0 | K5: =SUM(K1:K2) -> 0 | M5: =SUM(M1:M2) -> 0 | N5: =SUM(N1:N2) -> 0 | O5: =SUM(O1:O2) -> 0 | U5: =SUM(U1:U2) -> 0

Sheet DB)철수마켓
A2: 채널명 | B2: 주문번호 | C2: 상품주문번호 | D2: 구분 | E2: 상품명 | F2: 구매자명 | G2: 결제금액
A3: 철수마켓 | E3: 내역없음

Sheet DB)몽슈슈
B1: 12월 판매내역
A2: 순번 | B2: 제품 | C2: 상품코드 | D2: 소비자가 | E2: 단가 | F2: 재고 | G2: 입고 | H2: 반송 | I2: 판매 | J2: 월말재고 | K2: 판매합계
A3: 1 | B3: DOTEON Foot Cleaner | C3: BT25DTFC | D3: 22000 | E3: 13200 | F3: 20 | G3: 0 | I3: 1 | J3: 19 | K3: =E3*I3 -> 13200
A4: 2 | B4: DOTEON Outdoor Spray | C4: BT25OS | D4: 22000 | E4: 13200 | F4: 18 | G4: 0 | I4: 3 | J4: 15 | K4: =E4*I4 -> 39600
I5: =SUM(I3:I4) -> 4 | K5: =SUM(K3:K4) -> 52800
