Workbook

Sheet 종합정산
B2: [판매내역 종합] | J2: vat포함
B3: 정산 월 | C3: 실판매수량 | D3: 판매정가계 | E3: 할인계 | F3: 실판매계 | G3: 공제 수수료 (공급마진) | H3: 매출계 | I3: 실비 | J3: 이익
B4: 46143 | C4: ='채널별 판매데이터 정리'!K83 -> 117 | D4: ='채널별 판매데이터 정리'!K84 -> 2574000 | E4: =D4-F4 -> 524280 | F4: ='채널별 판매데이터 정리'!K85 -> 2049720 | G4: ='채널별 판매데이터 정리'!K86 -> 576330 | H4: =F4-G4 -> 1473390 | I4: =F26 -> 204000 | J4: =H4-I4 -> 1269390
L5: [재고현황] | M5: 자사물류센터 입출고 기준
B6: [정산 방식/ VAT포함] | N6: 5월 1일 | Q6: =N6&" ~ "&W6 -> 5월 1일 ~ 5월 31일 | W6: 5월 31일
B7: 항목 | F7: 비고 | N7: 기초재고 | Q7: 입고 | T7: 출고 | W7: 기말재고
B8: A 수수료 (공급마진) | F8: 각 유통 채널별 공급마진 (위탁은 수수료/ 매입은 공급할인액) 기준 | L8: 품목관리코드 | M8: 품목명 | N8: 전체 | O8: 정상 | P8: 불용 | Q8: 전체 | R8: 입고 | S8: 반품 | T8: 전체 | U8: 판매 | V8: 비매출 | W8: 전체 | X8: 정상 | Y8: 불용
B9: B 매출계 (월별 최종 판매 금액) | F9: 월별 제품 최종판매금액 (정가 - 프로모션 등 할인이 반영된 최종 결제 금액) | L9: 8809879544118 | M9: 도톤 포레스트 워터리스 풋클리너 100ml | N9: =O9+P9 -> 121 | O9: 121 | P9: 0 | Q9: =R9+S9 -> 0 | R9: 0 | T9: =U9+V9 -> 6 | U9: 5 | V9: 1 | W9: =N9+Q9-T9 -> 115 | X9: =W9-Y9 -> 115
B10: C 실비 | F10: 운송료 실비, PG결제 수수료 등 | L10: 8809879544101 | M10: 도톤 포레스트 아웃도어 스프레이 150ml | N10: =O10+P10 -> 259 | O10: 259 | P10: 0 | Q10: =R10+S10 -> 0 | R10: 0 | S10: 0 | T10: =U10+V10 -> 89 | U10: 87 | V10: 2 | W10: =N10+Q10-T10 -> 170 | X10: =W10-Y10 -> 170
B11: D 이익 | F11: 판매 매출 발생 시, “월별 제품 최종 판매 금액”을 기준으로, 인플루언서 공구 수수료를 포함한 각각의 입점 채널별 공급 수수료, 운송료 실비, PG사 결제 수수료를 제외한 금액
M12: 합계 | N12: =SUM(N9:N11) -> 380 | O12: =SUM(O9:O11) -> 380 | P12: =SUM(P9:P11) -> 0 | Q12: =SUM(Q9:Q11) -> 0 | R12: =SUM(R9:R11) -> 0 | S12: =SUM(S9:S11) -> 0 | T12: =SUM(T9:T11) -> 95 | U12: =SUM(U9:U11) -> 92 | ... Y12: =SUM(Y9:Y11) -> 0
B14: 매출계산서발행 | F14: vat포함
B15: 항목 | C15: 구분 | D15: 비율 | E15: 금액 | F15: 비고
B16: 이익분배 | C16: 유씨엘주식회사 | D16: 0.55 | E16: =J4*D16 -> 698164.5
C17: 우프컴퍼니(주) | D17: 0.45 | E17: =J4*D17 -> 571225.5
C18: 재계약중 | D18: 0 | E18: =J4*D18 -> 0 | F18: 제외
B19: 합계 | D19: =SUM(D16:D18) -> 1 | E19: =SUM(E16:E18) -> 1269390
B21: [실비 : 운임/물류] | F21: vat포함
B22: 2026년 5월 | C22: 물류 실비 산정
C23: 수량(출고건수) | D23: 택배 | E23: 피킹/패킹/부자재 | F23: 총계
B24: 택배(소형) | C24: 50 | D24: 2650 | E24: 1430 | F24: =C24*(D24+E24) -> 204000
B25: 택배(중대형) | D25: 4400 | E25: 1430 | F25: =C25*(D25+E25) -> 0
B26: 합계 | C26: =SUM(C24:C25) -> 50 | F26: =SUM(F24:F25) -> 204000
B27: *입고비용 및 보관비용은 한시적 청구제외 하였으며, 운송실비(당사가 3PL 지불하는 택배운임비 +물류비) 청구기준만 기재되었습니다.
B28: *퀵/용달 등 별도 운송비 발생시에는 개별기재합니다.
F29: vat별도
B30: 항목 | C30: 항목 | D30: 견적(원) | E30: 단위 | F30: 비고
B31: 3PL 단가표 | C31: 보관료 | E31: 월/평당 | F31: 청구제외
C32: 입고비용 | D32: 0 | E32: 건 | F32: 청구제외
C33: 택배운임비 | D33: 2500 | E33: 건 | F33: 로젠택배(소형)
C34: 택배운임비 | D34: 4000 | E34: 건 | F34: 로젠택배(중대형)
C35: 물류비 | D35: 1300 | E35: 건 | F35: 부자재 /피킹/패킹
B38: [메모/특이사항]
B39: 재고이동(오프라인 위탁진열/ 판매시 정산)
B40: 비매출: 협찬, 진열품, 샘플 등의 무상사용
B41: 세금계산서는 정산 월 기준 익익월 10일에 발행 예정입니다.
B42: 정산금액은 정산 월 기준 익월 15일에 입금 예정이며 정산금액 활용안 협의에 따라 변경될 수 있습니다.
B43: 불용이슈: 패키지 손상/파손

Sheet 채널별 판매데이터 정리
B1: 판매기간 2026 5/1 - 5/31
B4: 몽슈슈 | D4: 주요채널: 오프라인 백화점 팝업스토어 | K4: 위탁재고
B5: 순번 | C5: 제품 | D5: 정가 | E5: 공급가 | F5: 기본수수료 | G5: 판매수량 | H5: 프로모션차감 | I5: 매출합계 | J5: 수수료합계 | K5: 정산합계 | L5: 정가합계
B6: 1 | C6: DOTEON Foot Cleaner | D6: 22000 | E6: 13200 | F6: 0.4 | G6: ='DB)몽슈슈'!E11 -> 0 | I6: =E6*G6 -> 0 | K6: ='DB)몽슈슈'!H11 -> 0 | L6: =D6*G6 -> 0
B7: 2 | C7: DOTEON Outdoor Spray | D7: 22000 | E7: 13200 | F7: 0.4 | G7: 2 | I7: =D7*G7 -> 44000 | J7: =I7*F7 -> 17600 | K7: ='DB)몽슈슈'!H12 -> 26400 | L7: =D7*G7 -> 44000
C8: 합계 | G8: =SUM(G6:G7) -> 2 | H8: =SUM(H6:H7) -> 0 | I8: =SUM(I6:I7) -> 44000 | J8: =SUM(J7) -> 17600 | K8: =SUM(K6:K7) -> 26400 | L8: =SUM(L6:L7) -> 44000
B11: 스마트스토어
B12: 순번 | C12: 품목 구성 | D12: 정가 | E12: 프로모션가 | F12: 할인율 | G12: 판매수량 | H12: 매출합계 | I12: 수수료 | J12: 수수료합계 | K12: 정산합계 | L12: 정가합계
B13: 1 | C13: DOTEON Foot Cleaner | D13: 22000 | E13: =D13-(D13*F13) -> 19800 | F13: 0.1 | G13: ='DB)스마트스토어'!P12 -> 1 | H13: =E13*G13 -> 19800 | I13: 0.05 | J13: =H13*I13 -> 990 | K13: =H13-J13 -> 18810 | L13: =D13*G13 -> 22000
B14: 2 | C14: DOTEON Outdoor Spray | D14: 22000 | E14: =D14-(D14*F14) -> 19800 | F14: 0.1 | G14: ='DB)스마트스토어'!P11 -> 4 | H14: =E14*G14 -> 79200 | I14: 0.05 | J14: =H14*I14 -> 3960 | K14: =H14-J14 -> 75240 | L14: =D14*G14 -> 88000
C15: 합계 | G15: =SUM(G13:G14) -> 5 | H15: =SUM(H13:H14) -> 99000 | J15: =SUM(J13:J14) -> 4950 | K15: =H15-J15 -> 94050 | L15: =SUM(L13:L14) -> 110000
B18: 테일릿 | D18: 주요채널: 대리점(오프라인B2B전용 도매유통업) - 소매점 40% + 대리점마진 20% | K18: 매입(판매)
B19: 순번 | C19: 품목 구성 | D19: 정가 | E19: 대리점가 | F19: 기본수수료 | G19: 판매수량 | H19: 프로모션차감 | I19: 매출합계 | J19: 수수료합계 | K19: 정산합계 | L19: 정가합계
B20: 1 | C20: DOTEON Foot Cleaner | D20: 22000 | E20: 10560 | F20: 0.52 | G20: 0 | I20: =D20*G20 -> 0 | J20: =I20*F20 -> 0 | K20: =G20*I20 -> 0 | L20: =D20*G20 -> 0
B21: 2 | C21: DOTEON Outdoor Spray | D21: 22000 | E21: 10560 | F21: 0.52 | G21: 20 | I21: =D21*G21 -> 440000 | J21: =I21*F21 -> 228800 | K21: =I21-J21 -> 211200 | L21: =D21*G21 -> 440000
C22: 합계 | G22: 20 | H22: =SUM(H20:H21) -> 0 | I22: =SUM(I20:I21) -> 440000 | J22: =SUM(J20:J21) -> 228800 | K22: =SUM(K20:K21) -> 211200 | L22: =SUM(L17:L21) -> 440000
B25: 철수마켓 | K25: 판매자위탁배송
B26: 순번 | C26: 품목 구성 | D26: 정가 | E26: 프로모션가 | F26: 공급가 | G26: 수수료율 | H26: 판매수량 | I26: 매출합계 | J26: 수수료합계 | K26: 정산합계 | L26: 정가합계
B27: 1 | C27: DOTEON Foot Cleaner | D27: 22000 | E27: 22000 | F27: =E27-E27*G27 -> 16500 | G27: 0.25 | H27: 0 | I27: =E27*H27 -> 0 | J27: =E27*G27*H27 -> 0 | K27: =I27-J27 -> 0 | L27: =H27*D27 -> 0
C28: 합계 | H28: =SUM(H27:H27) -> 0 | I28: =SUM(I27) -> 0 | J28: =SUM(J27) -> 0 | K28: =SUM(K27) -> 0 | L28: =SUM(L27) -> 0
B31: 몰리스(이마트) | K31: 위탁재고
B32: 순번 | C32: 품목 구성 | D32: 정가 | E32: 프로모션가 | F32: 공급가 | G32: 수수료율 | H32: 판매수량 | I32: 매출합계 | J32: 수수료합계 | K32: 정산합계 | L32: 정가합계
B33: 1 | C33: DOTEON Foot Cleaner | D33: 22000 | E33: 22000 | F33: =E33-E33*G33 -> 15400 | G33: 0.3 | I33: =E33*H33 -> 0 | J33: =E33*G33*H33 -> 0 | K33: =I33-J33 -> 0 | L33: =D33*H33 -> 0
B34: 2 | C34: DOTEON Outdoor Spray | D34: 22000 | E34: 22000 | F34: =E34-E34*G34 -> 15400 | G34: 0.3 | H34: ='DB)이마트몰리스'!M11 -> 4 | I34: =E34*H34 -> 88000 | J34: =E34*G34*H34 -> 26400 | K34: =I34-J34 -> 61600 | L34: =D34*H34 -> 88000
C35: 합계 | H35: =SUM(H33:H34) -> 4 | I35: =SUM(I33:I34) -> 88000 | J35: =SUM(J33:J34) -> 26400 | K35: =SUM(K33:K34) -> 61600 | L35: =SUM(L33:L34) -> 88000
B38: 오버더센스 | D38: 주요채널: 제주도 반려동물 동반시설 | K38: 위탁재고
B39: 순번 | C39: 품목 구성 | D39: 정가 | E39: 공급가 | F39: 수수료율 | G39: 판매수량 | I39: 매출합계 | J39: 수수료합계 | K39: 정산합계 | L39: 정가합계
B40: 1 | C40: DOTEON Foot Cleaner | D40: 22000 | E40: =D40-D40*F40 -> 14740 | F40: 0.33 | G40: 0
B41: 2 | C41: DOTEON Outdoor Spray | D41: 22000 | E41: =D41-D41*F41 -> 14740 | F41: 0.33 | G41: 0
C42: 합계 | G42: =SUM(G40:G41) -> 0 | K42: =SUM(K40:K41) -> 0 | L42: =SUM(L40:L41) -> 0
B45: 우프자사몰 | D45: 주요채널: 우프앱/자사몰/스마트스토어 | G45: PG | K45: 직매출
B46: 순번 | C46: 품목 구성 | D46: 정가 | E46: 행사가 | F46: 할인율 | G46: 수수료율 | H46: 판매수량 | I46: 매출합계 | J46: 수수료합계 | K46: 정산합계 | L46: 정가합계
B47: 1 | C47: DOTEON Foot Cleaner | D47: 22000 | E47: =D47-D47*F47 -> 19800 | F47: 0.1 | G47: 0.05 | H47: ='DB)카페24'!D3 -> 4 | I47: =E47*H47 -> 79200 | J47: =I47*G47 -> 3960 | K47: =I47-J47 -> 75240 | L47: =D47*H47 -> 88000
B48: 2 | C48: DOTEON Outdoor Spray | D48: 22000 | E48: =D48-D48*F48 -> 19800 | F48: 0.1 | G48: 0.05 | H48: ='DB)카페24'!D4 -> 2 | I48: =E48*H48 -> 39600 | J48: =I48*G48 -> 1980 | K48: =I48-J48 -> 37620 | L48: =D48*H48 -> 44000
C49: 합계 | H49: =SUM(H47:H48) -> 6 | I49: =SUM(I47:I48) -> 118800 | J49: =SUM(J47:J48) -> 5940 | K49: =SUM(K47:K48) -> 112860 | L49: =SUM(L47:L48) -> 132000
B51: 자사몰-공구 | D51: 주요채널: 영이공구(인플루언서) | G51: 공구+PG | K51: 직매출
B52: 순번 | C52: 품목 구성 | D52: 정가 | E52: 행사가 | F52: 할인율 | G52: 공구수수료 | H52: 판매수량 | I52: 매출합계 | J52: 수수료합계 | K52: 정산합계 | L52: 정가합계
B53: 1 | C53: DOTEON Outdoor Spray | D53: 22000 | E53: =D53-D53*F53 -> 16500 | F53: 0.25 | G53: 0.25 | H53: ='DB)카페24 (공구)'!D3 -> 16 | I53: =E53*H53 -> 264000 | J53: =I53*G53 -> 66000 | K53: =I53-J53 -> 198000 | L53: =D53*H53 -> 352000
B54: 2 | C54: DOTEON Outdoor Spray 2개구매시 | D54: 22000 | E54: =D54-D54*F54 -> 14960 | F54: 0.32 | G54: 0.25 | H54: ='DB)카페24 (공구)'!I4 -> 20 | I54: =E54*H54 -> 299200 | J54: =I54*G54 -> 74800 | K54: =I54-J54 -> 224400 | L54: =D54*H54 -> 440000
B55: 3 | C55: DOTEON Outdoor Spray 3개구매시 | D55: 22000 | E55: =D55-D55*F55 -> 14080 | F55: 0.36 | G55: 0.25 | H55: ='DB)카페24 (공구)'!I5 -> 9 | I55: =E55*H55 -> 126720 | J55: =I55*G55 -> 31680 | K55: =I55-J55 -> 95040 | L55: =D55*H55 -> 198000
...

Sheet DB)입출고목록
C1: 출고건수 (송장기준/건) | F1: 품목 | H1: 입고합 | I1: 출고합
C2: 50 | F2: 도톤 포레스트 워터리스 풋클리너 100ml | H2: 0 | I2: 6
F3: 도톤 포레스트 아웃도어 스프레이 150ml | H3: 0 | I3: 89
H4: =SUBTOTAL(9,H2:H3) -> 0 | I4: =SUBTOTAL(9,I2:I3) -> 95
A7: 출고카운트 | B7: 입출고일자 | C7: 입력일자 | D7: 공급처명 | E7: 바코드번호 | F7: 상품명 | G7: 옵션내용 | H7: 상품코드 | I7: 원가 | J7: 입고수량 | K7: 입고금액 | L7: 출고수량 | M7: 출고금액 | N7: 재고작업구분 | O7: 판매처명 | P7: 판매단가 | Q7: 판매금액 | R7: 입출고구분
A8: 1 | B8: 46171 | C8: 2026-05-29 오후 12:00:45 | D8: 도톤 | E8: 8809879544118 | F8: 도톤 포레스트 워터리스 풋클리너 100ml | G8: 단일상품 | H8: 8810000000000 | I8: 0 | J8: 0 | K8: 0 | L8: 1 | M8: 0 | N8: 발송및출고 | O8: 스마트 스토어 (BETTERS) | P8: 22000 | Q8: 22000 | R8: 출고
A9: 3 | B9: 46168 | C9: 2026-05-26 오전 10:21:03 | D9: 도톤 | E9: 8809879544101 | F9: 도톤 포레스트 아웃도어 스프레이 150ml | G9: 단일상품 | H9: 8809880000000 | I9: 0 | J9: 0 | K9: 0 | L9: 3 | M9: 0 | N9: 발송및출고 | O9: 카페24_베럴즈 | P9: 22000 | Q9: 66000 | R9: 출고
A10: 4 | B10: 46164 | C10: 2026-05-22 오후 4:49:01 | D10: 도톤 | E10: 8809879544101 | F10: 도톤 포레스트 아웃도어 스프레이 150ml | G10: 단일상품 | H10: 8809880000000 | I10: 0 | J10: 0 | K10: 0 | L10: 1 | M10: 0 | N10: 발송및출고 | O10: 카페24_베럴즈_b2b | P10: 22000 | Q10: 22000 | R10: 출고
A11: 5 | B11: 46164 | C11: 2026-05-22 오후 4:49:01 | D11: 도톤 | E11: 8809879544118 | F11: 도톤 포레스트 워터리스 풋클리너 100ml | G11: 단일상품 | H11: 8810000000000 | I11: 0 | J11: 0 | K11: 0 | L11: 1 | M11: 0 | N11: 발송및출고 | O11: 카페24_베럴즈_b2b | P11: 22000 | Q11: 22000 | R11: 출고
A12: 6 | B12: 46161 | C12: 2026-05-19 오후 3:05:01 | D12: 도톤 | E12: 8809879544101 | F12: 도톤 포레스트 아웃도어 스프레이 150ml | G12: 단일상품 | H12: 8809880000000 | I12: 0 | J12: 0 | K12: 0 | L12: 1 | M12: 0 | N12: 발송및출고 | O12: 스마트 스토어 (BETTERS) | P12: 22000 | Q12: 22000 | R12: 출고
A13: 7 | B13: 46161 | C13: 2026-05-19 오후 3:04:55 | D13: 도톤 | E13: 8809879544101 | F13: 도톤 포레스트 아웃도어 스프레이 150ml | G13: 단일상품 | H13: 8809880000000 | I13: 0 | J13: 0 | K13: 0 | L13: 1 | M13: 0 | N13: 발송및출고 | O13: 카페24_베럴즈_b2b | P13: 22000 | Q13: 22000 | R13: 출고
A14: 8 | B14: 46160 | C14: 2026-05-18 오후 2:54:48 | D14: 도톤 | E14: 8809879544101 | F14: 도톤 포레스트 아웃도어 스프레이 150ml | G14: 단일상품 | H14: 8809880000000 | I14: 0 | J14: 0 | K14: 0 | L14: 1 | M14: 0 | N14: 발송및출고 | O14: 마켓컬리 | P14: 22000 | Q14: 22000 | R14: 출고
A15: 9 | B15: 46160 | C15: 2026-05-18 오전 9:32:43 | D15: 도톤 | E15: 8809879544101 | F15: 도톤 포레스트 아웃도어 스프레이 150ml | G15: 단일상품 | H15: 8809880000000 | I15: 0 | J15: 0 | K15: 0 | L15: 1 | M15: 0 | N15: 발송및출고 | O15: 카페24_베럴즈 | P15: 22000 | Q15: 22000 | R15: 출고
A16: 10 | B16: 46160 | C16: 2026-05-18 오전 9:32:38 | D16: 도톤 | E16: 8809879544101 | F16: 도톤 포레스트 아웃도어 스프레이 150ml | G16: 단일상품 | H16: 8809880000000 | I16: 0 | J16: 0 | K16: 0 | L16: 1 | M16: 0 | N16: 발송및출고 | O16: 카페24_베럴즈 | P16: 22000 | Q16: 22000 | R16: 출고
A17: 11 | B17: 46160 | C17: 2026-05-18 오전 9:32:34 | D17: 도톤 | E17: 8809879544101 | F17: 도톤 포레스트 아웃도어 스프레이 150ml | G17: 단일상품 | H17: 8809880000000 | I17: 0 | J17: 0 | K17: 0 | L17: 1 | M17: 0 | N17: 발송및출고 | O17: 카페24_베럴즈 | P17: 22000 | Q17: 22000 | R17: 출고
A18: 12 | B18: 46160 | C18: 2026-05-18 오전 9:32:29 | D18: 도톤 | E18: 8809879544101 | F18: 도톤 포레스트 아웃도어 스프레이 150ml | G18: 단일상품 | H18: 8809880000000 | I18: 0 | J18: 0 | K18: 0 | L18: 1 | M18: 0 | N18: 발송및출고 | O18: 카페24_베럴즈 | P18: 22000 | Q18: 22000 | R18: 출고
A19: 13 | B19: 46160 | C19: 2026-05-18 오전 9:32:07 | D19: 도톤 | E19: 8809879544101 | F19: 도톤 포레스트 아웃도어 스프레이 150ml | G19: 단일상품 | H19: 8809880000000 | I19: 0 | J19: 0 | K19: 0 | L19: 2 | M19: 0 | N19: 발송및출고 | O19: 카페24_베럴즈 | P19: 22000 | Q19: 44000 | R19: 출고
... A56: 50 | B56: 46146 | C56: 2026-05-04 오후 4:15:56 | D56: 도톤 | E56: 8809879544101 | F56: 도톤 포레스트 아웃도어 스프레이 150ml | G56: 단일상품 | H56: 8809880000000 | I56: 0 | J56: 0 | K56: 0 | L56: 1 | M56: 0 | N56: 발송및출고 | O56: 카페24_베럴즈_b2b | P56: 22000 | Q56: 22000 | R56: 출고

Sheet DB)입출고매칭용
A1: 공급처명 | B1: 주문일자 | C1: 판매처상품코드 | D1: 판매처상품명 | E1: 판매처명 | F1: 송장번호 | G1: 주문상품출고일시 | H1: 발송일자 | I1: 상품옵션 | J1: 주문수량 | K1: 주문자 | L1: 수령자 | M1: 재고매칭(1)바코드번호 | N1: 재고매칭(1)상품명 | O1: 재고매칭(1)주문수량 | Q1: 판매처주문번호 | R1: 판매처주문번호 | S1: 판매상세 (판매 수수료율)
A2: 도톤 | B2: 46170 | C2: 12423395816 | D2: 도톤 포레스트 워터리스 풋클리너 강아지 발세정제 100ml | E2: 스마트 스토어 (BETTERS) | F2: 92235591383 | G2: 2026-05-29 오후 12:00:45 | H2: 2026-05-29 오후 12:00:45 | J2: 1 | K2: ="유*애" -> 유*애 | L2: ="유*애" -> 유*애 | M2: 8809879544118 | N2: 도톤 포레스트 워터리스 풋클리너 100ml | O2: 1 | P2: 판매 | Q2: ="2026052860134141" -> 2026052860134141 | R2: ="20260429-0000187" -> 20260429-0000187
A3: 도톤 | B3: 46166 | C3: P000BMBG | D3: [영이공구특가 이벤트 상품] 도톤 포레스트 아웃도어 해충방지 스프레이 150ml | E3: 카페24_베럴즈 | F3: 92235430313 | G3: 2026-05-26 오전 10:21:03 | H3: 2026-05-26 오전 10:21:03 | I3: 수량=공구 3개세트 (36%할인) | J3: 1 | K3: ="한*연" -> 한*연 | L3: ="한*연" -> 한*연 | M3: 8809879544101 | N3: 도톤 포레스트 아웃도어 스프레이 150ml | O3: 3 | P3: 판매 | Q3: ="20260524-0000035" -> 20260524-0000035 | R3: ="20260428-0000100" -> 20260428-0000100
A4: 도톤 | B4: 46164 | C4: P000BLYY | D4: 도톤 포레스트 아웃도어 스프레이 150ml 강아지 해충방지 진드기 | E4: 카페24_베럴즈_b2b | F4: 92235390472 | G4: 2026-05-22 오후 4:49:01 | H4: 2026-05-22 오후 4:49:02 | J4: 1 | K4: ="B*********B" -> B*********B | L4: ="몰*******점" -> 몰*******점 | M4: 8809879544101 | N4: 도톤 포레스트 아웃도어 스프레이 150ml | O4: 1 | P4: 재고이동 | Q4: ="20260522-0000109" -> 20260522-0000109 | R4: ="2026042891931141" -> 2026042891931141
A5: 도톤 | B5: 46164 | C5: P000BLYX | D5: 도톤 포레스트 워터리스 풋클리너 강아지 발세정제 100ml | E5: 카페24_베럴즈_b2b | F5: 92235390472 | G5: 2026-05-22 오후 4:49:01 | H5: 2026-05-22 오후 4:49:02 | J5: 1 | K5: ="B*********B" -> B*********B | L5: ="몰*******점" -> 몰*******점 | M5: 8809879544118 | N5: 도톤 포레스트 워터리스 풋클리너 100ml | O5: 1 | P5: 재고이동 | Q5: ="20260522-0000109" -> 20260522-0000109 | R5: ="20260429-0000099" -> 20260429-0000099
A6: 도톤 | B6: 46161 | C6: P000BLYY | D6: 도톤 포레스트 아웃도어 스프레이 150ml 강아지 해충방지 진드기 | E6: 카페24_베럴즈_b2b | F6: 92235276490 | G6: 2026-05-19 오후 3:04:55 | H6: 2026-05-19 오후 3:04:55 | J6: 1 | K6: ="B*********B" -> B*********B | L6: ="안****팡" -> 안****팡 | M6: 8809879544101 | N6: 도톤 포레스트 아웃도어 스프레이 150ml | O6: 1 | P6: 판매 | Q6: ="20260519-0000199" -> 20260519-0000199 | R6: ="20260429-0000122" -> 20260429-0000122
A7: 도톤 | B7: 46161 | C7: 12423379709 | D7: 도톤 포레스트 아웃도어 스프레이 150ml 강아지 해충방지 진드기 | E7: 스마트 스토어 (BETTERS) | F7: 92235276604 | G7: 2026-05-19 오후 3:05:01 | H7: 2026-05-19 오후 3:05:02 | J7: 1 | K7: ="조*정" -> 조*정 | L7: ="조*정" -> 조*정 | M7: 8809879544101 | N7: 도톤 포레스트 아웃도어 스프레이 150ml | O7: 1 | P7: 판매 | Q7: ="2026051982360941" -> 2026051982360941 | R7: ="20260425-0000045" -> 20260425-0000045
A8: 도톤 | B8: 46160 | C8: P000BMBG | D8: [영이공구특가 이벤트 상품] 도톤 포레스트 아웃도어 해충방지 스프레이 150ml | E8: 카페24_베럴즈 | F8: 92235147384 | G8: 2026-05-18 오전 9:32:07 | H8: 2026-05-18 오전 9:32:07 | I8: 수량=공구 2개세트 (32%할인) | J8: 1 | K8: ="김*민" -> 김*민 | L8: ="김*민" -> 김*민 | M8: 8809879544101 | N8: 도톤 포레스트 아웃도어 스프레이 150ml | O8: 2 | P8: 판매 | Q8: ="20260517-0000086" -> 20260517-0000086 | R8: ="20260426-0000011" -> 20260426-0000011
A9: 도톤 | B9: 46160 | C9: P000BLYY | D9: 도톤 포레스트 아웃도어 스프레이 150ml 강아지 해충방지 진드기 | E9: 카페24_베럴즈 | F9: 92235147631 | G9: 2026-05-18 오전 9:32:38 | H9: 2026-05-18 오전 9:32:38 | J9: 1 | K9: ="박*영" -> 박*영 | L9: ="박*영" -> 박*영 | M9: 8809879544101 | N9: 도톤 포레스트 아웃도어 스프레이 150ml | O9: 1 | P9: 판매 | Q9: ="20260517-0000075" -> 20260517-0000075 | R9: ="20260426-0000062" -> 20260426-0000062
A10: 도톤 | B10: 46160 | C10: P000BMBG | D10: [영이공구특가 이벤트 상품] 도톤 포레스트 아웃도어 해충방지 스프레이 150ml | E10: 카페24_베럴즈 | F10: 92235147594 | G10: 2026-05-18 오전 9:32:34 | H10: 2026-05-18 오전 9:32:34 | I10: 수량=공구특가 1개 (25%할인) | J10: 1 | K10: ="최*영" -> 최*영 | L10: ="최*영" -> 최*영 | M10: 8809879544101 | N10: 도톤 포레스트 아웃도어 스프레이 150ml | O10: 1 | P10: 판매 | Q10: ="20260517-0000142" -> 20260517-0000142 | R10: ="20260426-0000221" -> 20260426-0000221
A11: 도톤 | B11: 46160 | C11: P000BMBG | D11: [영이공구특가 이벤트 상품] 도톤 포레스트 아웃도어 해충방지 스프레이 150ml | E11: 카페24_베럴즈 | F11: 92235147583 | G11: 2026-05-18 오전 9:32:29 | H11: 2026-05-18 오전 9:32:29 | I11: 수량=공구특가 1개 (25%할인) | J11: 1 | K11: ="마*" -> 마* | L11: ="마*" -> 마* | M11: 8809879544101 | N11: 도톤 포레스트 아웃도어 스프레이 150ml | O11: 1 | P11: 판매 | Q11: ="20260517-0000159" -> 20260517-0000159 | R11: ="20260427-0000031" -> 20260427-0000031
A12: 도톤 | B12: 46160 | C12: P25102716000204 | D12: [도톤] 포레스트 아웃도어 스프레이 150ml 강아지 해충방지 진드기 (도톤 포레스트 아웃도어 스프레이) | E12: 마켓컬리 | F12: 92235225891 | G12: 2026-05-18 오후 2:54:48 | H12: 2026-05-18 오후 2:54:48 | I12: 도톤 포레스트 아웃도어 스프레이 | J12: 1 | K12: ="김*연" -> 김*연 | L12: ="김*연" -> 김*연 | M12: 8809879544101 | N12: 도톤 포레스트 아웃도어 스프레이 150ml | O12: 1 | P12: 판매 | Q12: ="2415219160235" -> 2415219160235 | R12: ="20260427-0000052" -> 20260427-0000052
A13: 도톤 | B13: 46158 | C13: P000BMBG | D13: [영이공구특가 이벤트 상품] 도톤 포레스트 아웃도어 해충방지 스프레이 150ml | E13: 카페24_베럴즈 | F13: 92235147141 | G13: 2026-05-18 오전 9:32:03 | H13: 2026-05-18 오전 9:32:03 | I13: 수량=공구 2개세트 (32%할인) | J13: 1 | K13: ="오*경" -> 오*경 | L13: ="오*경" -> 오*경 | M13: 8809879544101 | N13: 도톤 포레스트 아웃도어 스프레이 150ml | O13: 2 | P13: 판매 | Q13: ="20260515-0000148" -> 20260515-0000148 | R13: ="2026042577184211" -> 2026042577184211
A14: 도톤 | B14: 46158 | C14: P000BMBG | D14: [영이공구특가 이벤트 상품] 도톤 포레스트 아웃도어 해충방지 스프레이 150ml | E14: 카페24_베럴즈 | F14: 92235147771 | G14: 2026-05-18 오전 9:32:43 | H14: 2026-05-18 오전 9:32:43 | I14: 수량=공구특가 1개 (25%할인) | J14: 1 | K14: ="홍*경" -> 홍*경 | L14: ="홍*경" -> 홍*경 | M14: 8809879544101 | N14: 도톤 포레스트 아웃도어 스프레이 150ml | O14: 1 | P14: 판매 | Q14: ="20260516-0000015" -> 20260516-0000015 | R14: ="20260425-0000019" -> 20260425-0000019
A15: 도톤 | B15: 46157 | C15: P000BMBG | D15: [영이공구특가 이벤트 상품] 도톤 포레스트 아웃도어 해충방지 스프레이 150ml | E15: 카페24_베럴즈 | F15: 92235116142 | G15: 2026-05-15 오후 2:56:48 | H15: 2026-05-15 오후 2:56:48 | I15: 수량=공구 2개세트 (32%할인) | J15: 1 | K15: ="유*용" -> 유*용 | L15: ="유*용" -> 유*용 | M15: 8809879544101 | N15: 도톤 포레스트 아웃도어 스프레이 150ml | O15: 2 | P15: 판매 | Q15: ="20260515-0000047" -> 20260515-0000047 | R15: ="20260425-0000031" -> 20260425-0000031
A16: 도톤 | B16: 46157 | C16: P000BMBG | D16: [영이공구특가 이벤트 상품] 도톤 포레스트 아웃도어 해충방지 스프레이 150ml | E16: 카페24_베럴즈 | F16: 92235090065 | G16: 2026-05-15 오전 9:15:57 | H16: 2026-05-15 오전 9:15:57 | I16: 수량=공구 2개세트 (32%할인) | J16: 1 | K16: ="박*연" -> 박*연 | L16: ="박*연" -> 박*연 | M16: 8809879544101 | N16: 도톤 포레스트 아웃도어 스프레이 150ml | O16: 2 | P16: 판매 | Q16: ="20260514-0000167" -> 20260514-0000167 | R16: ="20260426-0000091" -> 20260426-0000091
A17: 도톤 | B17: 46157 | C17: P000BMBG | D17: [영이공구특가 이벤트 상품] 도톤 포레스트 아웃도어 해충방지 스프레이 150ml | E17: 카페24_베럴즈 | F17: 92235090054 | G17: 2026-05-15 오전 9:15:53 | H17: 2026-05-15 오전 9:15:53 | I17: 수량=공구 2개세트 (32%할인) | J17: 1 | K17: ="오*진" -> 오*진 | L17: ="오*진" -> 오*진 | M17: 8809879544101 | N17: 도톤 포레스트 아웃도어 스프레이 150ml | O17: 2 | P17: 판매 | Q17: ="20260514-0000198" -> 20260514-0000198 | R17: ="20260426-0000115" -> 20260426-0000115
A18: 도톤 | B18: 46157 | C18: P000BMBG | D18: [영이공구특가 이벤트 상품] 도톤 포레스트 아웃도어 해충방지 스프레이 150ml | E18: 카페24_베럴즈 | F18: 92235090043 | G18: 2026-05-15 오전 9:15:50 | H18: 2026-05-15 오전 9:15:50 | I18: 수량=공구 2개세트 (32%할인) | J18: 1 | K18: ="김*비" -> 김*비 | L18: ="시*떡" -> 시*떡 | M18: 8809879544101 | N18: 도톤 포레스트 아웃도어 스프레이 150ml | O18: 2 | P18: 판매 | Q18: ="20260514-0000204" -> 20260514-0000204 | R18: ="20260424-0000051" -> 20260424-0000051
A19: 도톤 | B19: 46157 | C19: P000BMBG | D19: [영이공구특가 이벤트 상품] 도톤 포레스트 아웃도어 해충방지 스프레이 150ml | E19: 카페24_베럴즈 | F19: 92235090076 | G19: 2026-05-15 오전 9:15:43 | H19: 2026-05-15 오전 9:15:43 | I19: 수량=공구특가 1개 (25%할인) | J19: 1 | K19: ="남*선" -> 남*선 | L19: ="남*선" -> 남*선 | M19: 8809879544101 | N19: 도톤 포레스트 아웃도어 스프레이 150ml | O19: 1 | P19: 판매 | Q19: ="20260515-0000021" -> 20260515-0000021 | R19: ="20260424-0000065" -> 20260424-0000065
A20: 도톤 | B20: 46156 | C20: P000BLYY | D20: 도톤 포레스트 아웃도어 스프레이 150ml 강아지 해충방지 진드기 | E20: 카페24_베럴즈_b2b | F20: 92235116105 | G20: 2026-05-15 오후 3:15:11 | H20: 2026-05-15 오후 3:15:11 | J20: 9 | K20: ="김*성" -> 김*성 | L20: ="김*성" -> 김*성 | M20: 8809879544101 | N20: 도톤 포레스트 아웃도어 스프레이 150ml | O20: 9 | P20: 판매 | Q20: ="20260513-0000077" -> 20260513-0000077 | R20: ="20260423-0000261" -> 20260423-0000261
A21: 도톤 | B21: 46156 | C21: P000BMBG | D21: [영이공구특가 이벤트 상품] 도톤 포레스트 아웃도어 해충방지 스프레이 150ml | E21: 카페24_베럴즈 | F21: 92235055920 | G21: 2026-05-14 오전 9:44:36 | H21: 2026-05-14 오전 9:44:36 | I21: 수량=공구 3개세트 (36%할인) | J21: 1 | K21: ="박**리" -> 박**리 | L21: ="박**리" -> 박**리 | M21: 8809879544101 | N21: 도톤 포레스트 아웃도어 스프레이 150ml | O21: 3 | P21: 판매 | Q21: ="20260513-0000276" -> 20260513-0000276 | R21: ="20260424-0000043" -> 20260424-0000043
A22: 도톤 | B22: 46156 | C22: P000BMBG | D22: [영이공구특가 이벤트 상품] 도톤 포레스트 아웃도어 해충방지 스프레이 150ml | E22: 카페24_베럴즈 | F22: 92235071714 | G22: 2026-05-14 오후 1:46:14 | H22: 2026-05-14 오후 1:46:14 | I22: 수량=공구특가 1개 (25%할인) | J22: 1 | K22: ="백*영" -> 백*영 | L22: ="백*영" -> 백*영 | M22: 8809879544101 | N22: 도톤 포레스트 아웃도어 스프레이 150ml | O22: 1 | P22: 판매 | Q22: ="20260514-0000076" -> 20260514-0000076 | R22: ="20260424-0000043" -> 20260424-0000043
A23: 도톤 | B23: 46156 | C23: P000BMBG | D23: [영이공구특가 이벤트 상품] 도톤 포레스트 아웃도어 해충방지 스프레이 150ml | E23: 카페24_베럴즈 | F23: 92235056082 | G23: 2026-05-14 오전 9:44:26 | H23: 2026-05-14 오전 9:44:26 | I23: 수량=공구특가 1개 (25%할인) | J23: 1 | K23: ="정*은" -> 정*은 | L23: ="정*은" -> 정*은 | M23: 8809879544101 | N23: 도톤 포레스트 아웃도어 스프레이 150ml | O23: 1 | P23: 판매 | Q23: ="20260513-0000204" -> 20260513-0000204 | R23: ="20260423-0000201" -> 20260423-0000201
A24: 도톤 | B24: 46156 | C24: P000BMBG | D24: [영이공구특가 이벤트 상품] 도톤 포레스트 아웃도어 해충방지 스프레이 150ml | E24: 카페24_베럴즈 | F24: 92235055990 | G24: 2026-05-14 오전 9:44:22 | H24: 2026-05-14 오전 9:44:22 | I24: 수량=공구특가 1개 (25%할인) | J24: 1 | K24: ="유*혜" -> 유*혜 | L24: ="유*혜" -> 유*혜 | M24: 8809879544101 | N24: 도톤 포레스트 아웃도어 스프레이 150ml | O24: 1 | P24: 판매 | Q24: ="20260514-0000010" -> 20260514-0000010 | R24: ="20260423-0000164" -> 20260423-0000164
A25: 도톤 | B25: 46156 | C25: P000BMBG | D25: [영이공구특가 이벤트 상품] 도톤 포레스트 아웃도어 해충방지 스프레이 150ml | E25: 카페24_베럴즈 | F25: 92235055986 | G25: 2026-05-14 오전 9:44:24 | H25: 2026-05-14 오전 9:44:24 | I25: 수량=공구특가 1개 (25%할인) | J25: 1 | K25: ="윤*령" -> 윤*령 | L25: ="윤*령" -> 윤*령 | M25: 8809879544101 | N25: 도톤 포레스트 아웃도어 스프레이 150ml | O25: 1 | P25: 판매 | Q25: ="20260514-0000024" -> 20260514-0000024 | R25: ="20260422-0000144" -> 20260422-0000144
A26: 도톤 | B26: 46155 | C26: P000BMBG | D26: [영이공구특가 이벤트 상품] 도톤 포레스트 아웃도어 해충방지 스프레이 150ml | E26: 카페24_베럴즈 | F26: 92235055533 | G26: 2026-05-14 오전 9:44:31 | H26: 2026-05-14 오전 9:44:31 | I26: 수량=공구 2개세트 (32%할인) | J26: 1 | K26: ="변*솜" -> 변*솜 | L26: ="김*옥" -> 김*옥 | M26: 8809879544101 | N26: 도톤 포레스트 아웃도어 스프레이 150ml | O26: 2 | P26: 판매 | Q26: ="20260513-0000141" -> 20260513-0000141 | R26: ="20260423-0000102" -> 20260423-0000102
A27: 도톤 | B27: 46155 | C27: P000BLYY | D27: 도톤 포레스트 아웃도어 스프레이 150ml 강아지 해충방지 진드기 | E27: 카페24_베럴즈_b2b | F27: 92235055500 | G27: 2026-05-14 오전 9:54:03 | H27: 2026-05-14 오전 9:54:03 | J27: 20 | K27: ="우*(베*즈)" -> 우*(베*즈) | L27: ="테*릿" -> 테*릿 | M27: 8809879544101 | N27: 도톤 포레스트 아웃도어 스프레이 150ml | O27: 20 | P27: 판매 | Q27: ="20260513-0000179" -> 20260513-0000179 | R27: ="20260423-0000014" -> 20260423-0000014
A28: 도톤 | B28: 46155 | C28: P000BMBG | D28: [영이공구특가 이벤트 상품] 도톤 포레스트 아웃도어 해충방지 스프레이 150ml | E28: 카페24_베럴즈 | F28: 92235044171 | G28: 2026-05-13 오후 4:17:35 | H28: 2026-05-13 오후 4:17:35 | I28: 수량=공구 3개세트 (36%할인) | J28: 1 | K28: ="김*미" -> 김*미 | L28: ="r*******g" -> r*******g | M28: 8809879544101 | N28: 도톤 포레스트 아웃도어 스프레이 150ml | O28: 3 | P28: 판매 | Q28: ="20260513-0000094" -> 20260513-0000094 | R28: ="20260422-0000082" -> 20260422-0000082
A29: 도톤 | B29: 46155 | C29: P000BMBG | D29: [영이공구특가 이벤트 상품] 도톤 포레스트 아웃도어 해충방지 스프레이 150ml | E29: 카페24_베럴즈 | F29: 92235033800 | G29: 2026-05-13 오후 1:55:16 | H29: 2026-05-13 오후 1:55:16 | I29: 수량=공구 2개세트 (32%할인) | J29: 1 | K29: ="고*별" -> 고*별 | L29: ="고*별" -> 고*별 | M29: 8809879544101 | N29: 도톤 포레스트 아웃도어 스프레이 150ml | O29: 2 | P29: 판매 | Q29: ="20260513-0000049" -> 20260513-0000049 | R29: ="20260421-0000231" -> 20260421-0000231
A30: 도톤 | B30: 46155 | C30: P000BLYX | D30: 도톤 포레스트 워터리스 풋클리너 강아지 발세정제 100ml | E30: 카페24_베럴즈 | F30: 92235030193 | G30: 2026-05-13 오후 12:36:38 | H30: 2026-05-13 오후 12:36:38 | J30: 2 | K30: ="구*모" -> 구*모 | L30: ="구*모" -> 구*모 | M30: 8809879544118 | N30: 도톤 포레스트 워터리스 풋클리너 100ml | O30: 2 | P30: 판매 | Q30: ="20260513-0000012" -> 20260513-0000012 | R30: ="20260422-0000024" -> 20260422-0000024
A31: 도톤 | B31: 46155 | C31: P000BMBG | D31: [영이공구특가 이벤트 상품] 도톤 포레스트 아웃도어 해충방지 스프레이 150ml | E31: 카페24_베럴즈 | F31: 92235033870 | G31: 2026-05-13 오후 1:55:12 | H31: 2026-05-13 오후 1:55:13 | I31: 수량=공구특가 1개 (25%할인) | J31: 1 | K31: ="임*현" -> 임*현 | L31: ="홍*민" -> 홍*민 | M31: 8809879544101 | N31: 도톤 포레스트 아웃도어 스프레이 150ml | O31: 1 | P31: 판매 | Q31: ="20260513-0000086" -> 20260513-0000086 | R31: ="20260422-0000092" -> 20260422-0000092
A32: 도톤 | B32: 46153 | C32: P000BLYY | D32: 도톤 포레스트 아웃도어 스프레이 150ml 강아지 해충방지 진드기 | E32: 카페24_베럴즈_b2b | F32: 92234949590 | G32: 2026-05-11 오후 3:17:03 | H32: 2026-05-11 오후 3:17:03 | J32: 1 | K32: ="B*********B" -> B*********B | L32: ="인*****팡" -> 인*****팡 | M32: 8809879544101 | N32: 도톤 포레스트 아웃도어 스프레이 150ml | O32: 1 | P32: 판매 | Q32: ="20260511-0000065" -> 20260511-0000065 | R32: ="20260421-0000244" -> 20260421-0000244
A33: 도톤 | B33: 46152 | C33: 12423379709 | D33: 도톤 포레스트 아웃도어 스프레이 150ml 강아지 해충방지 진드기 | E33: 스마트 스토어 (BETTERS) | F33: 92234907520 | G33: 2026-05-11 오전 9:10:42 | H33: 2026-05-11 오전 9:10:42 | J33: 1 | K33: ="유*진" -> 유*진 | L33: ="공*" -> 공* | M33: 8809879544101 | N33: 도톤 포레스트 아웃도어 스프레이 150ml | O33: 1 | P33: 판매 | Q33: ="2026051018182881" -> 2026051018182881 | R33: ="20260422-0000037" -> 20260422-0000037
A34: 도톤 | B34: 46152 | C34: 12423395816 | D34: 도톤 포레스트 워터리스 풋클리너 강아지 발세정제 100ml | E34: 스마트 스토어 (BETTERS) | F34: 92234907520 | G34: 2026-05-11 오전 9:10:42 | H34: 2026-05-11 오전 9:10:42 | J34: 1 | K34: ="유*진" -> 유*진 | L34: ="공*" -> 공* | M34: 8809879544118 | N34: 도톤 포레스트 워터리스 풋클리너 100ml | O34: 1 | P34: 판매 | Q34: ="2026051018182881" -> 2026051018182881 | R34: ="20260422-0000068" -> 20260422-0000068
A35: 도톤 | B35: 46152 | C35: P000BMBG | D35: [영이공구특가 이벤트 상품] 도톤 포레스트 아웃도어 해충방지 스프레이 150ml | E35: 카페24_베럴즈 | F35: 92234907660 | G35: 2026-05-11 오전 9:10:48 | H35: 2026-05-11 오전 9:10:48 | I35: 수량=공구특가 1개 (25%할인) | J35: 1 | K35: ="김*은" -> 김*은 | L35: ="김*은" -> 김*은 | M35: 8809879544101 | N35: 도톤 포레스트 아웃도어 스프레이 150ml | O35: 1 | P35: 판매 | Q35: ="20260509-0000101" -> 20260509-0000101 | R35: ="20260421-0000082" -> 20260421-0000082
A36: 도톤 | B36: 46150 | C36: P000BLYY | D36: 도톤 포레스트 아웃도어 스프레이 150ml 강아지 해충방지 진드기 | E36: 카페24_베럴즈_b2b | F36: 92234875880 | G36: 2026-05-08 오후 3:39:40 | H36: 2026-05-08 오후 3:39:40 | J36: 1 | K36: ="B*********B" -> B*********B | L36: ="몰*******점" -> 몰*******점 | M36: 8809879544101 | N36: 도톤 포레스트 아웃도어 스프레이 150ml | O36: 1 | P36: 재고이동 | Q36: ="20260508-0000117" -> 20260508-0000117 | R36: ="20260421-0000101" -> 20260421-0000101
A37: 도톤 | B37: 46150 | C37: P000BMBG | D37: [영이공구특가 이벤트 상품] 도톤 포레스트 아웃도어 해충방지 스프레이 150ml | E37: 카페24_베럴즈 | F37: 92234852356 | G37: 2026-05-08 오후 1:56:15 | H37: 2026-05-08 오후 1:56:15 | I37: 수량=공구특가 1개 (25%할인) | J37: 1 | K37: ="유*나" -> 유*나 | L37: ="유*나" -> 유*나 | M37: 8809879544101 | N37: 도톤 포레스트 아웃도어 스프레이 150ml | O37: 1 | P37: 판매 | Q37: ="20260507-0000266" -> 20260507-0000266 | R37: ="20260421-0000121" -> 20260421-0000121
A38: 도톤 | B38: 46149 | C38: P000BLYY | D38: 도톤 포레스트 아웃도어 스프레이 150ml 강아지 해충방지 진드기 | E38: 카페24_베럴즈_b2b | F38: 92234826482 | G38: 2026-05-07 오후 2:34:15 | H38: 2026-05-07 오후 2:34:15 | J38: 2 | K38: ="B*********B" -> B*********B | L38: ="쿠******터" -> 쿠******터 | M38: 8809879544101 | N38: 도톤 포레스트 아웃도어 스프레이 150ml | O38: 2 | P38: 판매 | Q38: ="20260507-0000105" -> 20260507-0000105 | R38: ="20260421-0000164" -> 20260421-0000164
A39: 도톤 | B39: 46149 | C39: P25102716000204 | D39: [도톤] 포레스트 아웃도어 스프레이 150ml 강아지 해충방지 진드기 (도톤 포레스트 아웃도어 스프레이) | E39: 마켓컬리 | F39: 92234826460 | G39: 2026-05-07 오후 2:26:23 | H39: 2026-05-07 오후 2:26:23 | I39: 도톤 포레스트 아웃도어 스프레이 | J39: 2 | K39: ="이*진" -> 이*진 | L39: ="이*진" -> 이*진 | M39: 8809879544101 | N39: 도톤 포레스트 아웃도어 스프레이 150ml | O39: 2 | P39: 판매 | Q39: ="2414405580018" -> 2414405580018 | R39: ="20260421-0000069" -> 20260421-0000069
A40: 도톤 | B40: 46148 | C40: P000BMBG | D40: [영이공구특가 이벤트 상품] 도톤 포레스트 아웃도어 해충방지 스프레이 150ml | E40: 카페24_베럴즈 | F40: 92234762723 | G40: 2026-05-06 오후 1:12:38 | H40: 2026-05-06 오후 1:12:38 | I40: 수량=공구 2개세트 (32%할인) | J40: 1 | K40: ="김*람" -> 김*람 | L40: ="김*람" -> 김*람 | M40: 8809879544101 | N40: 도톤 포레스트 아웃도어 스프레이 150ml | O40: 2 | P40: 판매 | Q40: ="20260506-0000014" -> 20260506-0000014 | R40: ="20260421-0000142" -> 20260421-0000142
...

Sheet DB)카페24
A2: 집계기간: 26.5.1-5.31 | C2: 품목 | D2: 수량 | E2: 혜택적용 (프로모션 및 공구할인) | F2: 판매가격 | G2: 판매가합 | H2: 정가기준
A3: 기준: 배송완료 | C3: 도톤 포레스트 워터리스 풋클리너 강아지 발세정제 100ml | D3: 4 | E3: 상시할인 -10% | F3: =22000*90% -> 19800 | G3: =D3*F3 -> 79200 | H3: =22000*D3 -> 88000
C4: 도톤 포레스트 아웃도어 스프레이 150ml 강아지 해충방지 진드기 | D4: 2 | E4: 상시할인 -10% | F4: =22000*90% -> 19800 | G4: =D4*F4 -> 39600 | H4: =22000*D4 -> 44000
C8: 합계 | D8: =SUBTOTAL(9,D3:D7) -> 6 | G8: =SUBTOTAL(9,G3:G7) -> 118800 | H8: =SUBTOTAL(9,H3:H7) -> 132000
A13: 주문번호 | B13: 품목별 주문번호 | C13: 공급사 | D13: 공급사명 | E13: 결제일시(입금확인일) | F13: 배송시작일 | G13: 운송장번호 | H13: 배송완료일 | I13: 환불완료일 | J13: 주문상품명(기본) | K13: 상품옵션(기본) | L13: 수량 | M13: 판매가 | N13: 옵션추가 가격 | O13: 상품별 추가할인금액 | P13: 상품별 추가할인 상세 | Q13: 공급사 기본 배송비 | R13: 개별배송비 | S13: 쿠폰 할인금액(최종) | T13: 사용한 쿠폰명 | U13: 주문자명 | V13: 반품신청일 | W13: 교환상태 | X13: 쇼핑몰 | Y13: 옵션+판매가 | Z13: 주문 상태 | AA13: 지역별 배송비 | AB13: 환불상태 | AC13: 품목별 결제금액
A14: 20260501-0000125 | B14: 20260501-0000125-05 | C14: S00000QR | D14: 베럴즈 | E14: 46143.875 | F14: 46146.702 | G14: 92234714132 | H14: 46149.71 | J14: 도톤 포레스트 워터리스 풋클리너 강아지 발세정제 100ml | L14: 1 | M14: 22000 | N14: 0 | O14: 2200 | P14: 도톤 상시 | Q14: 0 | R14: 0 | S14: 3000 | T14: 신규가입 장바구니 3천원 할인 쿠폰 | U14: 위혜란 | X14: 우프(기본) | Y14: 22000 | Z14: 배송 완료 | AA14: 0
A15: 20260501-0000125 | B15: 20260501-0000125-06 | C15: S00000QR | D15: 베럴즈 | E15: 46143.875 | F15: 46146.702 | G15: 92234714132 | H15: 46149.71 | J15: 도톤 포레스트 아웃도어 스프레이 150ml 강아지 해충방지 진드기 | L15: 1 | M15: 22000 | N15: 0 | O15: 2200 | P15: 도톤 상시 | Q15: 0 | R15: 0 | S15: 3000 | T15: 신규가입 장바구니 3천원 할인 쿠폰 | U15: 위혜란 | X15: 우프(기본) | Y15: 22000 | Z15: 배송 완료 | AA15: 0
A16: 20260513-0000012 | B16: 20260513-0000012-01 | C16: S00000QR | D16: 베럴즈 | E16: 46155.026 | F16: 46155.528 | G16: 92235030193 | H16: 46160.423 | J16: 도톤 포레스트 워터리스 풋클리너 강아지 발세정제 100ml | L16: 2 | M16: 22000 | N16: 0 | O16: 4400 | P16: 도톤 상시 | Q16: 0 | R16: 0 | S16: 0 | U16: 구범모 | X16: 우프(기본) | Y16: 22000 | Z16: 배송 완료 | AA16: 0
A17: 20260517-0000075 | B17: 20260517-0000075-01 | C17: S00000QR | D17: 베럴즈 | E17: 46159.772 | F17: 46160.403 | G17: 92235147631 | H17: 46161.598 | J17: 도톤 포레스트 아웃도어 스프레이 150ml 강아지 해충방지 진드기 | L17: 1 | M17: 22000 | N17: 0 | O17: 2200 | P17: 도톤 상시 | Q17: 0 | R17: 0 | S17: 0 | U17: 박은영 | X17: 우프(기본) | Y17: 22000 | Z17: 배송 완료 | AA17: 0
A18: 20260530-0000050 | B18: 20260530-0000050-02 | C18: S00000QR | D18: 베럴즈 | E18: 46172.173 | F18: 46174.645 | G18: 92235668206 | H18: 46175.757 | J18: 도톤 포레스트 워터리스 풋클리너 강아지 발세정제 100ml | L18: 1 | M18: 22000 | N18: 0 | O18: 2200 | P18: 도톤 상시 | Q18: 0 | R18: 0 | S18: 0 | U18: 정현택 | X18: 우프(기본) | Y18: 22000 | Z18: 배송 완료 | AA18: 0

Sheet DB)카페24 (공구)
A2: 집계기간: 26.5.1-5.31 | C2: 품목 | D2: 수량(건) | E2: 혜택적용 (프로모션 및 공구할인) | F2: 판매가격 | G2: 판매가합 | H2: 정가기준 | I2: 실출고수량(개)
A3: 기준: 배송완료 | C3: 도톤 포레스트 아웃도어 스프레이 150ml 강아지 해충방지 진드기 | D3: 16 | E3: 수량=공구특가 1개 (25%할인) | F3: =H3*0.75 -> 16500 | G3: =D3*F3 -> 264000 | H3: 22000 | I3: =D3*1 -> 16
C4: 도톤 포레스트 아웃도어 스프레이 150ml 강아지 해충방지 진드기 | D4: 10 | E4: 수량=공구 2개세트 (32%할인) | F4: =H4*0.68 -> 29920 | G4: =D4*F4 -> 299200 | H4: 44000 | I4: =D4*2 -> 20
C5: 도톤 포레스트 아웃도어 스프레이 150ml 강아지 해충방지 진드기 | D5: 3 | E5: 수량=공구 3개세트 (36%할인) | F5: =H5*0.64 -> 42240 | G5: =D5*F5 -> 126720 | H5: 66000 | I5: =D5*3 -> 9
C8: 합계 | D8: =SUBTOTAL(9,D3:D7) -> 29 | G8: =SUBTOTAL(9,G3:G7) -> 689920 | I8: =SUBTOTAL(9,I3:I7) -> 45
A13: 주문번호 | B13: 품목별 주문번호 | C13: 공급사 | D13: 공급사명 | E13: 결제일시(입금확인일) | F13: 배송시작일 | G13: 운송장번호 | H13: 배송완료일 | I13: 환불완료일 | J13: 주문상품명(기본) | K13: 상품옵션(기본) | L13: 수량 | M13: 판매가 | N13: 옵션추가 가격 | O13: 상품별 추가할인금액 | P13: 상품별 추가할인 상세 | Q13: 공급사 기본 배송비 | R13: 개별배송비 | S13: 쿠폰 할인금액(최종) | T13: 사용한 쿠폰명 | U13: 주문자명 | V13: 반품신청일 | W13: 교환상태 | X13: 쇼핑몰 | Y13: 옵션+판매가 | Z13: 주문 상태 | AA13: 지역별 배송비 | AB13: 환불상태 | AC13: 품목별 결제금액
A14: 20260501-0000079 | B14: 20260501-0000079-01 | C14: S00000QR | D14: 베럴즈 | E14: 46143.602 | F14: 46146.702 | G14: 92234714353 | H14: 46152.543 | J14: [영이공구특가 이벤트 상품] 도톤 포레스트 아웃도어 해충방지 스프레이 150ml | K14: 수량=공구특가 1개 (25%할인) | L14: 1 | M14: 22000 | N14: 0 | O14: 5500 | P14: 영이공구 특가 도톤아웃도어스프레이 할인 | Q14: 0 | R14: 0 | S14: 0 | U14: 박혜은 | X14: 우프(기본) | Y14: 22000 | Z14: 배송 완료 | AA14: 0
A15: 20260502-0000061 | B15: 20260502-0000061-01 | C15: S00000QR | D15: 베럴즈 | E15: 46144.922 | F15: 46146.702 | G15: 92234714316 | H15: 46149.543 | J15: [영이공구특가 이벤트 상품] 도톤 포레스트 아웃도어 해충방지 스프레이 150ml | K15: 수량=공구특가 1개 (25%할인) | L15: 1 | M15: 22000 | N15: 0 | O15: 5500 | P15: 영이공구 특가 도톤아웃도어스프레이 할인 | Q15: 0 | R15: 0 | S15: 0 | U15: 서은경 | X15: 우프(기본) | Y15: 22000 | Z15: 배송 완료 | AA15: 0
A16: 20260503-0000075 | B16: 20260503-0000075-01 | C16: S00000QR | D16: 베럴즈 | E16: 46145.823 | F16: 46146.702 | G16: 92234714283 | H16: 46154.441 | J16: [영이공구특가 이벤트 상품] 도톤 포레스트 아웃도어 해충방지 스프레이 150ml | K16: 수량=공구특가 1개 (25%할인) | L16: 1 | M16: 22000 | N16: 0 | O16: 5500 | P16: 영이공구 특가 도톤아웃도어스프레이 할인 | Q16: 0 | R16: 0 | S16: 0 | U16: 한수정 | X16: 우프(기본) | Y16: 22000 | Z16: 배송 완료 | AA16: 0
A17: 20260504-0000065 | B17: 20260504-0000065-01 | C17: S00000QR | D17: 베럴즈 | E17: 46146.537 | F17: 46146.702 | G17: 92234714224 | H17: 46152.482 | J17: [영이공구특가 이벤트 상품] 도톤 포레스트 아웃도어 해충방지 스프레이 150ml | K17: 수량=공구 2개세트 (32%할인) | L17: 1 | M17: 22000 | N17: 13400 | O17: 5500 | P17: 영이공구 특가 도톤아웃도어스프레이 할인 | Q17: 0 | R17: 0 | S17: 0 | U17: 인나엽 | X17: 우프(기본) | Y17: 35400 | Z17: 배송 완료 | AA17: 0
A18: 20260505-0000106 | B18: 20260505-0000106-01 | C18: S00000QR | D18: 베럴즈 | E18: 46147.889 | F18: 46148.556 | G18: 92234763084 | H18: 46149.599 | J18: [영이공구특가 이벤트 상품] 도톤 포레스트 아웃도어 해충방지 스프레이 150ml | K18: 수량=공구특가 1개 (25%할인) | L18: 1 | M18: 22000 | N18: 0 | O18: 5500 | P18: 영이공구 특가 도톤아웃도어스프레이 할인 | Q18: 0 | R18: 0 | S18: 0 | U18: 이보람 | X18: 우프(기본) | Y18: 22000 | Z18: 배송 완료 | AA18: 0
A19: 20260506-0000014 | B19: 20260506-0000014-01 | C19: S00000QR | D19: 베럴즈 | E19: 46147.997 | F19: 46148.556 | G19: 92234762723 | H19: 46152.626 | J19: [영이공구특가 이벤트 상품] 도톤 포레스트 아웃도어 해충방지 스프레이 150ml | K19: 수량=공구 2개세트 (32%할인) | L19: 1 | M19: 22000 | N19: 13400 | O19: 5500 | P19: 영이공구 특가 도톤아웃도어스프레이 할인 | Q19: 0 | R19: 0 | S19: 0 | U19: 김보람 | X19: 우프(기본) | Y19: 35400 | Z19: 배송 완료 | AA19: 0
A20: 20260506-0000160 | B20: 20260506-0000160-01 | C20: S00000QR | D20: 베럴즈 | E20: 46148.683 | F20: 46149.605 | G20: 92234805924 | H20: 46150.673 | J20: [영이공구특가 이벤트 상품] 도톤 포레스트 아웃도어 해충방지 스프레이 150ml | K20: 수량=공구특가 1개 (25%할인) | L20: 1 | M20: 22000 | N20: 0 | O20: 5500 | P20: 영이공구 특가 도톤아웃도어스프레이 할인 | Q20: 0 | R20: 0 | S20: 0 | U20: 신지영 | X20: 우프(기본) | Y20: 22000 | Z20: 배송 완료 | AA20: 0
A21: 20260507-0000266 | B21: 20260507-0000266-01 | C21: S00000QR | D21: 베럴즈 | E21: 46149.97 | F21: 46150.584 | G21: 92234852356 | H21: 46161.031 | J21: [영이공구특가 이벤트 상품] 도톤 포레스트 아웃도어 해충방지 스프레이 150ml | K21: 수량=공구특가 1개 (25%할인) | L21: 1 | M21: 22000 | N21: 0 | O21: 5500 | P21: 영이공구 특가 도톤아웃도어스프레이 할인 | Q21: 0 | R21: 0 | S21: 0 | U21: 유지나 | X21: 우프(기본) | Y21: 22000 | Z21: 배송 완료 | AA21: 0
A22: 20260509-0000101 | B22: 20260509-0000101-01 | C22: S00000QR | D22: 베럴즈 | E22: 46151.978 | F22: 46153.39 | G22: 92234907660 | H22: 46154.968 | J22: [영이공구특가 이벤트 상품] 도톤 포레스트 아웃도어 해충방지 스프레이 150ml | K22: 수량=공구특가 1개 (25%할인) | L22: 1 | M22: 22000 | N22: 0 | O22: 5500 | P22: 영이공구 특가 도톤아웃도어스프레이 할인 | Q22: 0 | R22: 0 | S22: 0 | U22: 김보은 | X22: 우프(기본) | Y22: 22000 | Z22: 배송 완료 | AA22: 0
A23: 20260513-0000049 | B23: 20260513-0000049-01 | C23: S00000QR | D23: 베럴즈 | E23: 46155.508 | F23: 46155.584 | G23: 92235033800 | H23: 46159.953 | J23: [영이공구특가 이벤트 상품] 도톤 포레스트 아웃도어 해충방지 스프레이 150ml | K23: 수량=공구 2개세트 (32%할인) | L23: 1 | M23: 22000 | N23: 13400 | O23: 5500 | P23: 영이공구 특가 도톤아웃도어스프레이 할인 | Q23: 0 | R23: 0 | S23: 0 | U23: 고샛별 | X23: 우프(기본) | Y23: 35400 | Z23: 배송 완료 | AA23: 3000
A24: 20260513-0000086 | B24: 20260513-0000086-01 | C24: S00000QR | D24: 베럴즈 | E24: 46155.542 | F24: 46155.584 | G24: 92235033870 | H24: 46156.943 | J24: [영이공구특가 이벤트 상품] 도톤 포레스트 아웃도어 해충방지 스프레이 150ml | K24: 수량=공구특가 1개 (25%할인) | L24: 1 | M24: 22000 | N24: 0 | O24: 5500 | P24: 영이공구 특가 도톤아웃도어스프레이 할인 | Q24: 0 | R24: 0 | S24: 0 | U24: 임지현 | X24: 우프(기본) | Y24: 22000 | Z24: 배송 완료 | AA24: 0
A25: 20260513-0000094 | B25: 20260513-0000094-01 | C25: S00000QR | D25: 베럴즈 | E25: 46155.585 | F25: 46155.681 | G25: 92235044171 | H25: 46157.428 | J25: [영이공구특가 이벤트 상품] 도톤 포레스트 아웃도어 해충방지 스프레이 150ml | K25: 수량=공구 3개세트 (36%할인) | L25: 1 | M25: 22000 | N25: 25700 | O25: 5500 | P25: 영이공구 특가 도톤아웃도어스프레이 할인 | Q25: 0 | R25: 0 | S25: 0 | U25: 김찬미 | X25: 우프(기본) | Y25: 47700 | Z25: 배송 완료 | AA25: 0
... A42: 20260524-0000035 | B42: 20260524-0000035-01 | C42: S00000QR | D42: 베럴즈 | E42: 46166.672 | F42: 46168.438 | G42: 92235430313 | H42: 46169.811 | J42: [영이공구특가 이벤트 상품] 도톤 포레스트 아웃도어 해충방지 스프레이 150ml | K42: 수량=공구 3개세트 (36%할인) | L42: 1 | M42: 22000 | N42: 25700 | O42: 5500 | P42: 영이공구 특가 도톤아웃도어스프레이 할인 | Q42: 0 | R42: 0 | S42: 0 | U42: 한주연 | X42: 우프(기본) | Y42: 47700 | Z42: 배송 완료 | AA42: 0

Sheet DB)스마트스토어
A1: 상품주문번호 | B1: 주문번호 | C1: 구매확정일 | D1: 판매채널 | E1: 주문상태 | F1: 구매자명 | G1: 구매자ID | H1: 수취인명 | I1: 발송처리일 | J1: 배송방법 | K1: 택배사 | L1: 송장번호 | M1: 배송완료일 | N1: 상품번호 | O1: 상품명 | P1: 상품종류 | Q1: 옵션정보 | R1: 수량 | S1: 상품가격 | T1: 옵션가격 | U1: 최종 상품별 할인액 | V1: 판매자 부담 할인액 | W1: 최종 상품별 총 주문금액 | X1: 판매자 상품코드 | Y1: 판매자 내부코드1 | Z1: 판매자 내부코드2 | AA1: 배송비 묶음번호 | AB1: 배송비 형태 | AC1: 배송비 유형 | AD1: 배송비 합계 | AE1: 제주/도서 추가배송비 | AF1: 배송비 할인액 | AG1: 결제일 | AH1: 결제수단 | AI1: 결제위치 | AJ1: 네이버페이 주문관리 수수료 | AK1: 매출연동 수수료 | AL1: 정산예정금액
A2: 2026051964979581 | B2: 2026051982360941 | C2: 46170.098 | D2: 스마트스토어 | E2: 구매확정 | F2: 조윤정 | G2: yunj****** | H2: 조윤정 | I2: 46161.632 | J2: 택배,등기,소포 | K2: 로젠택배 | L2: 92235276604 | M2: 46162.679 | N2: 12423379709 | O2: 도톤 포레스트 아웃도어 스프레이 150ml 강아지 해충방지 진드기 | P2: 단일상품 | R2: 1 | S2: 22000 | T2: 0 | U2: 2200 | V2: 2200 | W2: 19800 | AA2: 2026051981433239 | AB2: 무료 | AC2: 무료 | AD2: 0 | AE2: 0 | AF2: 0 | AG2: 46161.443 | AH2: 신용카드 간편결제 | AI2: PC | AJ2: -540 | AK2: -198 | AL2: 19062
A3: 2026051059055961 | B3: 2026051018182881 | C3: 46162.056 | D3: 스마트스토어 | E3: 구매확정 | F3: 유은진 | G3: zzdb**** | H3: 공주 | I3: 46153.383 | J3: 택배,등기,소포 | K3: 로젠택배 | L3: 92234907520 | M3: 46154.69 | N3: 12423379709 | O3: 도톤 포레스트 아웃도어 스프레이 150ml 강아지 해충방지 진드기 | P3: 단일상품 | R3: 1 | S3: 22000 | T3: 0 | U3: 2200 | V3: 2200 | W3: 19800 | AA3: 2026051058054732 | AB3: 무료 | AC3: 무료 | AD3: 0 | AE3: 0 | AF3: 0 | AG3: 46152.43 | AH3: 무통장입금 | AI3: MOBILE | AJ3: -540 | AK3: -594 | AL3: 18666
A4: 2026051059055951 | B4: 2026051018182881 | C4: 46162.056 | D4: 스마트스토어 | E4: 구매확정 | F4: 유은진 | G4: zzdb**** | H4: 공주 | I4: 46153.383 | J4: 택배,등기,소포 | K4: 로젠택배 | L4: 92234907520 | M4: 46154.69 | N4: 12423395816 | O4: 도톤 포레스트 워터리스 풋클리너 강아지 발세정제 100ml | P4: 단일상품 | R4: 1 | S4: 22000 | T4: 0 | U4: 2200 | V4: 2200 | W4: 19800 | AA4: 2026051058054731 | AB4: 무료 | AC4: 무료 | AD4: 0 | AE4: 0 | AF4: 0 | AG4: 46152.43 | AH4: 무통장입금 | AI4: MOBILE | AJ4: -540 | AK4: -594 | AL4: 18666
A5: 2026043039610441 | B5: 2026043032327861 | C5: 46151.065 | D5: 스마트스토어 | E5: 구매확정 | F5: 장조은 | G5: feve***** | H5: 장조은 | I5: 46142.703 | J5: 택배,등기,소포 | K5: 로젠택배 | L5: 92234617171 | M5: 46143.466 | N5: 12423379709 | O5: 도톤 포레스트 아웃도어 스프레이 150ml 강아지 해충방지 진드기 | P5: 단일상품 | R5: 1 | S5: 22000 | T5: 0 | U5: 2200 | V5: 2200 | W5: 19800 | AA5: 2026043033590504 | AB5: 무료 | AC5: 무료 | AD5: 0 | AE5: 0 | AF5: 0 | AG5: 46142.225 | AH5: 신용카드 간편결제 | AI5: MOBILE | AJ5: -540 | AK5: -198 | AL5: 19062
A6: 2026042883954521 | B6: 2026042891931141 | C6: 46150.11 | D6: 스마트스토어 | E6: 구매확정 | F6: 정선주 | G6: fl**** | H6: 정선주 | I6: 46141.689 | J6: 택배,등기,소포 | K6: 로젠택배 | L6: 92234560261 | M6: 46142.963 | N6: 12423379709 | O6: 도톤 포레스트 아웃도어 스프레이 150ml 강아지 해충방지 진드기 | P6: 단일상품 | R6: 1 | S6: 22000 | T6: 0 | U6: 2300 | V6: 2300 | W6: 19700 | AA6: 2026042830699266 | AB6: 무료 | AC6: 무료 | AD6: 0 | AE6: 0 | AF6: 0 | AG6: 46140.978 | AH6: 신용카드 | AI6: MOBILE | AJ6: -536 | AK6: -197 | AL6: 18967
O8: 집계: 26.5.1-5.31 (구매확정 기준)
O10: 상품 | P10: 합계수량 | Q10: 정상가계 | R10: 혜택 | S10: 판매가계
O11: 도톤 포레스트 아웃도어 스프레이 150ml | P11: 4 | Q11: =22000*P11 -> 88000 | R11: 상시할인(-10%) | S11: =22000*90%*P11 -> 79200
O12: 도톤 포레스트 워터리스 풋클리너 100ml | P12: 1 | Q12: =22000*P12 -> 22000 | R12: 상시할인(-10%) | S12: =22000*90%*P12 -> 19800
O13: total | P13: =SUM(P11:P12) -> 5 | Q13: =SUM(Q11:Q12) -> 110000 | S13: =SUM(S11:S12) -> 99000

Sheet DB) 행사
A1: 품목 | B1: 판매수량 | C1: 마켓 할인가 | D1: 합계 | E1: 추가할인 | F1: 수수료(20%) | G1: 합계(실매출) | H1: 행사명
A2: 도톤 풋 | B2: 14 | C2: 15000 | D2: =B2*C2 -> 210000 | F2: =D2*20% -> 42000 | G2: =SUM(D2+D3) -> 240000 | H2: 5/3 플리마켓 태리마켓
A3: 도톤 아웃도어 | B3: 2 | C3: 15000 | D3: =B3*C3 -> 30000 | F3: =D3*20% -> 6000 | H3: 5/3 플리마켓 태리마켓
A5: 총합계 | D5: =SUM(D2:D4) -> 240000 | F5: =SUM(F2:F4) -> 48000 | G5: =D5-F5 -> 192000
A9: 상품 | B9: 합계수량 | C9: 정상가계 | D9: 혜택 | E9: 판매가계
A10: 도톤 포레스트 아웃도어 스프레이 150ml | B10: 2 | C10: =22000*B10 -> 44000 | D10: 마켓할인-7,000 | E10: =(22000-7000)*B10 -> 30000
A11: 도톤 포레스트 워터리스 풋클리너 100ml | B11: 14 | C11: =22000*B11 -> 308000 | D11: 마켓할인-7,000 | E11: =(22000-7000)*B11 -> 210000
A12: total | B12: =SUM(B10:B11) -> 16 | C12: =SUM(C10:C11) -> 352000 | E12: =SUM(E10:E11) -> 240000
A13: 판매수수료 | E13: =E12*20% -> 48000
A14: 정산계 | E14: =E12-E13 -> 192000

Sheet DB)사업자몰B2B
A1: 주문번호 | B1: 품목별 주문번호 | C1: 공급사 | D1: 공급사명 | E1: 결제일시(입금확인일) | F1: 배송시작일 | G1: 운송장번호 | H1: 배송완료일 | I1: 환불완료일 | J1: 주문상품명(기본) | K1: 상품옵션(기본) | L1: 수량 | M1: 판매가 | N1: 옵션추가 가격 | O1: 상품별 추가할인금액 | P1: 상품별 추가할인 상세 | Q1: 공급사 기본 배송비 | R1: 개별배송비 | S1: 쿠폰 할인금액(최종) | T1: 사용한 쿠폰명 | U1: 주문자명 | V1: 반품신청일 | W1: 교환상태 | X1: 쇼핑몰 | Y1: 옵션+판매가 | Z1: 주문 상태 | AA1: 지역별 배송비 | AB1: 환불상태 | AC1: 수령인
A2: 20260504-0000051 | B2: 20260504-0000051-03 | C2: S00000QR | D2: 베럴즈 | E2: 46146.492 | F2: 46146.681 | G2: 92234714191 | H2: 46148.737 | J2: 도톤 포레스트 아웃도어 스프레이 150ml 강아지 해충방지 진드기 | L2: 1 | M2: 13200 | N2: 0 | O2: 0 | Q2: 0 | R2: 0 | S2: 5850 | T2: 첫주문 5% 할인쿠폰 | U2: 김송희 | X2: 우프(B2B) | Y2: 13200 | Z2: 배송 완료 | AA2: 0 | AC2: 김송희
A3: 20260513-0000077 | B3: 20260513-0000077-06 | C3: S00000QR | D3: 베럴즈 | E3: 46155.563 | F3: 46157.639 | G3: 92235116105 | H3: 46158.778 | J3: 도톤 포레스트 아웃도어 스프레이 150ml 강아지 해충방지 진드기 | L3: 9 | M3: 13200 | N3: 0 | O3: 0 | Q3: 0 | R3: 0 | S3: 0 | U3: 김종성 | X3: 우프(B2B) | Y3: 13200 | Z3: 배송 완료 | AA3: 0 | AC3: 김종성
K5: 실판매수량 | L5: =SUM(L2:L4) -> 10
K6: 판매정가 | L6: 22000
K7: 소매점공급가 | L7: =L6*60% -> 13200
K8: 합계 | L8: =L5*L7 -> 132000

Sheet DB)이마트몰리스
A1: 이마트(몰리스하남) 5월 판매집계
A2: 점포코드 | B2: 업태코드 | C2: 업태명 | D2: 점포명 | E2: 업체코드 | F2: 업체명 | G2: 상품코드 | H2: 상품명 | I2: 납품일자 | J2: 발주일자 | K2: 문서번호 | L2: 납품구분 | M2: 발주량 | N2: 납품량 | O2: 발주금액 | P2: 납품금액 | Q2: 원가 | R2: 매입구분 | S2: 센터코드 | T2: 센터명 | U2: LOT | V2: 매입형태 | W2: 매입구분명 | X2: 원상품코드
A3: 5304 | B3: 1100 | C3: 이마트 | D3: 몰리스STF하남점 | E3: 1610931 | F3: 우프컴퍼니 | G3: 8809879544101 | H3: 도톤 포레스트 아웃도어 스프레이 150ml | I3: 20260630 | J3: 20260630 | K3: 6095289621 | L3: 직납 | M3: 1 | N3: 1 | O3: 14000 | P3: 14000 | Q3: 14000 | R3: 59 | S3: 5304 | T3: 몰리스STF하남점 | U3: 1 | V3: 정상 | W3: 특행/배달
A4: 5304 | B4: 1100 | C4: 이마트 | D4: 몰리스STF하남점 | E4: 1610931 | F4: 우프컴퍼니 | G4: 8809879544101 | H4: 도톤 포레스트 아웃도어 스프레이 150ml | I4: 20260627 | J4: 20260627 | K4: 6095109504 | L4: 직납 | M4: 1 | N4: 1 | O4: 14000 | P4: 14000 | Q4: 14000 | R4: 59 | S4: 5304 | T4: 몰리스STF하남점 | U4: 1 | V4: 정상 | W4: 특행/배달
A5: 5304 | B5: 1100 | C5: 이마트 | D5: 몰리스STF하남점 | E5: 1610931 | F5: 우프컴퍼니 | G5: 8809879544101 | H5: 도톤 포레스트 아웃도어 스프레이 150ml | I5: 20260607 | J5: 20260607 | K5: 6093863018 | L5: 직납 | M5: 2 | N5: 2 | O5: 28000 | P5: 28000 | Q5: 14000 | R5: 59 | S5: 5304 | T5: 몰리스STF하남점 | U5: 2 | V5: 정상 | W5: 특행/배달
L10: 품목 | M10: 수량합계 | N10: 정가 | O10: 공급가(부가세포함) | P10: 공급가합
L11: 도톤 포레스트 아웃도어 스프레이 150ml | M11: 4 | N11: 22000 | O11: =14000+1400 -> 15400 | P11: =M11*O11 -> 61600
L12: 도톤 포레스트 워터리스 풋클리너 100ml | N12: 22000 | O12: =14000+1400 -> 15400 | P12: =M12*O12 -> 0
L13: 합계 | M13: =SUM(M11:M12) -> 4 | P13: =SUM(P11:P12) -> 61600

Sheet DB) 컬리
A1: 컬리 5월
A2: 집계: 구매확정 기준
A3: 개별주문번호 | B3: 대표주문번호 | C3: 주문상태 | D3: 주문일시 | E3: 상품번호 | F3: 상품명 | G3: 옵션명 | H3: 옵션번호 | I3: 딜코드 | J3: 판매자코드 | K3: 권장소비자가 | L3: 판매가 | M3: 수량 | N3: 주문금액 | O3: 택배사 | P3: 운송장번호 | Q3: 주문자명 | R3: 수취인명 | S3: 배송유형 | T3: 발주확인일 | U3: 발송처리일 | V3: 배송완료일 | W3: 예약확정일 | X3: 예약일 | Y3: 설치사용완료일 | Z3: 구매확정일 | AA3: 픽업시작일 | AB3: 픽업종료일 | AC3: 픽업매장 | AD3: 미픽업반송대상 | AE3: 개인통관고유번호 | AF3: 상품ID | AG3: 주문ID
A4: 1777927884002 | B4: 2414205510007 | C4: 구매확정 | D4: 2026-05-05T05:51:25 | E4: P25102716000204 | F4: [도톤] 포레스트 아웃도어 스프레이 150ml 강아지 해충방지 진드기 (도톤 포레스트 아웃도어 스프레이) | G4: 도톤 포레스트 아웃도어 스프레이 | H4: P251027160002040001 | I4: 1001772676 | K4: 22000 | L4: 22000 | M4: 1 | N4: 22000 | O4: 로젠택배 | P4: 92234777784 | Q4: 최*정 | R4: 최*정 | S4: 택배 | T4: 2026-05-06T14:15:47 | U4: 2026-05-06T15:29:12 | V4: 2026-05-07T13:59:07 | Z4: 2026-05-14T04:00:48 | AF4: 1132897 | AG4: 20957024
A5: 1778101124001 | B5: 2414405580018 | C5: 구매확정 | D5: 2026-05-07T05:58:44 | E5: P25102716000204 | F5: [도톤] 포레스트 아웃도어 스프레이 150ml 강아지 해충방지 진드기 (도톤 포레스트 아웃도어 스프레이) | G5: 도톤 포레스트 아웃도어 스프레이 | H5: P251027160002040001 | I5: 1001772676 | K5: 22000 | L5: 22000 | M5: 2 | N5: 44000 | O5: 로젠택배 | P5: 92234826460 | Q5: 이*진 | R5: 이*진 | S5: 택배 | T5: 2026-05-07T13:59:40 | U5: 2026-05-07T16:14:34 | V5: 2026-05-08T11:12:15 | Z5: 2026-05-15T04:01:54 | AF5: 1132897 | AG5: 21037145
A6: 1778840217004 | B6: 2415219160235 | C6: 구매확정 | D6: 2026-05-15T19:16:57 | E6: P25102716000204 | F6: [도톤] 포레스트 아웃도어 스프레이 150ml 강아지 해충방지 진드기 (도톤 포레스트 아웃도어 스프레이) | G6: 도톤 포레스트 아웃도어 스프레이 | H6: P251027160002040001 | I6: 1001772676 | K6: 22000 | L6: 22000 | M6: 1 | N6: 22000 | O6: 로젠택배 | P6: 92235225891 | Q6: 김*연 | R6: 김*연 | S6: 택배 | T6: 2026-05-18T16:10:19 | U6: 2026-05-18T16:10:30 | V6: 2026-05-19T12:58:58 | Z6: 2026-05-26T04:00:55 | AF6: 1132897 | AG6: 21307901
A7: 1779428211001 | B7: 2415914360140 | C7: 구매확정 | D7: 2026-05-22T14:36:51 | E7: P25102716000204 | F7: [도톤] 포레스트 아웃도어 스프레이 150ml 강아지 해충방지 진드기 (도톤 포레스트 아웃도어 스프레이) | G7: 도톤 포레스트 아웃도어 스프레이 | H7: P251027160002040001 | I7: 1001772676 | K7: 22000 | L7: 22000 | M7: 1 | N7: 22000 | O7: 로젠택배 | P7: 92235453181 | Q7: 오*영 | R7: 오*영 | S7: 택배 | T7: 2026-05-22T18:26:37 | U7: 2026-05-26T14:00:31 | V7: 2026-05-27T14:17:05 | Z7: 2026-06-03T04:01:28 | AF7: 1132897 | AG7: 21565227
K8: 합계 | L8: 22000 | M8: =SUM(M4:M7) -> 5 | N8: =L8*M8 -> 110000

Sheet DB)쿠팡로켓
A1: 구분 | B1: 번호 | C1: SKU번호 | D1: SKU명 | E1: 입고/반출시각 | F1: 물류센터 | G1: 세금타입 | H1: 수량 | I1: 단가 | J1: 공급가액 | K1: 세액 | L1: 총단가 | M1: 총공급가액 | N1: 총세액 | O1: 계산서번호 | P1: 지급일
A2: 발주 | B2: 130902115 | C2: 70945869 | D2: 도톤 포레스트 아웃도어 강아지 스프레이 150ml 1개 단일색상 | E2: 2026/05/09 15:27:01 | F2: DAE3 | G2: 과세 | H2: 2 | I2: 13,860 | J2: 12,600 | K2: 1,260 | L2: 27720 | M2: 25,200 | N2: 2,520 | O2: 29580323 | P2: 2026/07/08 00:00:00
A3: 발주 | B3: 131154290 | C3: 70945869 | D3: 도톤 포레스트 아웃도어 강아지 스프레이 150ml 1개 단일색상 | E3: 2026/05/13 15:08:54 | F3: INC30 | G3: 과세 | H3: 1 | I3: 13,860 | J3: 12,600 | K3: 1,260 | L3: 13860 | M3: 12,600 | N3: 1,260 | O3: 29623389 | P3: 2026/07/10 00:00:00
A4: 발주 | B4: 131805352 | C4: 70945869 | D4: 도톤 포레스트 아웃도어 강아지 스프레이 150ml 1개 단일색상 | E4: 2026/05/24 03:22:56 | F4: SAN3 | G4: 과세 | H4: 1 | I4: 13,860 | J4: 12,600 | K4: 1,260 | L4: 13860 | M4: 12,600 | N4: 1,260 | O4: 29752709 | P4: 2026/07/23 00:00:00
G7: 수량계 | H7: =SUM(H2:H4) -> 4 | I7: 수수료율 | J7: 0.37
G8: 공급가계 | H8: =13860*H7 -> 55440

Sheet DB)대리점(파마스퀘어)
A1: 번호 | B1: 상품 | C1: 바코드 | D1: 재고 단위 | E1: 판매수량 | F1: 판매가 | G1: 공급율(55%) | H1: 수수료(45%) | I1: 심매출액
A2: 1 | B2: [도톤] 포레스트 아웃도어 스프레이 150ml 강아지 해중방지 진드기 | C2: 8809879544101 | D2: EA | E2: 1 | F2: 22000 | G2: 12100 | H2: 9900 | I2: 12100
E3: 1 | I3: 12100

Sheet DB)철수마켓
A2: 채널명 | B2: 주문번호 | C2: 상품주문번호 | D2: 구분 | E2: 상품명 | F2: 수량 | G2: 구매자명 | H2: 결제금액
E3: 판매없음
G5: 판매수수료(25%) | H5: =H3*25% -> 0
G6: 정산금액 | H6: =H3-H5 -> 0

Sheet DB)몽슈슈
B1: 5월 판매내역
A2: 순번 | B2: 제품 | C2: 상품코드 | D2: 소비자가 | E2: 공급가 | F2: 재고 | G2: 입고 | H2: 반송 | I2: 판매 | J2: 월말재고 | K2: 판매합계
A3: 1 | B3: DOTEON Foot Cleaner | C3: BT25DTFC | D3: 22000 | E3: 13200 | F3: 6 | G3: 0 | I3: 0 | J3: =F3+G3-H3-I3 -> 6 | K3: =E3*I3 -> 0
A4: 2 | B4: DOTEON Outdoor Spray | C4: BT25OS | D4: 22000 | E4: 13200 | F4: 6 | G4: 0 | I4: 2 | J4: =F4+G4-H4-I4 -> 4 | K4: =E4*I4 -> 26400
I5: =SUM(I3:I4) -> 2 | K5: =SUM(K3:K4) -> 26400
B8: 합계
B10: 제품 | C10: 정상가 | D10: 공급가 | E10: 수량 | F10: 판매계 | G10: 혜택공제 | H10: 정산계
B11: DOTEON Foot Cleaner | C11: 22000 | D11: 13200 | E11: =I3 -> 0 | F11: =D11*E11 -> 0 | H11: =F11-G11 -> 0
B12: DOTEON Outdoor Spray | C12: 22000 | D12: 13200 | E12: =I4 -> 2 | F12: =D12*E12 -> 26400 | H12: =F12-G12 -> 26400
E13: =SUM(E11:E12) -> 2 | F13: =SUM(F11:F12) -> 26400 | G13: =SUM(G11:G12) -> 0 | H13: =SUM(H11:H12) -> 26400

Sheet DB)대리점(테일릿)
A1: 주문번호 | B1: 품목별 주문번호 | C1: 공급사 | D1: 공급사명 | E1: 결제일시(입금확인일) | F1: 배송시작일 | G1: 운송장번호 | H1: 배송완료일 | I1: 환불완료일 | J1: 주문상품명(기본) | K1: 상품옵션(기본) | L1: 수량 | M1: 판매가 | N1: 옵션추가 가격 | O1: 상품별 추가할인금액 | P1: 상품별 추가할인 상세 | Q1: 공급사 기본 배송비 | R1: 개별배송비 | S1: 쿠폰 할인금액(최종) | T1: 사용한 쿠폰명 | U1: 주문자명 | V1: 반품신청일 | W1: 교환상태 | X1: 쇼핑몰 | Y1: 옵션+판매가 | Z1: 주문 상태 | AA1: 지역별 배송비 | AB1: 환불상태 | AC1: 수령인
A2: 20260513-0000179 | B2: 20260513-0000179-01 | C2: S00000QR | D2: 베럴즈 | E2: 46155.707 | F2: 46156.417 | G2: 92235055500 | H2: 46157.445 | J2: 도톤 포레스트 아웃도어 스프레이 150ml 강아지 해충방지 진드기 | L2: 20 | M2: 10560 | N2: 0 | O2: 0 | Q2: 0 | R2: 0 | S2: 0 | U2: 우프(베럴즈) | X2: 우프(B2B) | Y2: 10560 | Z2: 배송 완료 | AA2: 0 | AC2: 테일릿
L4: 정가 | M4: 22000
L5: 대리점가 | M5: =M4*48% -> 10560
L6: 판매계 | M6: =L2*M5 -> 211200
